
2023-04-06 19:58:49,817 INFO: errors [in /home/abdulaziz/abdulaziz/courses/udacity/nd/fyyur/app.py:546]
2023-04-06 19:58:54,350 INFO: errors [in /home/abdulaziz/abdulaziz/courses/udacity/nd/fyyur/app.py:546]
2023-04-06 19:58:59,121 INFO: errors [in /home/abdulaziz/abdulaziz/courses/udacity/nd/fyyur/app.py:546]
2023-04-06 20:02:18,517 INFO: errors [in /home/abdulaziz/abdulaziz/courses/udacity/nd/fyyur/app.py:545]
2023-04-06 20:09:02,268 INFO: errors [in /home/abdulaziz/abdulaziz/courses/udacity/nd/fyyur/app.py:571]
2023-04-06 20:09:24,437 INFO: errors [in /home/abdulaziz/abdulaziz/courses/udacity/nd/fyyur/app.py:571]
2023-04-06 20:09:41,625 INFO: errors [in /home/abdulaziz/abdulaziz/courses/udacity/nd/fyyur/app.py:571]
2023-04-06 20:10:39,260 INFO: errors [in /home/abdulaziz/abdulaziz/courses/udacity/nd/fyyur/app.py:571]
2023-04-06 20:10:41,563 ERROR: Exception on /artists/create [POST] [in /home/abdulaziz/abdulaziz/courses/udacity/nd/fyyur/udacity_nd/lib/python3.10/site-packages/flask/app.py:1744]
Traceback (most recent call last):
  File "/home/abdulaziz/abdulaziz/courses/udacity/nd/fyyur/udacity_nd/lib/python3.10/site-packages/flask/app.py", line 2528, in wsgi_app
    response = self.full_dispatch_request()
  File "/home/abdulaziz/abdulaziz/courses/udacity/nd/fyyur/udacity_nd/lib/python3.10/site-packages/flask/app.py", line 1825, in full_dispatch_request
    rv = self.handle_user_exception(e)
  File "/home/abdulaziz/abdulaziz/courses/udacity/nd/fyyur/udacity_nd/lib/python3.10/site-packages/flask/app.py", line 1823, in full_dispatch_request
    rv = self.dispatch_request()
  File "/home/abdulaziz/abdulaziz/courses/udacity/nd/fyyur/udacity_nd/lib/python3.10/site-packages/flask/app.py", line 1799, in dispatch_request
    return self.ensure_sync(self.view_functions[rule.endpoint])(**view_args)
  File "/home/abdulaziz/abdulaziz/courses/udacity/nd/fyyur/app.py", line 486, in create_artist_submission
    abort(exc)
UnboundLocalError: local variable 'exc' referenced before assignment
2023-04-06 20:10:59,638 INFO: errors [in /home/abdulaziz/abdulaziz/courses/udacity/nd/fyyur/app.py:572]
2023-04-06 20:11:42,389 INFO: errors [in /home/abdulaziz/abdulaziz/courses/udacity/nd/fyyur/app.py:572]
2023-04-06 20:14:29,314 INFO: errors [in /home/abdulaziz/abdulaziz/courses/udacity/nd/fyyur/app.py:566]
2023-04-06 20:16:23,763 INFO: errors [in /home/abdulaziz/abdulaziz/courses/udacity/nd/fyyur/app.py:566]
2023-04-06 20:16:50,476 INFO: errors [in /home/abdulaziz/abdulaziz/courses/udacity/nd/fyyur/app.py:567]
2023-04-06 20:18:12,642 INFO: errors [in /home/abdulaziz/abdulaziz/courses/udacity/nd/fyyur/app.py:567]
2023-04-06 20:18:19,097 INFO: errors [in /home/abdulaziz/abdulaziz/courses/udacity/nd/fyyur/app.py:567]
2023-04-06 20:18:46,311 INFO: errors [in /home/abdulaziz/abdulaziz/courses/udacity/nd/fyyur/app.py:567]
2023-04-06 20:18:48,524 INFO: errors [in /home/abdulaziz/abdulaziz/courses/udacity/nd/fyyur/app.py:567]
2023-04-06 20:19:02,509 INFO: errors [in /home/abdulaziz/abdulaziz/courses/udacity/nd/fyyur/app.py:567]
2023-04-06 20:19:05,685 INFO: errors [in /home/abdulaziz/abdulaziz/courses/udacity/nd/fyyur/app.py:567]
2023-04-06 20:19:38,917 INFO: errors [in /home/abdulaziz/abdulaziz/courses/udacity/nd/fyyur/app.py:567]
2023-04-06 20:21:17,473 INFO: errors [in /home/abdulaziz/abdulaziz/courses/udacity/nd/fyyur/app.py:567]
2023-04-06 20:27:25,862 INFO: errors [in /home/abdulaziz/abdulaziz/courses/udacity/nd/fyyur/app.py:575]
2023-04-08 13:09:31,790 INFO: errors [in /home/abdulaziz/abdulaziz/courses/udacity/nd/fyyur/app.py:578]
2023-04-08 13:09:36,281 INFO: errors [in /home/abdulaziz/abdulaziz/courses/udacity/nd/fyyur/app.py:578]
2023-04-08 13:09:40,336 INFO: errors [in /home/abdulaziz/abdulaziz/courses/udacity/nd/fyyur/app.py:578]
2023-04-08 13:09:59,845 INFO: errors [in /home/abdulaziz/abdulaziz/courses/udacity/nd/fyyur/app.py:578]
2023-04-08 13:10:01,769 INFO: errors [in /home/abdulaziz/abdulaziz/courses/udacity/nd/fyyur/app.py:578]
2023-04-08 13:10:21,113 INFO: errors [in /home/abdulaziz/abdulaziz/courses/udacity/nd/fyyur/app.py:578]
2023-04-08 13:10:22,359 INFO: errors [in /home/abdulaziz/abdulaziz/courses/udacity/nd/fyyur/app.py:578]
2023-04-08 13:10:31,907 INFO: errors [in /home/abdulaziz/abdulaziz/courses/udacity/nd/fyyur/app.py:578]
2023-04-08 13:10:51,047 INFO: errors [in /home/abdulaziz/abdulaziz/courses/udacity/nd/fyyur/app.py:578]
2023-04-08 13:16:11,396 INFO: errors [in /home/abdulaziz/abdulaziz/courses/udacity/nd/fyyur/app.py:578]
2023-04-08 13:28:24,742 INFO: errors [in /home/abdulaziz/abdulaziz/courses/udacity/nd/fyyur/app.py:575]
2023-04-08 13:28:29,507 ERROR: Exception on /artists/1 [GET] [in /home/abdulaziz/abdulaziz/courses/udacity/nd/fyyur/udacity_nd/lib/python3.10/site-packages/flask/app.py:1744]
Traceback (most recent call last):
  File "/home/abdulaziz/abdulaziz/courses/udacity/nd/fyyur/udacity_nd/lib/python3.10/site-packages/flask/app.py", line 2528, in wsgi_app
    response = self.full_dispatch_request()
  File "/home/abdulaziz/abdulaziz/courses/udacity/nd/fyyur/udacity_nd/lib/python3.10/site-packages/flask/app.py", line 1825, in full_dispatch_request
    rv = self.handle_user_exception(e)
  File "/home/abdulaziz/abdulaziz/courses/udacity/nd/fyyur/udacity_nd/lib/python3.10/site-packages/flask/app.py", line 1823, in full_dispatch_request
    rv = self.dispatch_request()
  File "/home/abdulaziz/abdulaziz/courses/udacity/nd/fyyur/udacity_nd/lib/python3.10/site-packages/flask/app.py", line 1799, in dispatch_request
    return self.ensure_sync(self.view_functions[rule.endpoint])(**view_args)
  File "/home/abdulaziz/abdulaziz/courses/udacity/nd/fyyur/app.py", line 384, in show_artist
    data = list(filter(lambda d: d['id'] == artist_id, [data1, data2, data3]))[0]
IndexError: list index out of range
2023-04-08 13:33:13,734 INFO: errors [in /home/abdulaziz/abdulaziz/courses/udacity/nd/fyyur/app.py:551]
2023-04-08 13:33:16,968 ERROR: Exception on /shows [GET] [in /home/abdulaziz/abdulaziz/courses/udacity/nd/fyyur/udacity_nd/lib/python3.10/site-packages/flask/app.py:1744]
Traceback (most recent call last):
  File "/home/abdulaziz/abdulaziz/courses/udacity/nd/fyyur/udacity_nd/lib/python3.10/site-packages/flask/app.py", line 2528, in wsgi_app
    response = self.full_dispatch_request()
  File "/home/abdulaziz/abdulaziz/courses/udacity/nd/fyyur/udacity_nd/lib/python3.10/site-packages/flask/app.py", line 1825, in full_dispatch_request
    rv = self.handle_user_exception(e)
  File "/home/abdulaziz/abdulaziz/courses/udacity/nd/fyyur/udacity_nd/lib/python3.10/site-packages/flask/app.py", line 1823, in full_dispatch_request
    rv = self.dispatch_request()
  File "/home/abdulaziz/abdulaziz/courses/udacity/nd/fyyur/udacity_nd/lib/python3.10/site-packages/flask/app.py", line 1799, in dispatch_request
    return self.ensure_sync(self.view_functions[rule.endpoint])(**view_args)
  File "/home/abdulaziz/abdulaziz/courses/udacity/nd/fyyur/app.py", line 495, in shows
    "venue_name": Venue.query.filter_by(show.venue_id).name,
TypeError: Query.filter_by() takes 1 positional argument but 2 were given
2023-04-08 13:33:18,920 ERROR: Exception on /shows [GET] [in /home/abdulaziz/abdulaziz/courses/udacity/nd/fyyur/udacity_nd/lib/python3.10/site-packages/flask/app.py:1744]
Traceback (most recent call last):
  File "/home/abdulaziz/abdulaziz/courses/udacity/nd/fyyur/udacity_nd/lib/python3.10/site-packages/flask/app.py", line 2528, in wsgi_app
    response = self.full_dispatch_request()
  File "/home/abdulaziz/abdulaziz/courses/udacity/nd/fyyur/udacity_nd/lib/python3.10/site-packages/flask/app.py", line 1825, in full_dispatch_request
    rv = self.handle_user_exception(e)
  File "/home/abdulaziz/abdulaziz/courses/udacity/nd/fyyur/udacity_nd/lib/python3.10/site-packages/flask/app.py", line 1823, in full_dispatch_request
    rv = self.dispatch_request()
  File "/home/abdulaziz/abdulaziz/courses/udacity/nd/fyyur/udacity_nd/lib/python3.10/site-packages/flask/app.py", line 1799, in dispatch_request
    return self.ensure_sync(self.view_functions[rule.endpoint])(**view_args)
  File "/home/abdulaziz/abdulaziz/courses/udacity/nd/fyyur/app.py", line 495, in shows
    "venue_name": Venue.query.filter_by(show.venue_id).name,
TypeError: Query.filter_by() takes 1 positional argument but 2 were given
2023-04-08 13:41:11,763 INFO: errors [in /home/abdulaziz/abdulaziz/courses/udacity/nd/fyyur/app.py:555]
2023-04-08 13:41:16,141 ERROR: Exception on /shows [GET] [in /home/abdulaziz/abdulaziz/courses/udacity/nd/fyyur/udacity_nd/lib/python3.10/site-packages/flask/app.py:1744]
Traceback (most recent call last):
  File "/home/abdulaziz/abdulaziz/courses/udacity/nd/fyyur/udacity_nd/lib/python3.10/site-packages/flask/app.py", line 2528, in wsgi_app
    response = self.full_dispatch_request()
  File "/home/abdulaziz/abdulaziz/courses/udacity/nd/fyyur/udacity_nd/lib/python3.10/site-packages/flask/app.py", line 1825, in full_dispatch_request
    rv = self.handle_user_exception(e)
  File "/home/abdulaziz/abdulaziz/courses/udacity/nd/fyyur/udacity_nd/lib/python3.10/site-packages/flask/app.py", line 1823, in full_dispatch_request
    rv = self.dispatch_request()
  File "/home/abdulaziz/abdulaziz/courses/udacity/nd/fyyur/udacity_nd/lib/python3.10/site-packages/flask/app.py", line 1799, in dispatch_request
    return self.ensure_sync(self.view_functions[rule.endpoint])(**view_args)
  File "/home/abdulaziz/abdulaziz/courses/udacity/nd/fyyur/app.py", line 495, in shows
    artist = Artist.query.filter_by(artist_id)
TypeError: Query.filter_by() takes 1 positional argument but 2 were given
2023-04-08 13:42:01,392 INFO: errors [in /home/abdulaziz/abdulaziz/courses/udacity/nd/fyyur/app.py:555]
2023-04-08 13:42:04,499 ERROR: Exception on /shows [GET] [in /home/abdulaziz/abdulaziz/courses/udacity/nd/fyyur/udacity_nd/lib/python3.10/site-packages/flask/app.py:1744]
Traceback (most recent call last):
  File "/home/abdulaziz/abdulaziz/courses/udacity/nd/fyyur/udacity_nd/lib/python3.10/site-packages/flask/app.py", line 2528, in wsgi_app
    response = self.full_dispatch_request()
  File "/home/abdulaziz/abdulaziz/courses/udacity/nd/fyyur/udacity_nd/lib/python3.10/site-packages/flask/app.py", line 1825, in full_dispatch_request
    rv = self.handle_user_exception(e)
  File "/home/abdulaziz/abdulaziz/courses/udacity/nd/fyyur/udacity_nd/lib/python3.10/site-packages/flask/app.py", line 1823, in full_dispatch_request
    rv = self.dispatch_request()
  File "/home/abdulaziz/abdulaziz/courses/udacity/nd/fyyur/udacity_nd/lib/python3.10/site-packages/flask/app.py", line 1799, in dispatch_request
    return self.ensure_sync(self.view_functions[rule.endpoint])(**view_args)
  File "/home/abdulaziz/abdulaziz/courses/udacity/nd/fyyur/app.py", line 499, in shows
    "venue_name": venue.name,
AttributeError: 'Query' object has no attribute 'name'
2023-04-08 13:42:26,951 INFO: errors [in /home/abdulaziz/abdulaziz/courses/udacity/nd/fyyur/app.py:557]
2023-04-08 13:42:29,305 ERROR: Exception on /shows [GET] [in /home/abdulaziz/abdulaziz/courses/udacity/nd/fyyur/udacity_nd/lib/python3.10/site-packages/flask/app.py:1744]
Traceback (most recent call last):
  File "/home/abdulaziz/abdulaziz/courses/udacity/nd/fyyur/udacity_nd/lib/python3.10/site-packages/flask/app.py", line 2528, in wsgi_app
    response = self.full_dispatch_request()
  File "/home/abdulaziz/abdulaziz/courses/udacity/nd/fyyur/udacity_nd/lib/python3.10/site-packages/flask/app.py", line 1825, in full_dispatch_request
    rv = self.handle_user_exception(e)
  File "/home/abdulaziz/abdulaziz/courses/udacity/nd/fyyur/udacity_nd/lib/python3.10/site-packages/flask/app.py", line 1823, in full_dispatch_request
    rv = self.dispatch_request()
  File "/home/abdulaziz/abdulaziz/courses/udacity/nd/fyyur/udacity_nd/lib/python3.10/site-packages/flask/app.py", line 1799, in dispatch_request
    return self.ensure_sync(self.view_functions[rule.endpoint])(**view_args)
  File "/home/abdulaziz/abdulaziz/courses/udacity/nd/fyyur/app.py", line 501, in shows
    "venue_name": venue.name,
AttributeError: 'Query' object has no attribute 'name'
2023-04-08 13:42:54,983 INFO: errors [in /home/abdulaziz/abdulaziz/courses/udacity/nd/fyyur/app.py:557]
2023-04-08 13:42:57,390 ERROR: Exception on /shows [GET] [in /home/abdulaziz/abdulaziz/courses/udacity/nd/fyyur/udacity_nd/lib/python3.10/site-packages/flask/app.py:1744]
Traceback (most recent call last):
  File "/home/abdulaziz/abdulaziz/courses/udacity/nd/fyyur/udacity_nd/lib/python3.10/site-packages/flask/app.py", line 2528, in wsgi_app
    response = self.full_dispatch_request()
  File "/home/abdulaziz/abdulaziz/courses/udacity/nd/fyyur/udacity_nd/lib/python3.10/site-packages/flask/app.py", line 1825, in full_dispatch_request
    rv = self.handle_user_exception(e)
  File "/home/abdulaziz/abdulaziz/courses/udacity/nd/fyyur/udacity_nd/lib/python3.10/site-packages/flask/app.py", line 1823, in full_dispatch_request
    rv = self.dispatch_request()
  File "/home/abdulaziz/abdulaziz/courses/udacity/nd/fyyur/udacity_nd/lib/python3.10/site-packages/flask/app.py", line 1799, in dispatch_request
    return self.ensure_sync(self.view_functions[rule.endpoint])(**view_args)
  File "/home/abdulaziz/abdulaziz/courses/udacity/nd/fyyur/app.py", line 501, in shows
    "venue_name": venue.name,
AttributeError: 'Query' object has no attribute 'name'
2023-04-08 13:43:46,936 INFO: errors [in /home/abdulaziz/abdulaziz/courses/udacity/nd/fyyur/app.py:558]
2023-04-08 13:43:48,446 ERROR: Exception on /shows [GET] [in /home/abdulaziz/abdulaziz/courses/udacity/nd/fyyur/udacity_nd/lib/python3.10/site-packages/flask/app.py:1744]
Traceback (most recent call last):
  File "/home/abdulaziz/abdulaziz/courses/udacity/nd/fyyur/udacity_nd/lib/python3.10/site-packages/flask/app.py", line 2528, in wsgi_app
    response = self.full_dispatch_request()
  File "/home/abdulaziz/abdulaziz/courses/udacity/nd/fyyur/udacity_nd/lib/python3.10/site-packages/flask/app.py", line 1825, in full_dispatch_request
    rv = self.handle_user_exception(e)
  File "/home/abdulaziz/abdulaziz/courses/udacity/nd/fyyur/udacity_nd/lib/python3.10/site-packages/flask/app.py", line 1823, in full_dispatch_request
    rv = self.dispatch_request()
  File "/home/abdulaziz/abdulaziz/courses/udacity/nd/fyyur/udacity_nd/lib/python3.10/site-packages/flask/app.py", line 1799, in dispatch_request
    return self.ensure_sync(self.view_functions[rule.endpoint])(**view_args)
  File "/home/abdulaziz/abdulaziz/courses/udacity/nd/fyyur/app.py", line 502, in shows
    "venue_name": venue.name,
AttributeError: 'Query' object has no attribute 'name'
2023-04-08 13:44:05,246 ERROR: Exception on /shows [GET] [in /home/abdulaziz/abdulaziz/courses/udacity/nd/fyyur/udacity_nd/lib/python3.10/site-packages/flask/app.py:1744]
Traceback (most recent call last):
  File "/home/abdulaziz/abdulaziz/courses/udacity/nd/fyyur/udacity_nd/lib/python3.10/site-packages/flask/app.py", line 2528, in wsgi_app
    response = self.full_dispatch_request()
  File "/home/abdulaziz/abdulaziz/courses/udacity/nd/fyyur/udacity_nd/lib/python3.10/site-packages/flask/app.py", line 1825, in full_dispatch_request
    rv = self.handle_user_exception(e)
  File "/home/abdulaziz/abdulaziz/courses/udacity/nd/fyyur/udacity_nd/lib/python3.10/site-packages/flask/app.py", line 1823, in full_dispatch_request
    rv = self.dispatch_request()
  File "/home/abdulaziz/abdulaziz/courses/udacity/nd/fyyur/udacity_nd/lib/python3.10/site-packages/flask/app.py", line 1799, in dispatch_request
    return self.ensure_sync(self.view_functions[rule.endpoint])(**view_args)
  File "/home/abdulaziz/abdulaziz/courses/udacity/nd/fyyur/app.py", line 502, in shows
    "venue_name": venue.name,
AttributeError: 'Query' object has no attribute 'name'
2023-04-08 13:44:25,458 INFO: errors [in /home/abdulaziz/abdulaziz/courses/udacity/nd/fyyur/app.py:558]
2023-04-08 13:44:26,860 ERROR: Exception on /shows [GET] [in /home/abdulaziz/abdulaziz/courses/udacity/nd/fyyur/udacity_nd/lib/python3.10/site-packages/flask/app.py:1744]
Traceback (most recent call last):
  File "/home/abdulaziz/abdulaziz/courses/udacity/nd/fyyur/udacity_nd/lib/python3.10/site-packages/flask/app.py", line 2528, in wsgi_app
    response = self.full_dispatch_request()
  File "/home/abdulaziz/abdulaziz/courses/udacity/nd/fyyur/udacity_nd/lib/python3.10/site-packages/flask/app.py", line 1825, in full_dispatch_request
    rv = self.handle_user_exception(e)
  File "/home/abdulaziz/abdulaziz/courses/udacity/nd/fyyur/udacity_nd/lib/python3.10/site-packages/flask/app.py", line 1823, in full_dispatch_request
    rv = self.dispatch_request()
  File "/home/abdulaziz/abdulaziz/courses/udacity/nd/fyyur/udacity_nd/lib/python3.10/site-packages/flask/app.py", line 1799, in dispatch_request
    return self.ensure_sync(self.view_functions[rule.endpoint])(**view_args)
  File "/home/abdulaziz/abdulaziz/courses/udacity/nd/fyyur/app.py", line 502, in shows
    "venue_name": venue.name,
AttributeError: 'Query' object has no attribute 'name'
2023-04-08 13:44:41,873 ERROR: Exception on /shows [GET] [in /home/abdulaziz/abdulaziz/courses/udacity/nd/fyyur/udacity_nd/lib/python3.10/site-packages/flask/app.py:1744]
Traceback (most recent call last):
  File "/home/abdulaziz/abdulaziz/courses/udacity/nd/fyyur/udacity_nd/lib/python3.10/site-packages/flask/app.py", line 2528, in wsgi_app
    response = self.full_dispatch_request()
  File "/home/abdulaziz/abdulaziz/courses/udacity/nd/fyyur/udacity_nd/lib/python3.10/site-packages/flask/app.py", line 1825, in full_dispatch_request
    rv = self.handle_user_exception(e)
  File "/home/abdulaziz/abdulaziz/courses/udacity/nd/fyyur/udacity_nd/lib/python3.10/site-packages/flask/app.py", line 1823, in full_dispatch_request
    rv = self.dispatch_request()
  File "/home/abdulaziz/abdulaziz/courses/udacity/nd/fyyur/udacity_nd/lib/python3.10/site-packages/flask/app.py", line 1799, in dispatch_request
    return self.ensure_sync(self.view_functions[rule.endpoint])(**view_args)
  File "/home/abdulaziz/abdulaziz/courses/udacity/nd/fyyur/app.py", line 502, in shows
    "venue_name": venue.name,
AttributeError: 'Query' object has no attribute 'name'
2023-04-08 13:44:50,692 INFO: errors [in /home/abdulaziz/abdulaziz/courses/udacity/nd/fyyur/app.py:558]
2023-04-08 13:44:52,106 ERROR: Exception on /shows [GET] [in /home/abdulaziz/abdulaziz/courses/udacity/nd/fyyur/udacity_nd/lib/python3.10/site-packages/flask/app.py:1744]
Traceback (most recent call last):
  File "/home/abdulaziz/abdulaziz/courses/udacity/nd/fyyur/udacity_nd/lib/python3.10/site-packages/flask/app.py", line 2528, in wsgi_app
    response = self.full_dispatch_request()
  File "/home/abdulaziz/abdulaziz/courses/udacity/nd/fyyur/udacity_nd/lib/python3.10/site-packages/flask/app.py", line 1825, in full_dispatch_request
    rv = self.handle_user_exception(e)
  File "/home/abdulaziz/abdulaziz/courses/udacity/nd/fyyur/udacity_nd/lib/python3.10/site-packages/flask/app.py", line 1823, in full_dispatch_request
    rv = self.dispatch_request()
  File "/home/abdulaziz/abdulaziz/courses/udacity/nd/fyyur/udacity_nd/lib/python3.10/site-packages/flask/app.py", line 1799, in dispatch_request
    return self.ensure_sync(self.view_functions[rule.endpoint])(**view_args)
  File "/home/abdulaziz/abdulaziz/courses/udacity/nd/fyyur/app.py", line 502, in shows
    "venue_name": venue.name,
AttributeError: 'Query' object has no attribute 'name'
2023-04-08 13:46:01,836 INFO: errors [in /home/abdulaziz/abdulaziz/courses/udacity/nd/fyyur/app.py:558]
2023-04-08 13:46:09,785 INFO: errors [in /home/abdulaziz/abdulaziz/courses/udacity/nd/fyyur/app.py:558]
2023-04-08 13:46:11,159 ERROR: Exception on /shows [GET] [in /home/abdulaziz/abdulaziz/courses/udacity/nd/fyyur/udacity_nd/lib/python3.10/site-packages/flask/app.py:1744]
Traceback (most recent call last):
  File "/home/abdulaziz/abdulaziz/courses/udacity/nd/fyyur/udacity_nd/lib/python3.10/site-packages/flask/app.py", line 2528, in wsgi_app
    response = self.full_dispatch_request()
  File "/home/abdulaziz/abdulaziz/courses/udacity/nd/fyyur/udacity_nd/lib/python3.10/site-packages/flask/app.py", line 1825, in full_dispatch_request
    rv = self.handle_user_exception(e)
  File "/home/abdulaziz/abdulaziz/courses/udacity/nd/fyyur/udacity_nd/lib/python3.10/site-packages/flask/app.py", line 1823, in full_dispatch_request
    rv = self.dispatch_request()
  File "/home/abdulaziz/abdulaziz/courses/udacity/nd/fyyur/udacity_nd/lib/python3.10/site-packages/flask/app.py", line 1799, in dispatch_request
    return self.ensure_sync(self.view_functions[rule.endpoint])(**view_args)
  File "/home/abdulaziz/abdulaziz/courses/udacity/nd/fyyur/app.py", line 496, in shows
    artist = Artist.query.filter_by(id==artist_id)
TypeError: Query.filter_by() takes 1 positional argument but 2 were given
2023-04-08 13:46:32,465 INFO: errors [in /home/abdulaziz/abdulaziz/courses/udacity/nd/fyyur/app.py:558]
2023-04-08 13:46:34,509 ERROR: Exception on /shows [GET] [in /home/abdulaziz/abdulaziz/courses/udacity/nd/fyyur/udacity_nd/lib/python3.10/site-packages/flask/app.py:1744]
Traceback (most recent call last):
  File "/home/abdulaziz/abdulaziz/courses/udacity/nd/fyyur/udacity_nd/lib/python3.10/site-packages/flask/app.py", line 2528, in wsgi_app
    response = self.full_dispatch_request()
  File "/home/abdulaziz/abdulaziz/courses/udacity/nd/fyyur/udacity_nd/lib/python3.10/site-packages/flask/app.py", line 1825, in full_dispatch_request
    rv = self.handle_user_exception(e)
  File "/home/abdulaziz/abdulaziz/courses/udacity/nd/fyyur/udacity_nd/lib/python3.10/site-packages/flask/app.py", line 1823, in full_dispatch_request
    rv = self.dispatch_request()
  File "/home/abdulaziz/abdulaziz/courses/udacity/nd/fyyur/udacity_nd/lib/python3.10/site-packages/flask/app.py", line 1799, in dispatch_request
    return self.ensure_sync(self.view_functions[rule.endpoint])(**view_args)
  File "/home/abdulaziz/abdulaziz/courses/udacity/nd/fyyur/app.py", line 502, in shows
    "venue_name": venue.name,
AttributeError: 'Query' object has no attribute 'name'
2023-04-08 13:46:57,524 ERROR: Exception on /shows [GET] [in /home/abdulaziz/abdulaziz/courses/udacity/nd/fyyur/udacity_nd/lib/python3.10/site-packages/flask/app.py:1744]
Traceback (most recent call last):
  File "/home/abdulaziz/abdulaziz/courses/udacity/nd/fyyur/udacity_nd/lib/python3.10/site-packages/flask/app.py", line 2528, in wsgi_app
    response = self.full_dispatch_request()
  File "/home/abdulaziz/abdulaziz/courses/udacity/nd/fyyur/udacity_nd/lib/python3.10/site-packages/flask/app.py", line 1825, in full_dispatch_request
    rv = self.handle_user_exception(e)
  File "/home/abdulaziz/abdulaziz/courses/udacity/nd/fyyur/udacity_nd/lib/python3.10/site-packages/flask/app.py", line 1823, in full_dispatch_request
    rv = self.dispatch_request()
  File "/home/abdulaziz/abdulaziz/courses/udacity/nd/fyyur/udacity_nd/lib/python3.10/site-packages/flask/app.py", line 1799, in dispatch_request
    return self.ensure_sync(self.view_functions[rule.endpoint])(**view_args)
  File "/home/abdulaziz/abdulaziz/courses/udacity/nd/fyyur/app.py", line 502, in shows
    "artist_id": show.artist_id,
AttributeError: 'Query' object has no attribute 'name'
2023-04-08 13:47:06,894 INFO: errors [in /home/abdulaziz/abdulaziz/courses/udacity/nd/fyyur/app.py:557]
2023-04-08 13:47:08,111 ERROR: Exception on /shows [GET] [in /home/abdulaziz/abdulaziz/courses/udacity/nd/fyyur/udacity_nd/lib/python3.10/site-packages/flask/app.py:1744]
Traceback (most recent call last):
  File "/home/abdulaziz/abdulaziz/courses/udacity/nd/fyyur/udacity_nd/lib/python3.10/site-packages/flask/app.py", line 2528, in wsgi_app
    response = self.full_dispatch_request()
  File "/home/abdulaziz/abdulaziz/courses/udacity/nd/fyyur/udacity_nd/lib/python3.10/site-packages/flask/app.py", line 1825, in full_dispatch_request
    rv = self.handle_user_exception(e)
  File "/home/abdulaziz/abdulaziz/courses/udacity/nd/fyyur/udacity_nd/lib/python3.10/site-packages/flask/app.py", line 1823, in full_dispatch_request
    rv = self.dispatch_request()
  File "/home/abdulaziz/abdulaziz/courses/udacity/nd/fyyur/udacity_nd/lib/python3.10/site-packages/flask/app.py", line 1799, in dispatch_request
    return self.ensure_sync(self.view_functions[rule.endpoint])(**view_args)
  File "/home/abdulaziz/abdulaziz/courses/udacity/nd/fyyur/app.py", line 501, in shows
    "venue_name": venue.name,
AttributeError: 'Query' object has no attribute 'name'
2023-04-08 13:48:03,772 INFO: errors [in /home/abdulaziz/abdulaziz/courses/udacity/nd/fyyur/app.py:551]
2023-04-08 13:48:05,978 ERROR: Exception on /shows [GET] [in /home/abdulaziz/abdulaziz/courses/udacity/nd/fyyur/udacity_nd/lib/python3.10/site-packages/flask/app.py:1744]
Traceback (most recent call last):
  File "/home/abdulaziz/abdulaziz/courses/udacity/nd/fyyur/udacity_nd/lib/python3.10/site-packages/flask/app.py", line 2528, in wsgi_app
    response = self.full_dispatch_request()
  File "/home/abdulaziz/abdulaziz/courses/udacity/nd/fyyur/udacity_nd/lib/python3.10/site-packages/flask/app.py", line 1825, in full_dispatch_request
    rv = self.handle_user_exception(e)
  File "/home/abdulaziz/abdulaziz/courses/udacity/nd/fyyur/udacity_nd/lib/python3.10/site-packages/flask/app.py", line 1823, in full_dispatch_request
    rv = self.dispatch_request()
  File "/home/abdulaziz/abdulaziz/courses/udacity/nd/fyyur/udacity_nd/lib/python3.10/site-packages/flask/app.py", line 1799, in dispatch_request
    return self.ensure_sync(self.view_functions[rule.endpoint])(**view_args)
  File "/home/abdulaziz/abdulaziz/courses/udacity/nd/fyyur/app.py", line 502, in shows
    return render_template('pages/shows.html', shows=data)
  File "/home/abdulaziz/abdulaziz/courses/udacity/nd/fyyur/udacity_nd/lib/python3.10/site-packages/flask/templating.py", line 147, in render_template
    return _render(app, template, context)
  File "/home/abdulaziz/abdulaziz/courses/udacity/nd/fyyur/udacity_nd/lib/python3.10/site-packages/flask/templating.py", line 130, in _render
    rv = template.render(context)
  File "/home/abdulaziz/abdulaziz/courses/udacity/nd/fyyur/udacity_nd/lib/python3.10/site-packages/jinja2/environment.py", line 1301, in render
    self.environment.handle_exception()
  File "/home/abdulaziz/abdulaziz/courses/udacity/nd/fyyur/udacity_nd/lib/python3.10/site-packages/jinja2/environment.py", line 936, in handle_exception
    raise rewrite_traceback_stack(source=source)
  File "/home/abdulaziz/abdulaziz/courses/udacity/nd/fyyur/templates/pages/shows.html", line 1, in top-level template code
    {% extends 'layouts/main.html' %}
  File "/home/abdulaziz/abdulaziz/courses/udacity/nd/fyyur/templates/layouts/main.html", line 103, in top-level template code
    {% block content %}{% endblock %}
  File "/home/abdulaziz/abdulaziz/courses/udacity/nd/fyyur/templates/pages/shows.html", line 9, in block 'content'
    <h4>{{ show.start_time|datetime('full') }}</h4>
  File "/home/abdulaziz/abdulaziz/courses/udacity/nd/fyyur/app.py", line 83, in format_datetime
    date = dateutil.parser.parse(value)
  File "/home/abdulaziz/abdulaziz/courses/udacity/nd/fyyur/udacity_nd/lib/python3.10/site-packages/dateutil/parser/_parser.py", line 1368, in parse
    return DEFAULTPARSER.parse(timestr, **kwargs)
  File "/home/abdulaziz/abdulaziz/courses/udacity/nd/fyyur/udacity_nd/lib/python3.10/site-packages/dateutil/parser/_parser.py", line 640, in parse
    res, skipped_tokens = self._parse(timestr, **kwargs)
  File "/home/abdulaziz/abdulaziz/courses/udacity/nd/fyyur/udacity_nd/lib/python3.10/site-packages/dateutil/parser/_parser.py", line 719, in _parse
    l = _timelex.split(timestr)         # Splits the timestr into tokens
  File "/home/abdulaziz/abdulaziz/courses/udacity/nd/fyyur/udacity_nd/lib/python3.10/site-packages/dateutil/parser/_parser.py", line 201, in split
    return list(cls(s))
  File "/home/abdulaziz/abdulaziz/courses/udacity/nd/fyyur/udacity_nd/lib/python3.10/site-packages/dateutil/parser/_parser.py", line 69, in __init__
    raise TypeError('Parser must be a string or character stream, not '
TypeError: Parser must be a string or character stream, not datetime
2023-04-08 14:07:28,854 INFO: errors [in /home/abdulaziz/abdulaziz/courses/udacity/nd/fyyur/app.py:551]
2023-04-08 14:07:33,551 ERROR: Exception on /shows [GET] [in /home/abdulaziz/abdulaziz/courses/udacity/nd/fyyur/udacity_nd/lib/python3.10/site-packages/flask/app.py:1744]
Traceback (most recent call last):
  File "/home/abdulaziz/abdulaziz/courses/udacity/nd/fyyur/udacity_nd/lib/python3.10/site-packages/flask/app.py", line 2528, in wsgi_app
    response = self.full_dispatch_request()
  File "/home/abdulaziz/abdulaziz/courses/udacity/nd/fyyur/udacity_nd/lib/python3.10/site-packages/flask/app.py", line 1825, in full_dispatch_request
    rv = self.handle_user_exception(e)
  File "/home/abdulaziz/abdulaziz/courses/udacity/nd/fyyur/udacity_nd/lib/python3.10/site-packages/flask/app.py", line 1823, in full_dispatch_request
    rv = self.dispatch_request()
  File "/home/abdulaziz/abdulaziz/courses/udacity/nd/fyyur/udacity_nd/lib/python3.10/site-packages/flask/app.py", line 1799, in dispatch_request
    return self.ensure_sync(self.view_functions[rule.endpoint])(**view_args)
  File "/home/abdulaziz/abdulaziz/courses/udacity/nd/fyyur/app.py", line 499, in shows
    "start_time": format_datetime(show.start_time)
  File "/home/abdulaziz/abdulaziz/courses/udacity/nd/fyyur/app.py", line 83, in format_datetime
    date = dateutil.parser.parse(value)
  File "/home/abdulaziz/abdulaziz/courses/udacity/nd/fyyur/udacity_nd/lib/python3.10/site-packages/dateutil/parser/_parser.py", line 1368, in parse
    return DEFAULTPARSER.parse(timestr, **kwargs)
  File "/home/abdulaziz/abdulaziz/courses/udacity/nd/fyyur/udacity_nd/lib/python3.10/site-packages/dateutil/parser/_parser.py", line 640, in parse
    res, skipped_tokens = self._parse(timestr, **kwargs)
  File "/home/abdulaziz/abdulaziz/courses/udacity/nd/fyyur/udacity_nd/lib/python3.10/site-packages/dateutil/parser/_parser.py", line 719, in _parse
    l = _timelex.split(timestr)         # Splits the timestr into tokens
  File "/home/abdulaziz/abdulaziz/courses/udacity/nd/fyyur/udacity_nd/lib/python3.10/site-packages/dateutil/parser/_parser.py", line 201, in split
    return list(cls(s))
  File "/home/abdulaziz/abdulaziz/courses/udacity/nd/fyyur/udacity_nd/lib/python3.10/site-packages/dateutil/parser/_parser.py", line 69, in __init__
    raise TypeError('Parser must be a string or character stream, not '
TypeError: Parser must be a string or character stream, not datetime
2023-04-08 14:07:49,563 ERROR: Exception on /shows [GET] [in /home/abdulaziz/abdulaziz/courses/udacity/nd/fyyur/udacity_nd/lib/python3.10/site-packages/flask/app.py:1744]
Traceback (most recent call last):
  File "/home/abdulaziz/abdulaziz/courses/udacity/nd/fyyur/udacity_nd/lib/python3.10/site-packages/flask/app.py", line 2528, in wsgi_app
    response = self.full_dispatch_request()
  File "/home/abdulaziz/abdulaziz/courses/udacity/nd/fyyur/udacity_nd/lib/python3.10/site-packages/flask/app.py", line 1825, in full_dispatch_request
    rv = self.handle_user_exception(e)
  File "/home/abdulaziz/abdulaziz/courses/udacity/nd/fyyur/udacity_nd/lib/python3.10/site-packages/flask/app.py", line 1823, in full_dispatch_request
    rv = self.dispatch_request()
  File "/home/abdulaziz/abdulaziz/courses/udacity/nd/fyyur/udacity_nd/lib/python3.10/site-packages/flask/app.py", line 1799, in dispatch_request
    return self.ensure_sync(self.view_functions[rule.endpoint])(**view_args)
  File "/home/abdulaziz/abdulaziz/courses/udacity/nd/fyyur/app.py", line 499, in shows
    "start_time": str(format_datetime(show.start_time)
  File "/home/abdulaziz/abdulaziz/courses/udacity/nd/fyyur/app.py", line 83, in format_datetime
    date = dateutil.parser.parse(value)
  File "/home/abdulaziz/abdulaziz/courses/udacity/nd/fyyur/udacity_nd/lib/python3.10/site-packages/dateutil/parser/_parser.py", line 1368, in parse
    return DEFAULTPARSER.parse(timestr, **kwargs)
  File "/home/abdulaziz/abdulaziz/courses/udacity/nd/fyyur/udacity_nd/lib/python3.10/site-packages/dateutil/parser/_parser.py", line 640, in parse
    res, skipped_tokens = self._parse(timestr, **kwargs)
  File "/home/abdulaziz/abdulaziz/courses/udacity/nd/fyyur/udacity_nd/lib/python3.10/site-packages/dateutil/parser/_parser.py", line 719, in _parse
    l = _timelex.split(timestr)         # Splits the timestr into tokens
  File "/home/abdulaziz/abdulaziz/courses/udacity/nd/fyyur/udacity_nd/lib/python3.10/site-packages/dateutil/parser/_parser.py", line 201, in split
    return list(cls(s))
  File "/home/abdulaziz/abdulaziz/courses/udacity/nd/fyyur/udacity_nd/lib/python3.10/site-packages/dateutil/parser/_parser.py", line 69, in __init__
    raise TypeError('Parser must be a string or character stream, not '
TypeError: Parser must be a string or character stream, not datetime
2023-04-08 14:08:11,383 ERROR: Exception on /shows [GET] [in /home/abdulaziz/abdulaziz/courses/udacity/nd/fyyur/udacity_nd/lib/python3.10/site-packages/flask/app.py:1744]
Traceback (most recent call last):
  File "/home/abdulaziz/abdulaziz/courses/udacity/nd/fyyur/udacity_nd/lib/python3.10/site-packages/flask/app.py", line 2528, in wsgi_app
    response = self.full_dispatch_request()
  File "/home/abdulaziz/abdulaziz/courses/udacity/nd/fyyur/udacity_nd/lib/python3.10/site-packages/flask/app.py", line 1825, in full_dispatch_request
    rv = self.handle_user_exception(e)
  File "/home/abdulaziz/abdulaziz/courses/udacity/nd/fyyur/udacity_nd/lib/python3.10/site-packages/flask/app.py", line 1823, in full_dispatch_request
    rv = self.dispatch_request()
  File "/home/abdulaziz/abdulaziz/courses/udacity/nd/fyyur/udacity_nd/lib/python3.10/site-packages/flask/app.py", line 1799, in dispatch_request
    return self.ensure_sync(self.view_functions[rule.endpoint])(**view_args)
  File "/home/abdulaziz/abdulaziz/courses/udacity/nd/fyyur/app.py", line 499, in shows
    "start_time": format_datetime(str(show.start_time))
  File "/home/abdulaziz/abdulaziz/courses/udacity/nd/fyyur/app.py", line 83, in format_datetime
    date = dateutil.parser.parse(value)
  File "/home/abdulaziz/abdulaziz/courses/udacity/nd/fyyur/udacity_nd/lib/python3.10/site-packages/dateutil/parser/_parser.py", line 1368, in parse
    return DEFAULTPARSER.parse(timestr, **kwargs)
  File "/home/abdulaziz/abdulaziz/courses/udacity/nd/fyyur/udacity_nd/lib/python3.10/site-packages/dateutil/parser/_parser.py", line 640, in parse
    res, skipped_tokens = self._parse(timestr, **kwargs)
  File "/home/abdulaziz/abdulaziz/courses/udacity/nd/fyyur/udacity_nd/lib/python3.10/site-packages/dateutil/parser/_parser.py", line 719, in _parse
    l = _timelex.split(timestr)         # Splits the timestr into tokens
  File "/home/abdulaziz/abdulaziz/courses/udacity/nd/fyyur/udacity_nd/lib/python3.10/site-packages/dateutil/parser/_parser.py", line 201, in split
    return list(cls(s))
  File "/home/abdulaziz/abdulaziz/courses/udacity/nd/fyyur/udacity_nd/lib/python3.10/site-packages/dateutil/parser/_parser.py", line 69, in __init__
    raise TypeError('Parser must be a string or character stream, not '
TypeError: Parser must be a string or character stream, not datetime
2023-04-08 14:08:16,722 INFO: errors [in /home/abdulaziz/abdulaziz/courses/udacity/nd/fyyur/app.py:551]
2023-04-08 14:11:07,612 INFO: errors [in /home/abdulaziz/abdulaziz/courses/udacity/nd/fyyur/app.py:588]
2023-04-08 14:11:32,214 INFO: errors [in /home/abdulaziz/abdulaziz/courses/udacity/nd/fyyur/app.py:551]
2023-04-08 14:11:34,884 ERROR: Exception on /artists/1 [GET] [in /home/abdulaziz/abdulaziz/courses/udacity/nd/fyyur/udacity_nd/lib/python3.10/site-packages/flask/app.py:1744]
Traceback (most recent call last):
  File "/home/abdulaziz/abdulaziz/courses/udacity/nd/fyyur/udacity_nd/lib/python3.10/site-packages/flask/app.py", line 2528, in wsgi_app
    response = self.full_dispatch_request()
  File "/home/abdulaziz/abdulaziz/courses/udacity/nd/fyyur/udacity_nd/lib/python3.10/site-packages/flask/app.py", line 1825, in full_dispatch_request
    rv = self.handle_user_exception(e)
  File "/home/abdulaziz/abdulaziz/courses/udacity/nd/fyyur/udacity_nd/lib/python3.10/site-packages/flask/app.py", line 1823, in full_dispatch_request
    rv = self.dispatch_request()
  File "/home/abdulaziz/abdulaziz/courses/udacity/nd/fyyur/udacity_nd/lib/python3.10/site-packages/flask/app.py", line 1799, in dispatch_request
    return self.ensure_sync(self.view_functions[rule.endpoint])(**view_args)
  File "/home/abdulaziz/abdulaziz/courses/udacity/nd/fyyur/app.py", line 384, in show_artist
    data = list(filter(lambda d: d['id'] == artist_id, [data1, data2, data3]))[0]
IndexError: list index out of range
2023-04-08 15:32:58,101 INFO: errors [in /home/abdulaziz/abdulaziz/courses/udacity/nd/fyyur/app.py:552]
2023-04-08 15:59:41,072 INFO: errors [in /home/abdulaziz/abdulaziz/courses/udacity/nd/fyyur/app.py:565]
2023-04-08 15:59:42,637 ERROR: Exception on /venues [GET] [in /home/abdulaziz/abdulaziz/courses/udacity/nd/fyyur/udacity_nd/lib/python3.10/site-packages/flask/app.py:1744]
Traceback (most recent call last):
  File "/home/abdulaziz/abdulaziz/courses/udacity/nd/fyyur/udacity_nd/lib/python3.10/site-packages/flask/app.py", line 2528, in wsgi_app
    response = self.full_dispatch_request()
  File "/home/abdulaziz/abdulaziz/courses/udacity/nd/fyyur/udacity_nd/lib/python3.10/site-packages/flask/app.py", line 1825, in full_dispatch_request
    rv = self.handle_user_exception(e)
  File "/home/abdulaziz/abdulaziz/courses/udacity/nd/fyyur/udacity_nd/lib/python3.10/site-packages/flask/app.py", line 1823, in full_dispatch_request
    rv = self.dispatch_request()
  File "/home/abdulaziz/abdulaziz/courses/udacity/nd/fyyur/udacity_nd/lib/python3.10/site-packages/flask/app.py", line 1799, in dispatch_request
    return self.ensure_sync(self.view_functions[rule.endpoint])(**view_args)
  File "/home/abdulaziz/abdulaziz/courses/udacity/nd/fyyur/app.py", line 117, in venues
    "city": venuelists.city,
AttributeError: 'Query' object has no attribute 'city'
2023-04-08 16:00:30,564 INFO: errors [in /home/abdulaziz/abdulaziz/courses/udacity/nd/fyyur/app.py:565]
2023-04-08 16:00:31,776 ERROR: Exception on /venues [GET] [in /home/abdulaziz/abdulaziz/courses/udacity/nd/fyyur/udacity_nd/lib/python3.10/site-packages/flask/app.py:1744]
Traceback (most recent call last):
  File "/home/abdulaziz/abdulaziz/courses/udacity/nd/fyyur/udacity_nd/lib/python3.10/site-packages/flask/app.py", line 2528, in wsgi_app
    response = self.full_dispatch_request()
  File "/home/abdulaziz/abdulaziz/courses/udacity/nd/fyyur/udacity_nd/lib/python3.10/site-packages/flask/app.py", line 1825, in full_dispatch_request
    rv = self.handle_user_exception(e)
  File "/home/abdulaziz/abdulaziz/courses/udacity/nd/fyyur/udacity_nd/lib/python3.10/site-packages/flask/app.py", line 1823, in full_dispatch_request
    rv = self.dispatch_request()
  File "/home/abdulaziz/abdulaziz/courses/udacity/nd/fyyur/udacity_nd/lib/python3.10/site-packages/flask/app.py", line 1799, in dispatch_request
    return self.ensure_sync(self.view_functions[rule.endpoint])(**view_args)
  File "/home/abdulaziz/abdulaziz/courses/udacity/nd/fyyur/app.py", line 117, in venues
    "city": venuelists.city,
AttributeError: 'Query' object has no attribute 'city'
2023-04-08 16:01:12,947 INFO: errors [in /home/abdulaziz/abdulaziz/courses/udacity/nd/fyyur/app.py:565]
2023-04-08 16:01:14,174 ERROR: Exception on /venues [GET] [in /home/abdulaziz/abdulaziz/courses/udacity/nd/fyyur/udacity_nd/lib/python3.10/site-packages/flask/app.py:1744]
Traceback (most recent call last):
  File "/home/abdulaziz/abdulaziz/courses/udacity/nd/fyyur/udacity_nd/lib/python3.10/site-packages/flask/app.py", line 2528, in wsgi_app
    response = self.full_dispatch_request()
  File "/home/abdulaziz/abdulaziz/courses/udacity/nd/fyyur/udacity_nd/lib/python3.10/site-packages/flask/app.py", line 1825, in full_dispatch_request
    rv = self.handle_user_exception(e)
  File "/home/abdulaziz/abdulaziz/courses/udacity/nd/fyyur/udacity_nd/lib/python3.10/site-packages/flask/app.py", line 1823, in full_dispatch_request
    rv = self.dispatch_request()
  File "/home/abdulaziz/abdulaziz/courses/udacity/nd/fyyur/udacity_nd/lib/python3.10/site-packages/flask/app.py", line 1799, in dispatch_request
    return self.ensure_sync(self.view_functions[rule.endpoint])(**view_args)
  File "/home/abdulaziz/abdulaziz/courses/udacity/nd/fyyur/app.py", line 117, in venues
    "city": venuelists.city,
AttributeError: 'list' object has no attribute 'city'
2023-04-08 16:02:16,091 INFO: errors [in /home/abdulaziz/abdulaziz/courses/udacity/nd/fyyur/app.py:566]
2023-04-08 16:02:17,246 ERROR: Exception on /venues [GET] [in /home/abdulaziz/abdulaziz/courses/udacity/nd/fyyur/udacity_nd/lib/python3.10/site-packages/flask/app.py:1744]
Traceback (most recent call last):
  File "/home/abdulaziz/abdulaziz/courses/udacity/nd/fyyur/udacity_nd/lib/python3.10/site-packages/flask/app.py", line 2528, in wsgi_app
    response = self.full_dispatch_request()
  File "/home/abdulaziz/abdulaziz/courses/udacity/nd/fyyur/udacity_nd/lib/python3.10/site-packages/flask/app.py", line 1825, in full_dispatch_request
    rv = self.handle_user_exception(e)
  File "/home/abdulaziz/abdulaziz/courses/udacity/nd/fyyur/udacity_nd/lib/python3.10/site-packages/flask/app.py", line 1823, in full_dispatch_request
    rv = self.dispatch_request()
  File "/home/abdulaziz/abdulaziz/courses/udacity/nd/fyyur/udacity_nd/lib/python3.10/site-packages/flask/app.py", line 1799, in dispatch_request
    return self.ensure_sync(self.view_functions[rule.endpoint])(**view_args)
  File "/home/abdulaziz/abdulaziz/courses/udacity/nd/fyyur/app.py", line 118, in venues
    "city": venuelists.city,
AttributeError: 'list' object has no attribute 'city'
2023-04-08 16:03:52,210 INFO: errors [in /home/abdulaziz/abdulaziz/courses/udacity/nd/fyyur/app.py:564]
2023-04-08 16:03:54,448 ERROR: Exception on /venues [GET] [in /home/abdulaziz/abdulaziz/courses/udacity/nd/fyyur/udacity_nd/lib/python3.10/site-packages/flask/app.py:1744]
Traceback (most recent call last):
  File "/home/abdulaziz/abdulaziz/courses/udacity/nd/fyyur/udacity_nd/lib/python3.10/site-packages/flask/app.py", line 2528, in wsgi_app
    response = self.full_dispatch_request()
  File "/home/abdulaziz/abdulaziz/courses/udacity/nd/fyyur/udacity_nd/lib/python3.10/site-packages/flask/app.py", line 1825, in full_dispatch_request
    rv = self.handle_user_exception(e)
  File "/home/abdulaziz/abdulaziz/courses/udacity/nd/fyyur/udacity_nd/lib/python3.10/site-packages/flask/app.py", line 1823, in full_dispatch_request
    rv = self.dispatch_request()
  File "/home/abdulaziz/abdulaziz/courses/udacity/nd/fyyur/udacity_nd/lib/python3.10/site-packages/flask/app.py", line 1799, in dispatch_request
    return self.ensure_sync(self.view_functions[rule.endpoint])(**view_args)
  File "/home/abdulaziz/abdulaziz/courses/udacity/nd/fyyur/app.py", line 116, in venues
    "city": venuelists.city,
AttributeError: 'list' object has no attribute 'city'
2023-04-08 16:05:09,668 INFO: errors [in /home/abdulaziz/abdulaziz/courses/udacity/nd/fyyur/app.py:565]
2023-04-08 16:05:11,949 ERROR: Exception on /venues [GET] [in /home/abdulaziz/abdulaziz/courses/udacity/nd/fyyur/udacity_nd/lib/python3.10/site-packages/flask/app.py:1744]
Traceback (most recent call last):
  File "/home/abdulaziz/abdulaziz/courses/udacity/nd/fyyur/udacity_nd/lib/python3.10/site-packages/flask/app.py", line 2528, in wsgi_app
    response = self.full_dispatch_request()
  File "/home/abdulaziz/abdulaziz/courses/udacity/nd/fyyur/udacity_nd/lib/python3.10/site-packages/flask/app.py", line 1825, in full_dispatch_request
    rv = self.handle_user_exception(e)
  File "/home/abdulaziz/abdulaziz/courses/udacity/nd/fyyur/udacity_nd/lib/python3.10/site-packages/flask/app.py", line 1823, in full_dispatch_request
    rv = self.dispatch_request()
  File "/home/abdulaziz/abdulaziz/courses/udacity/nd/fyyur/udacity_nd/lib/python3.10/site-packages/flask/app.py", line 1799, in dispatch_request
    return self.ensure_sync(self.view_functions[rule.endpoint])(**view_args)
  File "/home/abdulaziz/abdulaziz/courses/udacity/nd/fyyur/app.py", line 117, in venues
    "city": result[0].city,
AttributeError: 'str' object has no attribute 'city'
2023-04-08 16:05:32,667 INFO: errors [in /home/abdulaziz/abdulaziz/courses/udacity/nd/fyyur/app.py:568]
2023-04-08 16:05:33,518 ERROR: Exception on /venues [GET] [in /home/abdulaziz/abdulaziz/courses/udacity/nd/fyyur/udacity_nd/lib/python3.10/site-packages/flask/app.py:1744]
Traceback (most recent call last):
  File "/home/abdulaziz/abdulaziz/courses/udacity/nd/fyyur/udacity_nd/lib/python3.10/site-packages/flask/app.py", line 2528, in wsgi_app
    response = self.full_dispatch_request()
  File "/home/abdulaziz/abdulaziz/courses/udacity/nd/fyyur/udacity_nd/lib/python3.10/site-packages/flask/app.py", line 1825, in full_dispatch_request
    rv = self.handle_user_exception(e)
  File "/home/abdulaziz/abdulaziz/courses/udacity/nd/fyyur/udacity_nd/lib/python3.10/site-packages/flask/app.py", line 1823, in full_dispatch_request
    rv = self.dispatch_request()
  File "/home/abdulaziz/abdulaziz/courses/udacity/nd/fyyur/udacity_nd/lib/python3.10/site-packages/flask/app.py", line 1799, in dispatch_request
    return self.ensure_sync(self.view_functions[rule.endpoint])(**view_args)
  File "/home/abdulaziz/abdulaziz/courses/udacity/nd/fyyur/app.py", line 120, in venues
    "city": result[0].city,
AttributeError: 'str' object has no attribute 'city'
2023-04-08 16:05:49,393 INFO: errors [in /home/abdulaziz/abdulaziz/courses/udacity/nd/fyyur/app.py:568]
2023-04-08 16:09:05,534 INFO: errors [in /home/abdulaziz/abdulaziz/courses/udacity/nd/fyyur/app.py:572]
2023-04-08 16:09:07,476 ERROR: Exception on /venues [GET] [in /home/abdulaziz/abdulaziz/courses/udacity/nd/fyyur/udacity_nd/lib/python3.10/site-packages/flask/app.py:1744]
Traceback (most recent call last):
  File "/home/abdulaziz/abdulaziz/courses/udacity/nd/fyyur/udacity_nd/lib/python3.10/site-packages/flask/app.py", line 2528, in wsgi_app
    response = self.full_dispatch_request()
  File "/home/abdulaziz/abdulaziz/courses/udacity/nd/fyyur/udacity_nd/lib/python3.10/site-packages/flask/app.py", line 1825, in full_dispatch_request
    rv = self.handle_user_exception(e)
  File "/home/abdulaziz/abdulaziz/courses/udacity/nd/fyyur/udacity_nd/lib/python3.10/site-packages/flask/app.py", line 1823, in full_dispatch_request
    rv = self.dispatch_request()
  File "/home/abdulaziz/abdulaziz/courses/udacity/nd/fyyur/udacity_nd/lib/python3.10/site-packages/flask/app.py", line 1799, in dispatch_request
    return self.ensure_sync(self.view_functions[rule.endpoint])(**view_args)
  File "/home/abdulaziz/abdulaziz/courses/udacity/nd/fyyur/app.py", line 124, in venues
    shows = Show.query.filter_by(venue_id=venue.id).all()
AttributeError: 'list' object has no attribute 'id'
2023-04-08 16:09:22,235 INFO: errors [in /home/abdulaziz/abdulaziz/courses/udacity/nd/fyyur/app.py:572]
2023-04-08 16:09:23,157 ERROR: Exception on /venues [GET] [in /home/abdulaziz/abdulaziz/courses/udacity/nd/fyyur/udacity_nd/lib/python3.10/site-packages/flask/app.py:1744]
Traceback (most recent call last):
  File "/home/abdulaziz/abdulaziz/courses/udacity/nd/fyyur/udacity_nd/lib/python3.10/site-packages/flask/app.py", line 2528, in wsgi_app
    response = self.full_dispatch_request()
  File "/home/abdulaziz/abdulaziz/courses/udacity/nd/fyyur/udacity_nd/lib/python3.10/site-packages/flask/app.py", line 1825, in full_dispatch_request
    rv = self.handle_user_exception(e)
  File "/home/abdulaziz/abdulaziz/courses/udacity/nd/fyyur/udacity_nd/lib/python3.10/site-packages/flask/app.py", line 1823, in full_dispatch_request
    rv = self.dispatch_request()
  File "/home/abdulaziz/abdulaziz/courses/udacity/nd/fyyur/udacity_nd/lib/python3.10/site-packages/flask/app.py", line 1799, in dispatch_request
    return self.ensure_sync(self.view_functions[rule.endpoint])(**view_args)
  File "/home/abdulaziz/abdulaziz/courses/udacity/nd/fyyur/app.py", line 124, in venues
    shows = Show.query.filter_by(venue_id=venue.id).all()
AttributeError: 'list' object has no attribute 'id'
2023-04-08 16:09:40,352 INFO: errors [in /home/abdulaziz/abdulaziz/courses/udacity/nd/fyyur/app.py:572]
2023-04-08 16:09:42,310 ERROR: Exception on /venues [GET] [in /home/abdulaziz/abdulaziz/courses/udacity/nd/fyyur/udacity_nd/lib/python3.10/site-packages/flask/app.py:1744]
Traceback (most recent call last):
  File "/home/abdulaziz/abdulaziz/courses/udacity/nd/fyyur/udacity_nd/lib/python3.10/site-packages/flask/app.py", line 2528, in wsgi_app
    response = self.full_dispatch_request()
  File "/home/abdulaziz/abdulaziz/courses/udacity/nd/fyyur/udacity_nd/lib/python3.10/site-packages/flask/app.py", line 1825, in full_dispatch_request
    rv = self.handle_user_exception(e)
  File "/home/abdulaziz/abdulaziz/courses/udacity/nd/fyyur/udacity_nd/lib/python3.10/site-packages/flask/app.py", line 1823, in full_dispatch_request
    rv = self.dispatch_request()
  File "/home/abdulaziz/abdulaziz/courses/udacity/nd/fyyur/udacity_nd/lib/python3.10/site-packages/flask/app.py", line 1799, in dispatch_request
    return self.ensure_sync(self.view_functions[rule.endpoint])(**view_args)
  File "/home/abdulaziz/abdulaziz/courses/udacity/nd/fyyur/app.py", line 124, in venues
    shows = Show.query.filter_by(venue_id=venue.id).all()
AttributeError: 'list' object has no attribute 'id'
2023-04-08 16:09:55,871 INFO: errors [in /home/abdulaziz/abdulaziz/courses/udacity/nd/fyyur/app.py:572]
2023-04-08 16:09:56,830 ERROR: Exception on /venues [GET] [in /home/abdulaziz/abdulaziz/courses/udacity/nd/fyyur/udacity_nd/lib/python3.10/site-packages/flask/app.py:1744]
Traceback (most recent call last):
  File "/home/abdulaziz/abdulaziz/courses/udacity/nd/fyyur/udacity_nd/lib/python3.10/site-packages/flask/app.py", line 2528, in wsgi_app
    response = self.full_dispatch_request()
  File "/home/abdulaziz/abdulaziz/courses/udacity/nd/fyyur/udacity_nd/lib/python3.10/site-packages/flask/app.py", line 1825, in full_dispatch_request
    rv = self.handle_user_exception(e)
  File "/home/abdulaziz/abdulaziz/courses/udacity/nd/fyyur/udacity_nd/lib/python3.10/site-packages/flask/app.py", line 1823, in full_dispatch_request
    rv = self.dispatch_request()
  File "/home/abdulaziz/abdulaziz/courses/udacity/nd/fyyur/udacity_nd/lib/python3.10/site-packages/flask/app.py", line 1799, in dispatch_request
    return self.ensure_sync(self.view_functions[rule.endpoint])(**view_args)
  File "/home/abdulaziz/abdulaziz/courses/udacity/nd/fyyur/app.py", line 124, in venues
    shows = Show.query.filter_by(venue_id=venue.id).all()
AttributeError: 'list' object has no attribute 'id'
2023-04-08 16:10:34,721 INFO: errors [in /home/abdulaziz/abdulaziz/courses/udacity/nd/fyyur/app.py:569]
2023-04-08 16:15:07,681 INFO: errors [in /home/abdulaziz/abdulaziz/courses/udacity/nd/fyyur/app.py:556]
2023-04-08 16:15:13,239 ERROR: Exception on /venues [GET] [in /home/abdulaziz/abdulaziz/courses/udacity/nd/fyyur/udacity_nd/lib/python3.10/site-packages/flask/app.py:1744]
Traceback (most recent call last):
  File "/home/abdulaziz/abdulaziz/courses/udacity/nd/fyyur/udacity_nd/lib/python3.10/site-packages/flask/app.py", line 2528, in wsgi_app
    response = self.full_dispatch_request()
  File "/home/abdulaziz/abdulaziz/courses/udacity/nd/fyyur/udacity_nd/lib/python3.10/site-packages/flask/app.py", line 1825, in full_dispatch_request
    rv = self.handle_user_exception(e)
  File "/home/abdulaziz/abdulaziz/courses/udacity/nd/fyyur/udacity_nd/lib/python3.10/site-packages/flask/app.py", line 1823, in full_dispatch_request
    rv = self.dispatch_request()
  File "/home/abdulaziz/abdulaziz/courses/udacity/nd/fyyur/udacity_nd/lib/python3.10/site-packages/flask/app.py", line 1799, in dispatch_request
    return self.ensure_sync(self.view_functions[rule.endpoint])(**view_args)
  File "/home/abdulaziz/abdulaziz/courses/udacity/nd/fyyur/app.py", line 121, in venues
    shows = Show.query.filter_by(venue_id=venue.id).all()
AttributeError: 'dict' object has no attribute 'id'
2023-04-08 16:15:40,107 INFO: errors [in /home/abdulaziz/abdulaziz/courses/udacity/nd/fyyur/app.py:557]
2023-04-08 16:15:41,281 ERROR: Exception on /venues [GET] [in /home/abdulaziz/abdulaziz/courses/udacity/nd/fyyur/udacity_nd/lib/python3.10/site-packages/flask/app.py:1744]
Traceback (most recent call last):
  File "/home/abdulaziz/abdulaziz/courses/udacity/nd/fyyur/udacity_nd/lib/python3.10/site-packages/flask/app.py", line 2528, in wsgi_app
    response = self.full_dispatch_request()
  File "/home/abdulaziz/abdulaziz/courses/udacity/nd/fyyur/udacity_nd/lib/python3.10/site-packages/flask/app.py", line 1825, in full_dispatch_request
    rv = self.handle_user_exception(e)
  File "/home/abdulaziz/abdulaziz/courses/udacity/nd/fyyur/udacity_nd/lib/python3.10/site-packages/flask/app.py", line 1823, in full_dispatch_request
    rv = self.dispatch_request()
  File "/home/abdulaziz/abdulaziz/courses/udacity/nd/fyyur/udacity_nd/lib/python3.10/site-packages/flask/app.py", line 1799, in dispatch_request
    return self.ensure_sync(self.view_functions[rule.endpoint])(**view_args)
  File "/home/abdulaziz/abdulaziz/courses/udacity/nd/fyyur/app.py", line 122, in venues
    shows = Show.query.filter_by(venue_id=venue.id).all()
AttributeError: 'dict' object has no attribute 'id'
2023-04-08 16:15:42,074 ERROR: Exception on /venues [GET] [in /home/abdulaziz/abdulaziz/courses/udacity/nd/fyyur/udacity_nd/lib/python3.10/site-packages/flask/app.py:1744]
Traceback (most recent call last):
  File "/home/abdulaziz/abdulaziz/courses/udacity/nd/fyyur/udacity_nd/lib/python3.10/site-packages/flask/app.py", line 2528, in wsgi_app
    response = self.full_dispatch_request()
  File "/home/abdulaziz/abdulaziz/courses/udacity/nd/fyyur/udacity_nd/lib/python3.10/site-packages/flask/app.py", line 1825, in full_dispatch_request
    rv = self.handle_user_exception(e)
  File "/home/abdulaziz/abdulaziz/courses/udacity/nd/fyyur/udacity_nd/lib/python3.10/site-packages/flask/app.py", line 1823, in full_dispatch_request
    rv = self.dispatch_request()
  File "/home/abdulaziz/abdulaziz/courses/udacity/nd/fyyur/udacity_nd/lib/python3.10/site-packages/flask/app.py", line 1799, in dispatch_request
    return self.ensure_sync(self.view_functions[rule.endpoint])(**view_args)
  File "/home/abdulaziz/abdulaziz/courses/udacity/nd/fyyur/app.py", line 122, in venues
    shows = Show.query.filter_by(venue_id=venue.id).all()
AttributeError: 'dict' object has no attribute 'id'
2023-04-08 16:16:01,308 INFO: errors [in /home/abdulaziz/abdulaziz/courses/udacity/nd/fyyur/app.py:557]
2023-04-08 16:16:02,339 ERROR: Exception on /venues [GET] [in /home/abdulaziz/abdulaziz/courses/udacity/nd/fyyur/udacity_nd/lib/python3.10/site-packages/flask/app.py:1744]
Traceback (most recent call last):
  File "/home/abdulaziz/abdulaziz/courses/udacity/nd/fyyur/udacity_nd/lib/python3.10/site-packages/flask/app.py", line 2528, in wsgi_app
    response = self.full_dispatch_request()
  File "/home/abdulaziz/abdulaziz/courses/udacity/nd/fyyur/udacity_nd/lib/python3.10/site-packages/flask/app.py", line 1825, in full_dispatch_request
    rv = self.handle_user_exception(e)
  File "/home/abdulaziz/abdulaziz/courses/udacity/nd/fyyur/udacity_nd/lib/python3.10/site-packages/flask/app.py", line 1823, in full_dispatch_request
    rv = self.dispatch_request()
  File "/home/abdulaziz/abdulaziz/courses/udacity/nd/fyyur/udacity_nd/lib/python3.10/site-packages/flask/app.py", line 1799, in dispatch_request
    return self.ensure_sync(self.view_functions[rule.endpoint])(**view_args)
  File "/home/abdulaziz/abdulaziz/courses/udacity/nd/fyyur/app.py", line 121, in venues
    print(venue[0])
TypeError: 'Venue' object is not subscriptable
2023-04-08 16:16:17,791 INFO: errors [in /home/abdulaziz/abdulaziz/courses/udacity/nd/fyyur/app.py:557]
2023-04-08 16:16:19,570 ERROR: Exception on /venues [GET] [in /home/abdulaziz/abdulaziz/courses/udacity/nd/fyyur/udacity_nd/lib/python3.10/site-packages/flask/app.py:1744]
Traceback (most recent call last):
  File "/home/abdulaziz/abdulaziz/courses/udacity/nd/fyyur/udacity_nd/lib/python3.10/site-packages/flask/app.py", line 2528, in wsgi_app
    response = self.full_dispatch_request()
  File "/home/abdulaziz/abdulaziz/courses/udacity/nd/fyyur/udacity_nd/lib/python3.10/site-packages/flask/app.py", line 1825, in full_dispatch_request
    rv = self.handle_user_exception(e)
  File "/home/abdulaziz/abdulaziz/courses/udacity/nd/fyyur/udacity_nd/lib/python3.10/site-packages/flask/app.py", line 1823, in full_dispatch_request
    rv = self.dispatch_request()
  File "/home/abdulaziz/abdulaziz/courses/udacity/nd/fyyur/udacity_nd/lib/python3.10/site-packages/flask/app.py", line 1799, in dispatch_request
    return self.ensure_sync(self.view_functions[rule.endpoint])(**view_args)
  File "/home/abdulaziz/abdulaziz/courses/udacity/nd/fyyur/app.py", line 121, in venues
    print(venue.id)
AttributeError: 'dict' object has no attribute 'id'
2023-04-08 16:16:33,708 INFO: errors [in /home/abdulaziz/abdulaziz/courses/udacity/nd/fyyur/app.py:557]
2023-04-08 16:16:35,308 ERROR: Exception on /venues [GET] [in /home/abdulaziz/abdulaziz/courses/udacity/nd/fyyur/udacity_nd/lib/python3.10/site-packages/flask/app.py:1744]
Traceback (most recent call last):
  File "/home/abdulaziz/abdulaziz/courses/udacity/nd/fyyur/udacity_nd/lib/python3.10/site-packages/flask/app.py", line 2528, in wsgi_app
    response = self.full_dispatch_request()
  File "/home/abdulaziz/abdulaziz/courses/udacity/nd/fyyur/udacity_nd/lib/python3.10/site-packages/flask/app.py", line 1825, in full_dispatch_request
    rv = self.handle_user_exception(e)
  File "/home/abdulaziz/abdulaziz/courses/udacity/nd/fyyur/udacity_nd/lib/python3.10/site-packages/flask/app.py", line 1823, in full_dispatch_request
    rv = self.dispatch_request()
  File "/home/abdulaziz/abdulaziz/courses/udacity/nd/fyyur/udacity_nd/lib/python3.10/site-packages/flask/app.py", line 1799, in dispatch_request
    return self.ensure_sync(self.view_functions[rule.endpoint])(**view_args)
  File "/home/abdulaziz/abdulaziz/courses/udacity/nd/fyyur/app.py", line 121, in venues
    print(venue.id)
AttributeError: 'dict' object has no attribute 'id'
2023-04-08 16:16:59,363 INFO: errors [in /home/abdulaziz/abdulaziz/courses/udacity/nd/fyyur/app.py:556]
2023-04-08 16:17:00,701 ERROR: Exception on /venues [GET] [in /home/abdulaziz/abdulaziz/courses/udacity/nd/fyyur/udacity_nd/lib/python3.10/site-packages/flask/app.py:1744]
Traceback (most recent call last):
  File "/home/abdulaziz/abdulaziz/courses/udacity/nd/fyyur/udacity_nd/lib/python3.10/site-packages/flask/app.py", line 2528, in wsgi_app
    response = self.full_dispatch_request()
  File "/home/abdulaziz/abdulaziz/courses/udacity/nd/fyyur/udacity_nd/lib/python3.10/site-packages/flask/app.py", line 1825, in full_dispatch_request
    rv = self.handle_user_exception(e)
  File "/home/abdulaziz/abdulaziz/courses/udacity/nd/fyyur/udacity_nd/lib/python3.10/site-packages/flask/app.py", line 1823, in full_dispatch_request
    rv = self.dispatch_request()
  File "/home/abdulaziz/abdulaziz/courses/udacity/nd/fyyur/udacity_nd/lib/python3.10/site-packages/flask/app.py", line 1799, in dispatch_request
    return self.ensure_sync(self.view_functions[rule.endpoint])(**view_args)
  File "/home/abdulaziz/abdulaziz/courses/udacity/nd/fyyur/app.py", line 121, in venues
    shows = Show.query.filter_by(venue_id=venue.id).all()
AttributeError: 'dict' object has no attribute 'id'
2023-04-08 16:17:53,867 INFO: errors [in /home/abdulaziz/abdulaziz/courses/udacity/nd/fyyur/app.py:557]
2023-04-08 16:17:55,318 ERROR: Exception on /venues [GET] [in /home/abdulaziz/abdulaziz/courses/udacity/nd/fyyur/udacity_nd/lib/python3.10/site-packages/flask/app.py:1744]
Traceback (most recent call last):
  File "/home/abdulaziz/abdulaziz/courses/udacity/nd/fyyur/udacity_nd/lib/python3.10/site-packages/flask/app.py", line 2528, in wsgi_app
    response = self.full_dispatch_request()
  File "/home/abdulaziz/abdulaziz/courses/udacity/nd/fyyur/udacity_nd/lib/python3.10/site-packages/flask/app.py", line 1825, in full_dispatch_request
    rv = self.handle_user_exception(e)
  File "/home/abdulaziz/abdulaziz/courses/udacity/nd/fyyur/udacity_nd/lib/python3.10/site-packages/flask/app.py", line 1823, in full_dispatch_request
    rv = self.dispatch_request()
  File "/home/abdulaziz/abdulaziz/courses/udacity/nd/fyyur/udacity_nd/lib/python3.10/site-packages/flask/app.py", line 1799, in dispatch_request
    return self.ensure_sync(self.view_functions[rule.endpoint])(**view_args)
  File "/home/abdulaziz/abdulaziz/courses/udacity/nd/fyyur/app.py", line 121, in venues
    print(venue.id)
AttributeError: 'dict' object has no attribute 'id'
2023-04-08 16:18:07,191 INFO: errors [in /home/abdulaziz/abdulaziz/courses/udacity/nd/fyyur/app.py:557]
2023-04-08 16:18:08,313 ERROR: Exception on /venues [GET] [in /home/abdulaziz/abdulaziz/courses/udacity/nd/fyyur/udacity_nd/lib/python3.10/site-packages/flask/app.py:1744]
Traceback (most recent call last):
  File "/home/abdulaziz/abdulaziz/courses/udacity/nd/fyyur/udacity_nd/lib/python3.10/site-packages/flask/app.py", line 2528, in wsgi_app
    response = self.full_dispatch_request()
  File "/home/abdulaziz/abdulaziz/courses/udacity/nd/fyyur/udacity_nd/lib/python3.10/site-packages/flask/app.py", line 1825, in full_dispatch_request
    rv = self.handle_user_exception(e)
  File "/home/abdulaziz/abdulaziz/courses/udacity/nd/fyyur/udacity_nd/lib/python3.10/site-packages/flask/app.py", line 1823, in full_dispatch_request
    rv = self.dispatch_request()
  File "/home/abdulaziz/abdulaziz/courses/udacity/nd/fyyur/udacity_nd/lib/python3.10/site-packages/flask/app.py", line 1799, in dispatch_request
    return self.ensure_sync(self.view_functions[rule.endpoint])(**view_args)
  File "/home/abdulaziz/abdulaziz/courses/udacity/nd/fyyur/app.py", line 121, in venues
    print(venue["id"])
TypeError: 'Venue' object is not subscriptable
2023-04-08 16:18:17,346 INFO: errors [in /home/abdulaziz/abdulaziz/courses/udacity/nd/fyyur/app.py:557]
2023-04-08 16:18:22,352 ERROR: Exception on /venues [GET] [in /home/abdulaziz/abdulaziz/courses/udacity/nd/fyyur/udacity_nd/lib/python3.10/site-packages/flask/app.py:1744]
Traceback (most recent call last):
  File "/home/abdulaziz/abdulaziz/courses/udacity/nd/fyyur/udacity_nd/lib/python3.10/site-packages/flask/app.py", line 2528, in wsgi_app
    response = self.full_dispatch_request()
  File "/home/abdulaziz/abdulaziz/courses/udacity/nd/fyyur/udacity_nd/lib/python3.10/site-packages/flask/app.py", line 1825, in full_dispatch_request
    rv = self.handle_user_exception(e)
  File "/home/abdulaziz/abdulaziz/courses/udacity/nd/fyyur/udacity_nd/lib/python3.10/site-packages/flask/app.py", line 1823, in full_dispatch_request
    rv = self.dispatch_request()
  File "/home/abdulaziz/abdulaziz/courses/udacity/nd/fyyur/udacity_nd/lib/python3.10/site-packages/flask/app.py", line 1799, in dispatch_request
    return self.ensure_sync(self.view_functions[rule.endpoint])(**view_args)
  File "/home/abdulaziz/abdulaziz/courses/udacity/nd/fyyur/app.py", line 121, in venues
    print(venue)
TypeError: 'Venue' object is not subscriptable
2023-04-08 16:18:29,601 INFO: errors [in /home/abdulaziz/abdulaziz/courses/udacity/nd/fyyur/app.py:557]
2023-04-08 16:18:31,806 ERROR: Exception on /venues [GET] [in /home/abdulaziz/abdulaziz/courses/udacity/nd/fyyur/udacity_nd/lib/python3.10/site-packages/flask/app.py:1744]
Traceback (most recent call last):
  File "/home/abdulaziz/abdulaziz/courses/udacity/nd/fyyur/udacity_nd/lib/python3.10/site-packages/flask/app.py", line 2528, in wsgi_app
    response = self.full_dispatch_request()
  File "/home/abdulaziz/abdulaziz/courses/udacity/nd/fyyur/udacity_nd/lib/python3.10/site-packages/flask/app.py", line 1825, in full_dispatch_request
    rv = self.handle_user_exception(e)
  File "/home/abdulaziz/abdulaziz/courses/udacity/nd/fyyur/udacity_nd/lib/python3.10/site-packages/flask/app.py", line 1823, in full_dispatch_request
    rv = self.dispatch_request()
  File "/home/abdulaziz/abdulaziz/courses/udacity/nd/fyyur/udacity_nd/lib/python3.10/site-packages/flask/app.py", line 1799, in dispatch_request
    return self.ensure_sync(self.view_functions[rule.endpoint])(**view_args)
  File "/home/abdulaziz/abdulaziz/courses/udacity/nd/fyyur/app.py", line 122, in venues
    shows = Show.query.filter_by(venue_id=venue.id).all()
AttributeError: 'dict' object has no attribute 'id'
2023-04-08 16:18:52,018 INFO: errors [in /home/abdulaziz/abdulaziz/courses/udacity/nd/fyyur/app.py:558]
2023-04-08 16:18:53,152 ERROR: Exception on /venues [GET] [in /home/abdulaziz/abdulaziz/courses/udacity/nd/fyyur/udacity_nd/lib/python3.10/site-packages/flask/app.py:1744]
Traceback (most recent call last):
  File "/home/abdulaziz/abdulaziz/courses/udacity/nd/fyyur/udacity_nd/lib/python3.10/site-packages/flask/app.py", line 2528, in wsgi_app
    response = self.full_dispatch_request()
  File "/home/abdulaziz/abdulaziz/courses/udacity/nd/fyyur/udacity_nd/lib/python3.10/site-packages/flask/app.py", line 1825, in full_dispatch_request
    rv = self.handle_user_exception(e)
  File "/home/abdulaziz/abdulaziz/courses/udacity/nd/fyyur/udacity_nd/lib/python3.10/site-packages/flask/app.py", line 1823, in full_dispatch_request
    rv = self.dispatch_request()
  File "/home/abdulaziz/abdulaziz/courses/udacity/nd/fyyur/udacity_nd/lib/python3.10/site-packages/flask/app.py", line 1799, in dispatch_request
    return self.ensure_sync(self.view_functions[rule.endpoint])(**view_args)
  File "/home/abdulaziz/abdulaziz/courses/udacity/nd/fyyur/app.py", line 122, in venues
    shows = Show.query.filter_by(venue_id=venue_id).all()
AttributeError: 'dict' object has no attribute 'id'
2023-04-08 16:19:33,168 INFO: errors [in /home/abdulaziz/abdulaziz/courses/udacity/nd/fyyur/app.py:557]
2023-04-08 16:19:34,341 ERROR: Exception on /venues [GET] [in /home/abdulaziz/abdulaziz/courses/udacity/nd/fyyur/udacity_nd/lib/python3.10/site-packages/flask/app.py:1744]
Traceback (most recent call last):
  File "/home/abdulaziz/abdulaziz/courses/udacity/nd/fyyur/udacity_nd/lib/python3.10/site-packages/flask/app.py", line 2528, in wsgi_app
    response = self.full_dispatch_request()
  File "/home/abdulaziz/abdulaziz/courses/udacity/nd/fyyur/udacity_nd/lib/python3.10/site-packages/flask/app.py", line 1825, in full_dispatch_request
    rv = self.handle_user_exception(e)
  File "/home/abdulaziz/abdulaziz/courses/udacity/nd/fyyur/udacity_nd/lib/python3.10/site-packages/flask/app.py", line 1823, in full_dispatch_request
    rv = self.dispatch_request()
  File "/home/abdulaziz/abdulaziz/courses/udacity/nd/fyyur/udacity_nd/lib/python3.10/site-packages/flask/app.py", line 1799, in dispatch_request
    return self.ensure_sync(self.view_functions[rule.endpoint])(**view_args)
  File "/home/abdulaziz/abdulaziz/courses/udacity/nd/fyyur/app.py", line 121, in venues
    venue_id = venue.id
AttributeError: 'dict' object has no attribute 'id'
2023-04-08 16:24:16,634 INFO: errors [in /home/abdulaziz/abdulaziz/courses/udacity/nd/fyyur/app.py:556]
2023-04-08 16:24:26,485 INFO: errors [in /home/abdulaziz/abdulaziz/courses/udacity/nd/fyyur/app.py:556]
2023-04-08 16:44:40,559 INFO: errors [in /home/abdulaziz/abdulaziz/courses/udacity/nd/fyyur/app.py:556]
2023-04-08 16:57:59,506 ERROR: Exception on /artists/1 [GET] [in /home/abdulaziz/abdulaziz/courses/udacity/nd/fyyur/udacity_nd/lib/python3.10/site-packages/flask/app.py:1744]
Traceback (most recent call last):
  File "/home/abdulaziz/abdulaziz/courses/udacity/nd/fyyur/udacity_nd/lib/python3.10/site-packages/flask/app.py", line 2528, in wsgi_app
    response = self.full_dispatch_request()
  File "/home/abdulaziz/abdulaziz/courses/udacity/nd/fyyur/udacity_nd/lib/python3.10/site-packages/flask/app.py", line 1825, in full_dispatch_request
    rv = self.handle_user_exception(e)
  File "/home/abdulaziz/abdulaziz/courses/udacity/nd/fyyur/udacity_nd/lib/python3.10/site-packages/flask/app.py", line 1823, in full_dispatch_request
    rv = self.dispatch_request()
  File "/home/abdulaziz/abdulaziz/courses/udacity/nd/fyyur/udacity_nd/lib/python3.10/site-packages/flask/app.py", line 1799, in dispatch_request
    return self.ensure_sync(self.view_functions[rule.endpoint])(**view_args)
  File "/home/abdulaziz/abdulaziz/courses/udacity/nd/fyyur/app.py", line 389, in show_artist
    data = list(filter(lambda d: d['id'] == artist_id, [data1, data2, data3]))[0]
IndexError: list index out of range
2023-04-08 17:05:33,219 INFO: errors [in /home/abdulaziz/abdulaziz/courses/udacity/nd/fyyur/app.py:556]
2023-04-08 17:05:46,638 INFO: errors [in /home/abdulaziz/abdulaziz/courses/udacity/nd/fyyur/app.py:556]
2023-04-08 17:12:24,993 INFO: errors [in /home/abdulaziz/abdulaziz/courses/udacity/nd/fyyur/app.py:556]
2023-04-08 17:31:15,837 INFO: errors [in /home/abdulaziz/abdulaziz/courses/udacity/nd/fyyur/app.py:552]
2023-04-08 17:48:18,454 INFO: errors [in /home/abdulaziz/abdulaziz/courses/udacity/nd/fyyur/app.py:487]
2023-04-08 17:48:27,453 ERROR: Exception on /venues/2 [GET] [in /home/abdulaziz/abdulaziz/courses/udacity/nd/fyyur/udacity_nd/lib/python3.10/site-packages/flask/app.py:1744]
Traceback (most recent call last):
  File "/home/abdulaziz/abdulaziz/courses/udacity/nd/fyyur/udacity_nd/lib/python3.10/site-packages/flask/app.py", line 2528, in wsgi_app
    response = self.full_dispatch_request()
  File "/home/abdulaziz/abdulaziz/courses/udacity/nd/fyyur/udacity_nd/lib/python3.10/site-packages/flask/app.py", line 1825, in full_dispatch_request
    rv = self.handle_user_exception(e)
  File "/home/abdulaziz/abdulaziz/courses/udacity/nd/fyyur/udacity_nd/lib/python3.10/site-packages/flask/app.py", line 1823, in full_dispatch_request
    rv = self.dispatch_request()
  File "/home/abdulaziz/abdulaziz/courses/udacity/nd/fyyur/udacity_nd/lib/python3.10/site-packages/flask/app.py", line 1799, in dispatch_request
    return self.ensure_sync(self.view_functions[rule.endpoint])(**view_args)
  File "/home/abdulaziz/abdulaziz/courses/udacity/nd/fyyur/app.py", line 154, in show_venue
    "id": venue.id,
AttributeError: 'list' object has no attribute 'id'
2023-04-08 17:48:39,919 INFO: errors [in /home/abdulaziz/abdulaziz/courses/udacity/nd/fyyur/app.py:487]
2023-04-08 17:48:41,468 ERROR: Exception on /venues/2 [GET] [in /home/abdulaziz/abdulaziz/courses/udacity/nd/fyyur/udacity_nd/lib/python3.10/site-packages/flask/app.py:1744]
Traceback (most recent call last):
  File "/home/abdulaziz/abdulaziz/courses/udacity/nd/fyyur/udacity_nd/lib/python3.10/site-packages/flask/app.py", line 2528, in wsgi_app
    response = self.full_dispatch_request()
  File "/home/abdulaziz/abdulaziz/courses/udacity/nd/fyyur/udacity_nd/lib/python3.10/site-packages/flask/app.py", line 1825, in full_dispatch_request
    rv = self.handle_user_exception(e)
  File "/home/abdulaziz/abdulaziz/courses/udacity/nd/fyyur/udacity_nd/lib/python3.10/site-packages/flask/app.py", line 1823, in full_dispatch_request
    rv = self.dispatch_request()
  File "/home/abdulaziz/abdulaziz/courses/udacity/nd/fyyur/udacity_nd/lib/python3.10/site-packages/flask/app.py", line 1799, in dispatch_request
    return self.ensure_sync(self.view_functions[rule.endpoint])(**view_args)
  File "/home/abdulaziz/abdulaziz/courses/udacity/nd/fyyur/app.py", line 154, in show_venue
    "id": venue.id,
AttributeError: 'Query' object has no attribute 'id'
2023-04-08 17:48:51,028 INFO: errors [in /home/abdulaziz/abdulaziz/courses/udacity/nd/fyyur/app.py:487]
2023-04-08 17:49:04,408 INFO: errors [in /home/abdulaziz/abdulaziz/courses/udacity/nd/fyyur/app.py:488]
2023-04-08 17:49:08,324 ERROR: Exception on /venues/2 [GET] [in /home/abdulaziz/abdulaziz/courses/udacity/nd/fyyur/udacity_nd/lib/python3.10/site-packages/flask/app.py:1744]
Traceback (most recent call last):
  File "/home/abdulaziz/abdulaziz/courses/udacity/nd/fyyur/udacity_nd/lib/python3.10/site-packages/flask/app.py", line 2528, in wsgi_app
    response = self.full_dispatch_request()
  File "/home/abdulaziz/abdulaziz/courses/udacity/nd/fyyur/udacity_nd/lib/python3.10/site-packages/flask/app.py", line 1825, in full_dispatch_request
    rv = self.handle_user_exception(e)
  File "/home/abdulaziz/abdulaziz/courses/udacity/nd/fyyur/udacity_nd/lib/python3.10/site-packages/flask/app.py", line 1823, in full_dispatch_request
    rv = self.dispatch_request()
  File "/home/abdulaziz/abdulaziz/courses/udacity/nd/fyyur/udacity_nd/lib/python3.10/site-packages/flask/app.py", line 1799, in dispatch_request
    return self.ensure_sync(self.view_functions[rule.endpoint])(**view_args)
  File "/home/abdulaziz/abdulaziz/courses/udacity/nd/fyyur/app.py", line 155, in show_venue
    "id": venue.id,
AttributeError: 'list' object has no attribute 'id'
2023-04-08 17:49:21,928 INFO: errors [in /home/abdulaziz/abdulaziz/courses/udacity/nd/fyyur/app.py:487]
2023-04-08 17:53:28,568 INFO: errors [in /home/abdulaziz/abdulaziz/courses/udacity/nd/fyyur/app.py:491]
2023-04-08 18:17:47,540 INFO: errors [in /home/abdulaziz/abdulaziz/courses/udacity/nd/fyyur/app.py:507]
2023-04-08 18:18:06,479 ERROR: Exception on /venues/3 [GET] [in /home/abdulaziz/abdulaziz/courses/udacity/nd/fyyur/udacity_nd/lib/python3.10/site-packages/flask/app.py:1744]
Traceback (most recent call last):
  File "/home/abdulaziz/abdulaziz/courses/udacity/nd/fyyur/udacity_nd/lib/python3.10/site-packages/flask/app.py", line 2528, in wsgi_app
    response = self.full_dispatch_request()
  File "/home/abdulaziz/abdulaziz/courses/udacity/nd/fyyur/udacity_nd/lib/python3.10/site-packages/flask/app.py", line 1825, in full_dispatch_request
    rv = self.handle_user_exception(e)
  File "/home/abdulaziz/abdulaziz/courses/udacity/nd/fyyur/udacity_nd/lib/python3.10/site-packages/flask/app.py", line 1823, in full_dispatch_request
    rv = self.dispatch_request()
  File "/home/abdulaziz/abdulaziz/courses/udacity/nd/fyyur/udacity_nd/lib/python3.10/site-packages/flask/app.py", line 1799, in dispatch_request
    return self.ensure_sync(self.view_functions[rule.endpoint])(**view_args)
  File "/home/abdulaziz/abdulaziz/courses/udacity/nd/fyyur/app.py", line 154, in show_venue
    print(shows[0])
IndexError: list index out of range
2023-04-08 18:27:29,699 INFO: errors [in /home/abdulaziz/abdulaziz/courses/udacity/nd/fyyur/app.py:465]
2023-04-08 18:27:32,402 ERROR: Exception on /artists/5 [GET] [in /home/abdulaziz/abdulaziz/courses/udacity/nd/fyyur/udacity_nd/lib/python3.10/site-packages/flask/app.py:1744]
Traceback (most recent call last):
  File "/home/abdulaziz/abdulaziz/courses/udacity/nd/fyyur/udacity_nd/lib/python3.10/site-packages/flask/app.py", line 2528, in wsgi_app
    response = self.full_dispatch_request()
  File "/home/abdulaziz/abdulaziz/courses/udacity/nd/fyyur/udacity_nd/lib/python3.10/site-packages/flask/app.py", line 1825, in full_dispatch_request
    rv = self.handle_user_exception(e)
  File "/home/abdulaziz/abdulaziz/courses/udacity/nd/fyyur/udacity_nd/lib/python3.10/site-packages/flask/app.py", line 1823, in full_dispatch_request
    rv = self.dispatch_request()
  File "/home/abdulaziz/abdulaziz/courses/udacity/nd/fyyur/udacity_nd/lib/python3.10/site-packages/flask/app.py", line 1799, in dispatch_request
    return self.ensure_sync(self.view_functions[rule.endpoint])(**view_args)
  File "/home/abdulaziz/abdulaziz/courses/udacity/nd/fyyur/app.py", line 268, in show_artist
    shows = Show.query.filter_by(venue_id=venue_id).all()
NameError: name 'venue_id' is not defined
2023-04-08 18:27:50,330 INFO: errors [in /home/abdulaziz/abdulaziz/courses/udacity/nd/fyyur/app.py:465]
2023-04-08 18:39:20,119 INFO: errors [in /home/abdulaziz/abdulaziz/courses/udacity/nd/fyyur/app.py:466]
2023-04-08 18:41:51,592 INFO: errors [in /home/abdulaziz/abdulaziz/courses/udacity/nd/fyyur/app.py:470]
2023-04-08 18:48:54,300 INFO: errors [in /home/abdulaziz/abdulaziz/courses/udacity/nd/fyyur/app.py:489]
2023-04-08 18:51:01,249 INFO: errors [in /home/abdulaziz/abdulaziz/courses/udacity/nd/fyyur/app.py:489]
2023-04-08 18:51:14,749 INFO: errors [in /home/abdulaziz/abdulaziz/courses/udacity/nd/fyyur/app.py:489]
2023-04-08 18:51:36,509 INFO: errors [in /home/abdulaziz/abdulaziz/courses/udacity/nd/fyyur/app.py:490]
2023-04-08 18:51:38,620 ERROR: Exception on /artists/1/edit [GET] [in /home/abdulaziz/abdulaziz/courses/udacity/nd/fyyur/udacity_nd/lib/python3.10/site-packages/flask/app.py:1744]
Traceback (most recent call last):
  File "/home/abdulaziz/abdulaziz/courses/udacity/nd/fyyur/udacity_nd/lib/python3.10/site-packages/flask/app.py", line 2528, in wsgi_app
    response = self.full_dispatch_request()
  File "/home/abdulaziz/abdulaziz/courses/udacity/nd/fyyur/udacity_nd/lib/python3.10/site-packages/flask/app.py", line 1825, in full_dispatch_request
    rv = self.handle_user_exception(e)
  File "/home/abdulaziz/abdulaziz/courses/udacity/nd/fyyur/udacity_nd/lib/python3.10/site-packages/flask/app.py", line 1823, in full_dispatch_request
    rv = self.dispatch_request()
  File "/home/abdulaziz/abdulaziz/courses/udacity/nd/fyyur/udacity_nd/lib/python3.10/site-packages/flask/app.py", line 1799, in dispatch_request
    return self.ensure_sync(self.view_functions[rule.endpoint])(**view_args)
  File "/home/abdulaziz/abdulaziz/courses/udacity/nd/fyyur/app.py", line 327, in edit_artist
    return render_template('forms/edit_artist.html', form=form, artist=data)
  File "/home/abdulaziz/abdulaziz/courses/udacity/nd/fyyur/udacity_nd/lib/python3.10/site-packages/flask/templating.py", line 147, in render_template
    return _render(app, template, context)
  File "/home/abdulaziz/abdulaziz/courses/udacity/nd/fyyur/udacity_nd/lib/python3.10/site-packages/flask/templating.py", line 130, in _render
    rv = template.render(context)
  File "/home/abdulaziz/abdulaziz/courses/udacity/nd/fyyur/udacity_nd/lib/python3.10/site-packages/jinja2/environment.py", line 1301, in render
    self.environment.handle_exception()
  File "/home/abdulaziz/abdulaziz/courses/udacity/nd/fyyur/udacity_nd/lib/python3.10/site-packages/jinja2/environment.py", line 936, in handle_exception
    raise rewrite_traceback_stack(source=source)
  File "/home/abdulaziz/abdulaziz/courses/udacity/nd/fyyur/templates/forms/edit_artist.html", line 1, in top-level template code
    {% extends 'layouts/main.html' %}
  File "/home/abdulaziz/abdulaziz/courses/udacity/nd/fyyur/templates/layouts/main.html", line 103, in top-level template code
    {% block content %}{% endblock %}
  File "/home/abdulaziz/abdulaziz/courses/udacity/nd/fyyur/templates/forms/edit_artist.html", line 9, in block 'content'
    {{ form.name(class_ = 'form-control', autofocus = true) }}
TypeError: 'str' object is not callable
2023-04-08 18:52:11,101 INFO: errors [in /home/abdulaziz/abdulaziz/courses/udacity/nd/fyyur/app.py:488]
2023-04-08 18:52:13,530 ERROR: Exception on /artists/1/edit [GET] [in /home/abdulaziz/abdulaziz/courses/udacity/nd/fyyur/udacity_nd/lib/python3.10/site-packages/flask/app.py:1744]
Traceback (most recent call last):
  File "/home/abdulaziz/abdulaziz/courses/udacity/nd/fyyur/udacity_nd/lib/python3.10/site-packages/flask/app.py", line 2528, in wsgi_app
    response = self.full_dispatch_request()
  File "/home/abdulaziz/abdulaziz/courses/udacity/nd/fyyur/udacity_nd/lib/python3.10/site-packages/flask/app.py", line 1825, in full_dispatch_request
    rv = self.handle_user_exception(e)
  File "/home/abdulaziz/abdulaziz/courses/udacity/nd/fyyur/udacity_nd/lib/python3.10/site-packages/flask/app.py", line 1823, in full_dispatch_request
    rv = self.dispatch_request()
  File "/home/abdulaziz/abdulaziz/courses/udacity/nd/fyyur/udacity_nd/lib/python3.10/site-packages/flask/app.py", line 1799, in dispatch_request
    return self.ensure_sync(self.view_functions[rule.endpoint])(**view_args)
  File "/home/abdulaziz/abdulaziz/courses/udacity/nd/fyyur/app.py", line 323, in edit_artist
    form = ArtistForm(data)
  File "/home/abdulaziz/abdulaziz/courses/udacity/nd/fyyur/udacity_nd/lib/python3.10/site-packages/wtforms/form.py", line 208, in __call__
    return type.__call__(cls, *args, **kwargs)
  File "/home/abdulaziz/abdulaziz/courses/udacity/nd/fyyur/udacity_nd/lib/python3.10/site-packages/wtforms/form.py", line 286, in __init__
    self.process(formdata, obj, data=data, **kwargs)
  File "/home/abdulaziz/abdulaziz/courses/udacity/nd/fyyur/udacity_nd/lib/python3.10/site-packages/wtforms/form.py", line 106, in process
    formdata = self.meta.wrap_formdata(self, formdata)
  File "/home/abdulaziz/abdulaziz/courses/udacity/nd/fyyur/udacity_nd/lib/python3.10/site-packages/wtforms/meta.py", line 45, in wrap_formdata
    raise TypeError(
TypeError: formdata should be a multidict-type wrapper that supports the 'getlist' method
2023-04-08 18:52:26,809 INFO: errors [in /home/abdulaziz/abdulaziz/courses/udacity/nd/fyyur/app.py:488]
2023-04-08 18:55:27,010 INFO: errors [in /home/abdulaziz/abdulaziz/courses/udacity/nd/fyyur/app.py:484]
2023-04-08 18:55:30,232 ERROR: Exception on /artists/1/edit [GET] [in /home/abdulaziz/abdulaziz/courses/udacity/nd/fyyur/udacity_nd/lib/python3.10/site-packages/flask/app.py:1744]
Traceback (most recent call last):
  File "/home/abdulaziz/abdulaziz/courses/udacity/nd/fyyur/udacity_nd/lib/python3.10/site-packages/flask/app.py", line 2528, in wsgi_app
    response = self.full_dispatch_request()
  File "/home/abdulaziz/abdulaziz/courses/udacity/nd/fyyur/udacity_nd/lib/python3.10/site-packages/flask/app.py", line 1825, in full_dispatch_request
    rv = self.handle_user_exception(e)
  File "/home/abdulaziz/abdulaziz/courses/udacity/nd/fyyur/udacity_nd/lib/python3.10/site-packages/flask/app.py", line 1823, in full_dispatch_request
    rv = self.dispatch_request()
  File "/home/abdulaziz/abdulaziz/courses/udacity/nd/fyyur/udacity_nd/lib/python3.10/site-packages/flask/app.py", line 1799, in dispatch_request
    return self.ensure_sync(self.view_functions[rule.endpoint])(**view_args)
  File "/home/abdulaziz/abdulaziz/courses/udacity/nd/fyyur/app.py", line 321, in edit_artist
    return render_template('forms/edit_artist.html', form=form, artist=artist)
  File "/home/abdulaziz/abdulaziz/courses/udacity/nd/fyyur/udacity_nd/lib/python3.10/site-packages/flask/templating.py", line 147, in render_template
    return _render(app, template, context)
  File "/home/abdulaziz/abdulaziz/courses/udacity/nd/fyyur/udacity_nd/lib/python3.10/site-packages/flask/templating.py", line 130, in _render
    rv = template.render(context)
  File "/home/abdulaziz/abdulaziz/courses/udacity/nd/fyyur/udacity_nd/lib/python3.10/site-packages/jinja2/environment.py", line 1301, in render
    self.environment.handle_exception()
  File "/home/abdulaziz/abdulaziz/courses/udacity/nd/fyyur/udacity_nd/lib/python3.10/site-packages/jinja2/environment.py", line 936, in handle_exception
    raise rewrite_traceback_stack(source=source)
  File "/home/abdulaziz/abdulaziz/courses/udacity/nd/fyyur/templates/forms/edit_artist.html", line 1, in top-level template code
    {% extends 'layouts/main.html' %}
  File "/home/abdulaziz/abdulaziz/courses/udacity/nd/fyyur/templates/layouts/main.html", line 103, in top-level template code
    {% block content %}{% endblock %}
  File "/home/abdulaziz/abdulaziz/courses/udacity/nd/fyyur/templates/forms/edit_artist.html", line 9, in block 'content'
    {{ form.name(class_ = 'form-control', autofocus = true) }}
TypeError: 'str' object is not callable
2023-04-08 19:00:01,267 ERROR: Exception on /artists/1/edit [GET] [in /home/abdulaziz/abdulaziz/courses/udacity/nd/fyyur/udacity_nd/lib/python3.10/site-packages/flask/app.py:1744]
Traceback (most recent call last):
  File "/home/abdulaziz/abdulaziz/courses/udacity/nd/fyyur/udacity_nd/lib/python3.10/site-packages/flask/app.py", line 2528, in wsgi_app
    response = self.full_dispatch_request()
  File "/home/abdulaziz/abdulaziz/courses/udacity/nd/fyyur/udacity_nd/lib/python3.10/site-packages/flask/app.py", line 1825, in full_dispatch_request
    rv = self.handle_user_exception(e)
  File "/home/abdulaziz/abdulaziz/courses/udacity/nd/fyyur/udacity_nd/lib/python3.10/site-packages/flask/app.py", line 1823, in full_dispatch_request
    rv = self.dispatch_request()
  File "/home/abdulaziz/abdulaziz/courses/udacity/nd/fyyur/udacity_nd/lib/python3.10/site-packages/flask/app.py", line 1799, in dispatch_request
    return self.ensure_sync(self.view_functions[rule.endpoint])(**view_args)
  File "/home/abdulaziz/abdulaziz/courses/udacity/nd/fyyur/app.py", line 321, in edit_artist
    "image_link": artist.image_link,
  File "/home/abdulaziz/abdulaziz/courses/udacity/nd/fyyur/udacity_nd/lib/python3.10/site-packages/flask/templating.py", line 147, in render_template
    return _render(app, template, context)
  File "/home/abdulaziz/abdulaziz/courses/udacity/nd/fyyur/udacity_nd/lib/python3.10/site-packages/flask/templating.py", line 130, in _render
    rv = template.render(context)
  File "/home/abdulaziz/abdulaziz/courses/udacity/nd/fyyur/udacity_nd/lib/python3.10/site-packages/jinja2/environment.py", line 1301, in render
    self.environment.handle_exception()
  File "/home/abdulaziz/abdulaziz/courses/udacity/nd/fyyur/udacity_nd/lib/python3.10/site-packages/jinja2/environment.py", line 936, in handle_exception
    raise rewrite_traceback_stack(source=source)
  File "/home/abdulaziz/abdulaziz/courses/udacity/nd/fyyur/templates/forms/edit_artist.html", line 1, in top-level template code
    {% extends 'layouts/main.html' %}
  File "/home/abdulaziz/abdulaziz/courses/udacity/nd/fyyur/templates/layouts/main.html", line 103, in top-level template code
    {% block content %}{% endblock %}
  File "/home/abdulaziz/abdulaziz/courses/udacity/nd/fyyur/templates/forms/edit_artist.html", line 9, in block 'content'
    {{ form.name(class_ = 'form-control', autofocus = true) }}
TypeError: 'str' object is not callable
2023-04-08 19:00:06,417 ERROR: Exception on /artists/1/edit [GET] [in /home/abdulaziz/abdulaziz/courses/udacity/nd/fyyur/udacity_nd/lib/python3.10/site-packages/flask/app.py:1744]
Traceback (most recent call last):
  File "/home/abdulaziz/abdulaziz/courses/udacity/nd/fyyur/udacity_nd/lib/python3.10/site-packages/flask/app.py", line 2528, in wsgi_app
    response = self.full_dispatch_request()
  File "/home/abdulaziz/abdulaziz/courses/udacity/nd/fyyur/udacity_nd/lib/python3.10/site-packages/flask/app.py", line 1825, in full_dispatch_request
    rv = self.handle_user_exception(e)
  File "/home/abdulaziz/abdulaziz/courses/udacity/nd/fyyur/udacity_nd/lib/python3.10/site-packages/flask/app.py", line 1823, in full_dispatch_request
    rv = self.dispatch_request()
  File "/home/abdulaziz/abdulaziz/courses/udacity/nd/fyyur/udacity_nd/lib/python3.10/site-packages/flask/app.py", line 1799, in dispatch_request
    return self.ensure_sync(self.view_functions[rule.endpoint])(**view_args)
  File "/home/abdulaziz/abdulaziz/courses/udacity/nd/fyyur/app.py", line 321, in edit_artist
    "image_link": artist.image_link,
  File "/home/abdulaziz/abdulaziz/courses/udacity/nd/fyyur/udacity_nd/lib/python3.10/site-packages/flask/templating.py", line 147, in render_template
    return _render(app, template, context)
  File "/home/abdulaziz/abdulaziz/courses/udacity/nd/fyyur/udacity_nd/lib/python3.10/site-packages/flask/templating.py", line 130, in _render
    rv = template.render(context)
  File "/home/abdulaziz/abdulaziz/courses/udacity/nd/fyyur/udacity_nd/lib/python3.10/site-packages/jinja2/environment.py", line 1301, in render
    self.environment.handle_exception()
  File "/home/abdulaziz/abdulaziz/courses/udacity/nd/fyyur/udacity_nd/lib/python3.10/site-packages/jinja2/environment.py", line 936, in handle_exception
    raise rewrite_traceback_stack(source=source)
  File "/home/abdulaziz/abdulaziz/courses/udacity/nd/fyyur/templates/forms/edit_artist.html", line 1, in top-level template code
    {% extends 'layouts/main.html' %}
  File "/home/abdulaziz/abdulaziz/courses/udacity/nd/fyyur/templates/layouts/main.html", line 103, in top-level template code
    {% block content %}{% endblock %}
  File "/home/abdulaziz/abdulaziz/courses/udacity/nd/fyyur/templates/forms/edit_artist.html", line 9, in block 'content'
    {{ form.name(class_ = 'form-control', autofocus = true) }}
TypeError: 'str' object is not callable
2023-04-08 19:00:10,388 INFO: errors [in /home/abdulaziz/abdulaziz/courses/udacity/nd/fyyur/app.py:499]
2023-04-08 19:00:12,243 ERROR: Exception on /artists/1/edit [GET] [in /home/abdulaziz/abdulaziz/courses/udacity/nd/fyyur/udacity_nd/lib/python3.10/site-packages/flask/app.py:1744]
Traceback (most recent call last):
  File "/home/abdulaziz/abdulaziz/courses/udacity/nd/fyyur/udacity_nd/lib/python3.10/site-packages/flask/app.py", line 2528, in wsgi_app
    response = self.full_dispatch_request()
  File "/home/abdulaziz/abdulaziz/courses/udacity/nd/fyyur/udacity_nd/lib/python3.10/site-packages/flask/app.py", line 1825, in full_dispatch_request
    rv = self.handle_user_exception(e)
  File "/home/abdulaziz/abdulaziz/courses/udacity/nd/fyyur/udacity_nd/lib/python3.10/site-packages/flask/app.py", line 1823, in full_dispatch_request
    rv = self.dispatch_request()
  File "/home/abdulaziz/abdulaziz/courses/udacity/nd/fyyur/udacity_nd/lib/python3.10/site-packages/flask/app.py", line 1799, in dispatch_request
    return self.ensure_sync(self.view_functions[rule.endpoint])(**view_args)
  File "/home/abdulaziz/abdulaziz/courses/udacity/nd/fyyur/app.py", line 336, in edit_artist
    return render_template('forms/edit_artist.html', form=form, artist=data)
  File "/home/abdulaziz/abdulaziz/courses/udacity/nd/fyyur/udacity_nd/lib/python3.10/site-packages/flask/templating.py", line 147, in render_template
    return _render(app, template, context)
  File "/home/abdulaziz/abdulaziz/courses/udacity/nd/fyyur/udacity_nd/lib/python3.10/site-packages/flask/templating.py", line 130, in _render
    rv = template.render(context)
  File "/home/abdulaziz/abdulaziz/courses/udacity/nd/fyyur/udacity_nd/lib/python3.10/site-packages/jinja2/environment.py", line 1301, in render
    self.environment.handle_exception()
  File "/home/abdulaziz/abdulaziz/courses/udacity/nd/fyyur/udacity_nd/lib/python3.10/site-packages/jinja2/environment.py", line 936, in handle_exception
    raise rewrite_traceback_stack(source=source)
  File "/home/abdulaziz/abdulaziz/courses/udacity/nd/fyyur/templates/forms/edit_artist.html", line 1, in top-level template code
    {% extends 'layouts/main.html' %}
  File "/home/abdulaziz/abdulaziz/courses/udacity/nd/fyyur/templates/layouts/main.html", line 103, in top-level template code
    {% block content %}{% endblock %}
  File "/home/abdulaziz/abdulaziz/courses/udacity/nd/fyyur/templates/forms/edit_artist.html", line 9, in block 'content'
    {{ form.name(class_ = 'form-control', autofocus = true) }}
TypeError: 'str' object is not callable
2023-04-08 19:25:24,595 INFO: errors [in /home/abdulaziz/abdulaziz/courses/udacity/nd/fyyur/app.py:499]
2023-04-08 19:25:32,111 ERROR: Exception on /artists/1/edit [GET] [in /home/abdulaziz/abdulaziz/courses/udacity/nd/fyyur/udacity_nd/lib/python3.10/site-packages/flask/app.py:1744]
Traceback (most recent call last):
  File "/home/abdulaziz/abdulaziz/courses/udacity/nd/fyyur/udacity_nd/lib/python3.10/site-packages/flask/app.py", line 2528, in wsgi_app
    response = self.full_dispatch_request()
  File "/home/abdulaziz/abdulaziz/courses/udacity/nd/fyyur/udacity_nd/lib/python3.10/site-packages/flask/app.py", line 1825, in full_dispatch_request
    rv = self.handle_user_exception(e)
  File "/home/abdulaziz/abdulaziz/courses/udacity/nd/fyyur/udacity_nd/lib/python3.10/site-packages/flask/app.py", line 1823, in full_dispatch_request
    rv = self.dispatch_request()
  File "/home/abdulaziz/abdulaziz/courses/udacity/nd/fyyur/udacity_nd/lib/python3.10/site-packages/flask/app.py", line 1799, in dispatch_request
    return self.ensure_sync(self.view_functions[rule.endpoint])(**view_args)
  File "/home/abdulaziz/abdulaziz/courses/udacity/nd/fyyur/app.py", line 308, in edit_artist
    artist = Artist.query.get(artist_id).all()
AttributeError: 'Artist' object has no attribute 'all'
2023-04-08 19:25:48,980 INFO: errors [in /home/abdulaziz/abdulaziz/courses/udacity/nd/fyyur/app.py:499]
2023-04-08 19:25:58,021 ERROR: Exception on /artists/4/edit [GET] [in /home/abdulaziz/abdulaziz/courses/udacity/nd/fyyur/udacity_nd/lib/python3.10/site-packages/flask/app.py:1744]
Traceback (most recent call last):
  File "/home/abdulaziz/abdulaziz/courses/udacity/nd/fyyur/udacity_nd/lib/python3.10/site-packages/flask/app.py", line 2528, in wsgi_app
    response = self.full_dispatch_request()
  File "/home/abdulaziz/abdulaziz/courses/udacity/nd/fyyur/udacity_nd/lib/python3.10/site-packages/flask/app.py", line 1825, in full_dispatch_request
    rv = self.handle_user_exception(e)
  File "/home/abdulaziz/abdulaziz/courses/udacity/nd/fyyur/udacity_nd/lib/python3.10/site-packages/flask/app.py", line 1823, in full_dispatch_request
    rv = self.dispatch_request()
  File "/home/abdulaziz/abdulaziz/courses/udacity/nd/fyyur/udacity_nd/lib/python3.10/site-packages/flask/app.py", line 1799, in dispatch_request
    return self.ensure_sync(self.view_functions[rule.endpoint])(**view_args)
  File "/home/abdulaziz/abdulaziz/courses/udacity/nd/fyyur/app.py", line 336, in edit_artist
    return render_template('forms/edit_artist.html', form=form, artist=data)
  File "/home/abdulaziz/abdulaziz/courses/udacity/nd/fyyur/udacity_nd/lib/python3.10/site-packages/flask/templating.py", line 147, in render_template
    return _render(app, template, context)
  File "/home/abdulaziz/abdulaziz/courses/udacity/nd/fyyur/udacity_nd/lib/python3.10/site-packages/flask/templating.py", line 130, in _render
    rv = template.render(context)
  File "/home/abdulaziz/abdulaziz/courses/udacity/nd/fyyur/udacity_nd/lib/python3.10/site-packages/jinja2/environment.py", line 1301, in render
    self.environment.handle_exception()
  File "/home/abdulaziz/abdulaziz/courses/udacity/nd/fyyur/udacity_nd/lib/python3.10/site-packages/jinja2/environment.py", line 936, in handle_exception
    raise rewrite_traceback_stack(source=source)
  File "/home/abdulaziz/abdulaziz/courses/udacity/nd/fyyur/templates/forms/edit_artist.html", line 1, in top-level template code
    {% extends 'layouts/main.html' %}
  File "/home/abdulaziz/abdulaziz/courses/udacity/nd/fyyur/templates/layouts/main.html", line 103, in top-level template code
    {% block content %}{% endblock %}
  File "/home/abdulaziz/abdulaziz/courses/udacity/nd/fyyur/templates/forms/edit_artist.html", line 9, in block 'content'
    {{ form.name(class_ = 'form-control', autofocus = true) }}
TypeError: 'str' object is not callable
2023-04-08 19:26:50,869 INFO: errors [in /home/abdulaziz/abdulaziz/courses/udacity/nd/fyyur/app.py:484]
2023-04-08 19:26:55,693 ERROR: Exception on /artists/4/edit [GET] [in /home/abdulaziz/abdulaziz/courses/udacity/nd/fyyur/udacity_nd/lib/python3.10/site-packages/flask/app.py:1744]
Traceback (most recent call last):
  File "/home/abdulaziz/abdulaziz/courses/udacity/nd/fyyur/udacity_nd/lib/python3.10/site-packages/flask/app.py", line 2528, in wsgi_app
    response = self.full_dispatch_request()
  File "/home/abdulaziz/abdulaziz/courses/udacity/nd/fyyur/udacity_nd/lib/python3.10/site-packages/flask/app.py", line 1825, in full_dispatch_request
    rv = self.handle_user_exception(e)
  File "/home/abdulaziz/abdulaziz/courses/udacity/nd/fyyur/udacity_nd/lib/python3.10/site-packages/flask/app.py", line 1823, in full_dispatch_request
    rv = self.dispatch_request()
  File "/home/abdulaziz/abdulaziz/courses/udacity/nd/fyyur/udacity_nd/lib/python3.10/site-packages/flask/app.py", line 1799, in dispatch_request
    return self.ensure_sync(self.view_functions[rule.endpoint])(**view_args)
  File "/home/abdulaziz/abdulaziz/courses/udacity/nd/fyyur/app.py", line 321, in edit_artist
    return render_template('forms/edit_artist.html', form=form, artist=artist)
  File "/home/abdulaziz/abdulaziz/courses/udacity/nd/fyyur/udacity_nd/lib/python3.10/site-packages/flask/templating.py", line 147, in render_template
    return _render(app, template, context)
  File "/home/abdulaziz/abdulaziz/courses/udacity/nd/fyyur/udacity_nd/lib/python3.10/site-packages/flask/templating.py", line 130, in _render
    rv = template.render(context)
  File "/home/abdulaziz/abdulaziz/courses/udacity/nd/fyyur/udacity_nd/lib/python3.10/site-packages/jinja2/environment.py", line 1301, in render
    self.environment.handle_exception()
  File "/home/abdulaziz/abdulaziz/courses/udacity/nd/fyyur/udacity_nd/lib/python3.10/site-packages/jinja2/environment.py", line 936, in handle_exception
    raise rewrite_traceback_stack(source=source)
  File "/home/abdulaziz/abdulaziz/courses/udacity/nd/fyyur/templates/forms/edit_artist.html", line 1, in top-level template code
    {% extends 'layouts/main.html' %}
  File "/home/abdulaziz/abdulaziz/courses/udacity/nd/fyyur/templates/layouts/main.html", line 103, in top-level template code
    {% block content %}{% endblock %}
  File "/home/abdulaziz/abdulaziz/courses/udacity/nd/fyyur/templates/forms/edit_artist.html", line 9, in block 'content'
    {{ form.name(class_ = 'form-control', autofocus = true) }}
TypeError: 'str' object is not callable
2023-04-08 19:27:25,010 INFO: errors [in /home/abdulaziz/abdulaziz/courses/udacity/nd/fyyur/app.py:484]
2023-04-08 19:27:27,223 ERROR: Exception on /artists/4/edit [GET] [in /home/abdulaziz/abdulaziz/courses/udacity/nd/fyyur/udacity_nd/lib/python3.10/site-packages/flask/app.py:1744]
Traceback (most recent call last):
  File "/home/abdulaziz/abdulaziz/courses/udacity/nd/fyyur/udacity_nd/lib/python3.10/site-packages/flask/app.py", line 2528, in wsgi_app
    response = self.full_dispatch_request()
  File "/home/abdulaziz/abdulaziz/courses/udacity/nd/fyyur/udacity_nd/lib/python3.10/site-packages/flask/app.py", line 1825, in full_dispatch_request
    rv = self.handle_user_exception(e)
  File "/home/abdulaziz/abdulaziz/courses/udacity/nd/fyyur/udacity_nd/lib/python3.10/site-packages/flask/app.py", line 1823, in full_dispatch_request
    rv = self.dispatch_request()
  File "/home/abdulaziz/abdulaziz/courses/udacity/nd/fyyur/udacity_nd/lib/python3.10/site-packages/flask/app.py", line 1799, in dispatch_request
    return self.ensure_sync(self.view_functions[rule.endpoint])(**view_args)
  File "/home/abdulaziz/abdulaziz/courses/udacity/nd/fyyur/app.py", line 321, in edit_artist
    return render_template('forms/edit_artist.html', form=form, artist=data)
NameError: name 'data' is not defined
2023-04-08 19:28:23,231 INFO: errors [in /home/abdulaziz/abdulaziz/courses/udacity/nd/fyyur/app.py:484]
2023-04-08 19:28:24,999 ERROR: Exception on /artists/4/edit [GET] [in /home/abdulaziz/abdulaziz/courses/udacity/nd/fyyur/udacity_nd/lib/python3.10/site-packages/flask/app.py:1744]
Traceback (most recent call last):
  File "/home/abdulaziz/abdulaziz/courses/udacity/nd/fyyur/udacity_nd/lib/python3.10/site-packages/flask/app.py", line 2528, in wsgi_app
    response = self.full_dispatch_request()
  File "/home/abdulaziz/abdulaziz/courses/udacity/nd/fyyur/udacity_nd/lib/python3.10/site-packages/flask/app.py", line 1825, in full_dispatch_request
    rv = self.handle_user_exception(e)
  File "/home/abdulaziz/abdulaziz/courses/udacity/nd/fyyur/udacity_nd/lib/python3.10/site-packages/flask/app.py", line 1823, in full_dispatch_request
    rv = self.dispatch_request()
  File "/home/abdulaziz/abdulaziz/courses/udacity/nd/fyyur/udacity_nd/lib/python3.10/site-packages/flask/app.py", line 1799, in dispatch_request
    return self.ensure_sync(self.view_functions[rule.endpoint])(**view_args)
  File "/home/abdulaziz/abdulaziz/courses/udacity/nd/fyyur/app.py", line 308, in edit_artist
    artist = Artist.query.get(Artist, artist_id)
TypeError: Query.get() takes 2 positional arguments but 3 were given
2023-04-08 19:29:47,494 INFO: errors [in /home/abdulaziz/abdulaziz/courses/udacity/nd/fyyur/app.py:484]
2023-04-08 19:29:48,695 ERROR: Exception on /artists/4/edit [GET] [in /home/abdulaziz/abdulaziz/courses/udacity/nd/fyyur/udacity_nd/lib/python3.10/site-packages/flask/app.py:1744]
Traceback (most recent call last):
  File "/home/abdulaziz/abdulaziz/courses/udacity/nd/fyyur/udacity_nd/lib/python3.10/site-packages/flask/app.py", line 2528, in wsgi_app
    response = self.full_dispatch_request()
  File "/home/abdulaziz/abdulaziz/courses/udacity/nd/fyyur/udacity_nd/lib/python3.10/site-packages/flask/app.py", line 1825, in full_dispatch_request
    rv = self.handle_user_exception(e)
  File "/home/abdulaziz/abdulaziz/courses/udacity/nd/fyyur/udacity_nd/lib/python3.10/site-packages/flask/app.py", line 1823, in full_dispatch_request
    rv = self.dispatch_request()
  File "/home/abdulaziz/abdulaziz/courses/udacity/nd/fyyur/udacity_nd/lib/python3.10/site-packages/flask/app.py", line 1799, in dispatch_request
    return self.ensure_sync(self.view_functions[rule.endpoint])(**view_args)
  File "/home/abdulaziz/abdulaziz/courses/udacity/nd/fyyur/app.py", line 308, in edit_artist
    artist = Artist.query.get(Artist, artist_id)
TypeError: Query.get() takes 2 positional arguments but 3 were given
2023-04-08 19:30:07,098 INFO: errors [in /home/abdulaziz/abdulaziz/courses/udacity/nd/fyyur/app.py:484]
2023-04-08 19:30:07,882 ERROR: Exception on /artists/4/edit [GET] [in /home/abdulaziz/abdulaziz/courses/udacity/nd/fyyur/udacity_nd/lib/python3.10/site-packages/flask/app.py:1744]
Traceback (most recent call last):
  File "/home/abdulaziz/abdulaziz/courses/udacity/nd/fyyur/udacity_nd/lib/python3.10/site-packages/flask/app.py", line 2528, in wsgi_app
    response = self.full_dispatch_request()
  File "/home/abdulaziz/abdulaziz/courses/udacity/nd/fyyur/udacity_nd/lib/python3.10/site-packages/flask/app.py", line 1825, in full_dispatch_request
    rv = self.handle_user_exception(e)
  File "/home/abdulaziz/abdulaziz/courses/udacity/nd/fyyur/udacity_nd/lib/python3.10/site-packages/flask/app.py", line 1823, in full_dispatch_request
    rv = self.dispatch_request()
  File "/home/abdulaziz/abdulaziz/courses/udacity/nd/fyyur/udacity_nd/lib/python3.10/site-packages/flask/app.py", line 1799, in dispatch_request
    return self.ensure_sync(self.view_functions[rule.endpoint])(**view_args)
  File "/home/abdulaziz/abdulaziz/courses/udacity/nd/fyyur/app.py", line 308, in edit_artist
    artist = Artist.query.get(id=artist_id)
TypeError: Query.get() got an unexpected keyword argument 'id'
2023-04-08 19:30:29,773 INFO: errors [in /home/abdulaziz/abdulaziz/courses/udacity/nd/fyyur/app.py:484]
2023-04-08 19:30:30,510 ERROR: Exception on /artists/4/edit [GET] [in /home/abdulaziz/abdulaziz/courses/udacity/nd/fyyur/udacity_nd/lib/python3.10/site-packages/flask/app.py:1744]
Traceback (most recent call last):
  File "/home/abdulaziz/abdulaziz/courses/udacity/nd/fyyur/udacity_nd/lib/python3.10/site-packages/flask/app.py", line 2528, in wsgi_app
    response = self.full_dispatch_request()
  File "/home/abdulaziz/abdulaziz/courses/udacity/nd/fyyur/udacity_nd/lib/python3.10/site-packages/flask/app.py", line 1825, in full_dispatch_request
    rv = self.handle_user_exception(e)
  File "/home/abdulaziz/abdulaziz/courses/udacity/nd/fyyur/udacity_nd/lib/python3.10/site-packages/flask/app.py", line 1823, in full_dispatch_request
    rv = self.dispatch_request()
  File "/home/abdulaziz/abdulaziz/courses/udacity/nd/fyyur/udacity_nd/lib/python3.10/site-packages/flask/app.py", line 1799, in dispatch_request
    return self.ensure_sync(self.view_functions[rule.endpoint])(**view_args)
  File "/home/abdulaziz/abdulaziz/courses/udacity/nd/fyyur/app.py", line 310, in edit_artist
    form.name = artist.name
AttributeError: 'list' object has no attribute 'name'
2023-04-08 19:30:43,894 INFO: errors [in /home/abdulaziz/abdulaziz/courses/udacity/nd/fyyur/app.py:485]
2023-04-08 19:30:44,537 ERROR: Exception on /artists/4/edit [GET] [in /home/abdulaziz/abdulaziz/courses/udacity/nd/fyyur/udacity_nd/lib/python3.10/site-packages/flask/app.py:1744]
Traceback (most recent call last):
  File "/home/abdulaziz/abdulaziz/courses/udacity/nd/fyyur/udacity_nd/lib/python3.10/site-packages/flask/app.py", line 2528, in wsgi_app
    response = self.full_dispatch_request()
  File "/home/abdulaziz/abdulaziz/courses/udacity/nd/fyyur/udacity_nd/lib/python3.10/site-packages/flask/app.py", line 1825, in full_dispatch_request
    rv = self.handle_user_exception(e)
  File "/home/abdulaziz/abdulaziz/courses/udacity/nd/fyyur/udacity_nd/lib/python3.10/site-packages/flask/app.py", line 1823, in full_dispatch_request
    rv = self.dispatch_request()
  File "/home/abdulaziz/abdulaziz/courses/udacity/nd/fyyur/udacity_nd/lib/python3.10/site-packages/flask/app.py", line 1799, in dispatch_request
    return self.ensure_sync(self.view_functions[rule.endpoint])(**view_args)
  File "/home/abdulaziz/abdulaziz/courses/udacity/nd/fyyur/app.py", line 311, in edit_artist
    form.name = artist.name
AttributeError: 'list' object has no attribute 'name'
2023-04-08 19:31:01,258 INFO: errors [in /home/abdulaziz/abdulaziz/courses/udacity/nd/fyyur/app.py:484]
2023-04-08 19:31:01,905 ERROR: Exception on /artists/4/edit [GET] [in /home/abdulaziz/abdulaziz/courses/udacity/nd/fyyur/udacity_nd/lib/python3.10/site-packages/flask/app.py:1744]
Traceback (most recent call last):
  File "/home/abdulaziz/abdulaziz/courses/udacity/nd/fyyur/udacity_nd/lib/python3.10/site-packages/flask/app.py", line 2528, in wsgi_app
    response = self.full_dispatch_request()
  File "/home/abdulaziz/abdulaziz/courses/udacity/nd/fyyur/udacity_nd/lib/python3.10/site-packages/flask/app.py", line 1825, in full_dispatch_request
    rv = self.handle_user_exception(e)
  File "/home/abdulaziz/abdulaziz/courses/udacity/nd/fyyur/udacity_nd/lib/python3.10/site-packages/flask/app.py", line 1823, in full_dispatch_request
    rv = self.dispatch_request()
  File "/home/abdulaziz/abdulaziz/courses/udacity/nd/fyyur/udacity_nd/lib/python3.10/site-packages/flask/app.py", line 1799, in dispatch_request
    return self.ensure_sync(self.view_functions[rule.endpoint])(**view_args)
  File "/home/abdulaziz/abdulaziz/courses/udacity/nd/fyyur/app.py", line 321, in edit_artist
    return render_template('forms/edit_artist.html', form=form, artist=data)
NameError: name 'data' is not defined
2023-04-08 19:31:11,445 INFO: errors [in /home/abdulaziz/abdulaziz/courses/udacity/nd/fyyur/app.py:485]
2023-04-08 19:31:11,977 ERROR: Exception on /artists/4/edit [GET] [in /home/abdulaziz/abdulaziz/courses/udacity/nd/fyyur/udacity_nd/lib/python3.10/site-packages/flask/app.py:1744]
Traceback (most recent call last):
  File "/home/abdulaziz/abdulaziz/courses/udacity/nd/fyyur/udacity_nd/lib/python3.10/site-packages/flask/app.py", line 2528, in wsgi_app
    response = self.full_dispatch_request()
  File "/home/abdulaziz/abdulaziz/courses/udacity/nd/fyyur/udacity_nd/lib/python3.10/site-packages/flask/app.py", line 1825, in full_dispatch_request
    rv = self.handle_user_exception(e)
  File "/home/abdulaziz/abdulaziz/courses/udacity/nd/fyyur/udacity_nd/lib/python3.10/site-packages/flask/app.py", line 1823, in full_dispatch_request
    rv = self.dispatch_request()
  File "/home/abdulaziz/abdulaziz/courses/udacity/nd/fyyur/udacity_nd/lib/python3.10/site-packages/flask/app.py", line 1799, in dispatch_request
    return self.ensure_sync(self.view_functions[rule.endpoint])(**view_args)
  File "/home/abdulaziz/abdulaziz/courses/udacity/nd/fyyur/app.py", line 322, in edit_artist
    return render_template('forms/edit_artist.html', form=form, artist=data)
NameError: name 'data' is not defined
2023-04-08 19:31:24,107 INFO: errors [in /home/abdulaziz/abdulaziz/courses/udacity/nd/fyyur/app.py:485]
2023-04-08 19:31:24,793 ERROR: Exception on /artists/4/edit [GET] [in /home/abdulaziz/abdulaziz/courses/udacity/nd/fyyur/udacity_nd/lib/python3.10/site-packages/flask/app.py:1744]
Traceback (most recent call last):
  File "/home/abdulaziz/abdulaziz/courses/udacity/nd/fyyur/udacity_nd/lib/python3.10/site-packages/flask/app.py", line 2528, in wsgi_app
    response = self.full_dispatch_request()
  File "/home/abdulaziz/abdulaziz/courses/udacity/nd/fyyur/udacity_nd/lib/python3.10/site-packages/flask/app.py", line 1825, in full_dispatch_request
    rv = self.handle_user_exception(e)
  File "/home/abdulaziz/abdulaziz/courses/udacity/nd/fyyur/udacity_nd/lib/python3.10/site-packages/flask/app.py", line 1823, in full_dispatch_request
    rv = self.dispatch_request()
  File "/home/abdulaziz/abdulaziz/courses/udacity/nd/fyyur/udacity_nd/lib/python3.10/site-packages/flask/app.py", line 1799, in dispatch_request
    return self.ensure_sync(self.view_functions[rule.endpoint])(**view_args)
  File "/home/abdulaziz/abdulaziz/courses/udacity/nd/fyyur/app.py", line 311, in edit_artist
    form.name = artist.name
AttributeError: 'Query' object has no attribute 'name'
2023-04-08 19:31:42,233 INFO: errors [in /home/abdulaziz/abdulaziz/courses/udacity/nd/fyyur/app.py:485]
2023-04-08 19:31:44,800 ERROR: Exception on /artists/4/edit [GET] [in /home/abdulaziz/abdulaziz/courses/udacity/nd/fyyur/udacity_nd/lib/python3.10/site-packages/flask/app.py:1744]
Traceback (most recent call last):
  File "/home/abdulaziz/abdulaziz/courses/udacity/nd/fyyur/udacity_nd/lib/python3.10/site-packages/flask/app.py", line 2528, in wsgi_app
    response = self.full_dispatch_request()
  File "/home/abdulaziz/abdulaziz/courses/udacity/nd/fyyur/udacity_nd/lib/python3.10/site-packages/flask/app.py", line 1825, in full_dispatch_request
    rv = self.handle_user_exception(e)
  File "/home/abdulaziz/abdulaziz/courses/udacity/nd/fyyur/udacity_nd/lib/python3.10/site-packages/flask/app.py", line 1823, in full_dispatch_request
    rv = self.dispatch_request()
  File "/home/abdulaziz/abdulaziz/courses/udacity/nd/fyyur/udacity_nd/lib/python3.10/site-packages/flask/app.py", line 1799, in dispatch_request
    return self.ensure_sync(self.view_functions[rule.endpoint])(**view_args)
  File "/home/abdulaziz/abdulaziz/courses/udacity/nd/fyyur/app.py", line 311, in edit_artist
    form.name = artist.name
AttributeError: 'list' object has no attribute 'name'
2023-04-08 19:32:11,736 INFO: errors [in /home/abdulaziz/abdulaziz/courses/udacity/nd/fyyur/app.py:486]
2023-04-08 19:32:12,536 ERROR: Exception on /artists/4/edit [GET] [in /home/abdulaziz/abdulaziz/courses/udacity/nd/fyyur/udacity_nd/lib/python3.10/site-packages/flask/app.py:1744]
Traceback (most recent call last):
  File "/home/abdulaziz/abdulaziz/courses/udacity/nd/fyyur/udacity_nd/lib/python3.10/site-packages/flask/app.py", line 2528, in wsgi_app
    response = self.full_dispatch_request()
  File "/home/abdulaziz/abdulaziz/courses/udacity/nd/fyyur/udacity_nd/lib/python3.10/site-packages/flask/app.py", line 1825, in full_dispatch_request
    rv = self.handle_user_exception(e)
  File "/home/abdulaziz/abdulaziz/courses/udacity/nd/fyyur/udacity_nd/lib/python3.10/site-packages/flask/app.py", line 1823, in full_dispatch_request
    rv = self.dispatch_request()
  File "/home/abdulaziz/abdulaziz/courses/udacity/nd/fyyur/udacity_nd/lib/python3.10/site-packages/flask/app.py", line 1799, in dispatch_request
    return self.ensure_sync(self.view_functions[rule.endpoint])(**view_args)
  File "/home/abdulaziz/abdulaziz/courses/udacity/nd/fyyur/app.py", line 312, in edit_artist
    form.name = artist.name
AttributeError: 'list' object has no attribute 'name'
2023-04-08 19:32:35,713 INFO: errors [in /home/abdulaziz/abdulaziz/courses/udacity/nd/fyyur/app.py:484]
2023-04-08 19:32:37,018 ERROR: Exception on /artists/4/edit [GET] [in /home/abdulaziz/abdulaziz/courses/udacity/nd/fyyur/udacity_nd/lib/python3.10/site-packages/flask/app.py:1744]
Traceback (most recent call last):
  File "/home/abdulaziz/abdulaziz/courses/udacity/nd/fyyur/udacity_nd/lib/python3.10/site-packages/flask/app.py", line 2528, in wsgi_app
    response = self.full_dispatch_request()
  File "/home/abdulaziz/abdulaziz/courses/udacity/nd/fyyur/udacity_nd/lib/python3.10/site-packages/flask/app.py", line 1825, in full_dispatch_request
    rv = self.handle_user_exception(e)
  File "/home/abdulaziz/abdulaziz/courses/udacity/nd/fyyur/udacity_nd/lib/python3.10/site-packages/flask/app.py", line 1823, in full_dispatch_request
    rv = self.dispatch_request()
  File "/home/abdulaziz/abdulaziz/courses/udacity/nd/fyyur/udacity_nd/lib/python3.10/site-packages/flask/app.py", line 1799, in dispatch_request
    return self.ensure_sync(self.view_functions[rule.endpoint])(**view_args)
  File "/home/abdulaziz/abdulaziz/courses/udacity/nd/fyyur/app.py", line 308, in edit_artist
    artist = Artist.query.filter(id=artist_id).all()
TypeError: Query.filter() got an unexpected keyword argument 'id'
2023-04-08 19:34:36,960 INFO: errors [in /home/abdulaziz/abdulaziz/courses/udacity/nd/fyyur/app.py:499]
2023-04-08 19:34:39,574 ERROR: Exception on /artists/4/edit [GET] [in /home/abdulaziz/abdulaziz/courses/udacity/nd/fyyur/udacity_nd/lib/python3.10/site-packages/flask/app.py:1744]
Traceback (most recent call last):
  File "/home/abdulaziz/abdulaziz/courses/udacity/nd/fyyur/udacity_nd/lib/python3.10/site-packages/flask/app.py", line 2528, in wsgi_app
    response = self.full_dispatch_request()
  File "/home/abdulaziz/abdulaziz/courses/udacity/nd/fyyur/udacity_nd/lib/python3.10/site-packages/flask/app.py", line 1825, in full_dispatch_request
    rv = self.handle_user_exception(e)
  File "/home/abdulaziz/abdulaziz/courses/udacity/nd/fyyur/udacity_nd/lib/python3.10/site-packages/flask/app.py", line 1823, in full_dispatch_request
    rv = self.dispatch_request()
  File "/home/abdulaziz/abdulaziz/courses/udacity/nd/fyyur/udacity_nd/lib/python3.10/site-packages/flask/app.py", line 1799, in dispatch_request
    return self.ensure_sync(self.view_functions[rule.endpoint])(**view_args)
  File "/home/abdulaziz/abdulaziz/courses/udacity/nd/fyyur/app.py", line 336, in edit_artist
    return render_template('forms/edit_artist.html', form=form, artist=data)
  File "/home/abdulaziz/abdulaziz/courses/udacity/nd/fyyur/udacity_nd/lib/python3.10/site-packages/flask/templating.py", line 147, in render_template
    return _render(app, template, context)
  File "/home/abdulaziz/abdulaziz/courses/udacity/nd/fyyur/udacity_nd/lib/python3.10/site-packages/flask/templating.py", line 130, in _render
    rv = template.render(context)
  File "/home/abdulaziz/abdulaziz/courses/udacity/nd/fyyur/udacity_nd/lib/python3.10/site-packages/jinja2/environment.py", line 1301, in render
    self.environment.handle_exception()
  File "/home/abdulaziz/abdulaziz/courses/udacity/nd/fyyur/udacity_nd/lib/python3.10/site-packages/jinja2/environment.py", line 936, in handle_exception
    raise rewrite_traceback_stack(source=source)
  File "/home/abdulaziz/abdulaziz/courses/udacity/nd/fyyur/templates/forms/edit_artist.html", line 1, in top-level template code
    {% extends 'layouts/main.html' %}
  File "/home/abdulaziz/abdulaziz/courses/udacity/nd/fyyur/templates/layouts/main.html", line 103, in top-level template code
    {% block content %}{% endblock %}
  File "/home/abdulaziz/abdulaziz/courses/udacity/nd/fyyur/templates/forms/edit_artist.html", line 9, in block 'content'
    {{ form.name(class_ = 'form-control', autofocus = true) }}
TypeError: 'str' object is not callable
2023-04-08 19:35:12,734 INFO: errors [in /home/abdulaziz/abdulaziz/courses/udacity/nd/fyyur/app.py:486]
2023-04-08 19:35:13,443 ERROR: Exception on /artists/4/edit [GET] [in /home/abdulaziz/abdulaziz/courses/udacity/nd/fyyur/udacity_nd/lib/python3.10/site-packages/flask/app.py:1744]
Traceback (most recent call last):
  File "/home/abdulaziz/abdulaziz/courses/udacity/nd/fyyur/udacity_nd/lib/python3.10/site-packages/flask/app.py", line 2528, in wsgi_app
    response = self.full_dispatch_request()
  File "/home/abdulaziz/abdulaziz/courses/udacity/nd/fyyur/udacity_nd/lib/python3.10/site-packages/flask/app.py", line 1825, in full_dispatch_request
    rv = self.handle_user_exception(e)
  File "/home/abdulaziz/abdulaziz/courses/udacity/nd/fyyur/udacity_nd/lib/python3.10/site-packages/flask/app.py", line 1823, in full_dispatch_request
    rv = self.dispatch_request()
  File "/home/abdulaziz/abdulaziz/courses/udacity/nd/fyyur/udacity_nd/lib/python3.10/site-packages/flask/app.py", line 1799, in dispatch_request
    return self.ensure_sync(self.view_functions[rule.endpoint])(**view_args)
  File "/home/abdulaziz/abdulaziz/courses/udacity/nd/fyyur/app.py", line 323, in edit_artist
    return render_template('forms/edit_artist.html', form=form, artist=artist)
  File "/home/abdulaziz/abdulaziz/courses/udacity/nd/fyyur/udacity_nd/lib/python3.10/site-packages/flask/templating.py", line 147, in render_template
    return _render(app, template, context)
  File "/home/abdulaziz/abdulaziz/courses/udacity/nd/fyyur/udacity_nd/lib/python3.10/site-packages/flask/templating.py", line 130, in _render
    rv = template.render(context)
  File "/home/abdulaziz/abdulaziz/courses/udacity/nd/fyyur/udacity_nd/lib/python3.10/site-packages/jinja2/environment.py", line 1301, in render
    self.environment.handle_exception()
  File "/home/abdulaziz/abdulaziz/courses/udacity/nd/fyyur/udacity_nd/lib/python3.10/site-packages/jinja2/environment.py", line 936, in handle_exception
    raise rewrite_traceback_stack(source=source)
  File "/home/abdulaziz/abdulaziz/courses/udacity/nd/fyyur/templates/forms/edit_artist.html", line 1, in top-level template code
    {% extends 'layouts/main.html' %}
  File "/home/abdulaziz/abdulaziz/courses/udacity/nd/fyyur/templates/layouts/main.html", line 103, in top-level template code
    {% block content %}{% endblock %}
  File "/home/abdulaziz/abdulaziz/courses/udacity/nd/fyyur/templates/forms/edit_artist.html", line 9, in block 'content'
    {{ form.name(class_ = 'form-control', autofocus = true) }}
TypeError: 'str' object is not callable
2023-04-08 19:35:27,552 INFO: errors [in /home/abdulaziz/abdulaziz/courses/udacity/nd/fyyur/app.py:498]
2023-04-08 19:35:28,417 ERROR: Exception on /artists/4/edit [GET] [in /home/abdulaziz/abdulaziz/courses/udacity/nd/fyyur/udacity_nd/lib/python3.10/site-packages/flask/app.py:1744]
Traceback (most recent call last):
  File "/home/abdulaziz/abdulaziz/courses/udacity/nd/fyyur/udacity_nd/lib/python3.10/site-packages/flask/app.py", line 2528, in wsgi_app
    response = self.full_dispatch_request()
  File "/home/abdulaziz/abdulaziz/courses/udacity/nd/fyyur/udacity_nd/lib/python3.10/site-packages/flask/app.py", line 1825, in full_dispatch_request
    rv = self.handle_user_exception(e)
  File "/home/abdulaziz/abdulaziz/courses/udacity/nd/fyyur/udacity_nd/lib/python3.10/site-packages/flask/app.py", line 1823, in full_dispatch_request
    rv = self.dispatch_request()
  File "/home/abdulaziz/abdulaziz/courses/udacity/nd/fyyur/udacity_nd/lib/python3.10/site-packages/flask/app.py", line 1799, in dispatch_request
    return self.ensure_sync(self.view_functions[rule.endpoint])(**view_args)
  File "/home/abdulaziz/abdulaziz/courses/udacity/nd/fyyur/app.py", line 335, in edit_artist
    return render_template('forms/edit_artist.html', form=form, artist=data)
  File "/home/abdulaziz/abdulaziz/courses/udacity/nd/fyyur/udacity_nd/lib/python3.10/site-packages/flask/templating.py", line 147, in render_template
    return _render(app, template, context)
  File "/home/abdulaziz/abdulaziz/courses/udacity/nd/fyyur/udacity_nd/lib/python3.10/site-packages/flask/templating.py", line 130, in _render
    rv = template.render(context)
  File "/home/abdulaziz/abdulaziz/courses/udacity/nd/fyyur/udacity_nd/lib/python3.10/site-packages/jinja2/environment.py", line 1301, in render
    self.environment.handle_exception()
  File "/home/abdulaziz/abdulaziz/courses/udacity/nd/fyyur/udacity_nd/lib/python3.10/site-packages/jinja2/environment.py", line 936, in handle_exception
    raise rewrite_traceback_stack(source=source)
  File "/home/abdulaziz/abdulaziz/courses/udacity/nd/fyyur/templates/forms/edit_artist.html", line 1, in top-level template code
    {% extends 'layouts/main.html' %}
  File "/home/abdulaziz/abdulaziz/courses/udacity/nd/fyyur/templates/layouts/main.html", line 103, in top-level template code
    {% block content %}{% endblock %}
  File "/home/abdulaziz/abdulaziz/courses/udacity/nd/fyyur/templates/forms/edit_artist.html", line 9, in block 'content'
    {{ form.name(class_ = 'form-control', autofocus = true) }}
TypeError: 'str' object is not callable
2023-04-08 19:35:37,010 INFO: errors [in /home/abdulaziz/abdulaziz/courses/udacity/nd/fyyur/app.py:498]
2023-04-08 19:35:43,196 ERROR: Exception on /artists/1/edit [GET] [in /home/abdulaziz/abdulaziz/courses/udacity/nd/fyyur/udacity_nd/lib/python3.10/site-packages/flask/app.py:1744]
Traceback (most recent call last):
  File "/home/abdulaziz/abdulaziz/courses/udacity/nd/fyyur/udacity_nd/lib/python3.10/site-packages/flask/app.py", line 2528, in wsgi_app
    response = self.full_dispatch_request()
  File "/home/abdulaziz/abdulaziz/courses/udacity/nd/fyyur/udacity_nd/lib/python3.10/site-packages/flask/app.py", line 1825, in full_dispatch_request
    rv = self.handle_user_exception(e)
  File "/home/abdulaziz/abdulaziz/courses/udacity/nd/fyyur/udacity_nd/lib/python3.10/site-packages/flask/app.py", line 1823, in full_dispatch_request
    rv = self.dispatch_request()
  File "/home/abdulaziz/abdulaziz/courses/udacity/nd/fyyur/udacity_nd/lib/python3.10/site-packages/flask/app.py", line 1799, in dispatch_request
    return self.ensure_sync(self.view_functions[rule.endpoint])(**view_args)
  File "/home/abdulaziz/abdulaziz/courses/udacity/nd/fyyur/app.py", line 335, in edit_artist
    return render_template('forms/edit_artist.html', form=form, artist=data)
  File "/home/abdulaziz/abdulaziz/courses/udacity/nd/fyyur/udacity_nd/lib/python3.10/site-packages/flask/templating.py", line 147, in render_template
    return _render(app, template, context)
  File "/home/abdulaziz/abdulaziz/courses/udacity/nd/fyyur/udacity_nd/lib/python3.10/site-packages/flask/templating.py", line 130, in _render
    rv = template.render(context)
  File "/home/abdulaziz/abdulaziz/courses/udacity/nd/fyyur/udacity_nd/lib/python3.10/site-packages/jinja2/environment.py", line 1301, in render
    self.environment.handle_exception()
  File "/home/abdulaziz/abdulaziz/courses/udacity/nd/fyyur/udacity_nd/lib/python3.10/site-packages/jinja2/environment.py", line 936, in handle_exception
    raise rewrite_traceback_stack(source=source)
  File "/home/abdulaziz/abdulaziz/courses/udacity/nd/fyyur/templates/forms/edit_artist.html", line 1, in top-level template code
    {% extends 'layouts/main.html' %}
  File "/home/abdulaziz/abdulaziz/courses/udacity/nd/fyyur/templates/layouts/main.html", line 103, in top-level template code
    {% block content %}{% endblock %}
  File "/home/abdulaziz/abdulaziz/courses/udacity/nd/fyyur/templates/forms/edit_artist.html", line 9, in block 'content'
    {{ form.name(class_ = 'form-control', autofocus = true) }}
TypeError: 'str' object is not callable
2023-04-08 19:36:47,875 INFO: errors [in /home/abdulaziz/abdulaziz/courses/udacity/nd/fyyur/app.py:484]
2023-04-08 19:36:50,868 ERROR: Exception on /artists/1/edit [GET] [in /home/abdulaziz/abdulaziz/courses/udacity/nd/fyyur/udacity_nd/lib/python3.10/site-packages/flask/app.py:1744]
Traceback (most recent call last):
  File "/home/abdulaziz/abdulaziz/courses/udacity/nd/fyyur/udacity_nd/lib/python3.10/site-packages/flask/app.py", line 2528, in wsgi_app
    response = self.full_dispatch_request()
  File "/home/abdulaziz/abdulaziz/courses/udacity/nd/fyyur/udacity_nd/lib/python3.10/site-packages/flask/app.py", line 1825, in full_dispatch_request
    rv = self.handle_user_exception(e)
  File "/home/abdulaziz/abdulaziz/courses/udacity/nd/fyyur/udacity_nd/lib/python3.10/site-packages/flask/app.py", line 1823, in full_dispatch_request
    rv = self.dispatch_request()
  File "/home/abdulaziz/abdulaziz/courses/udacity/nd/fyyur/udacity_nd/lib/python3.10/site-packages/flask/app.py", line 1799, in dispatch_request
    return self.ensure_sync(self.view_functions[rule.endpoint])(**view_args)
  File "/home/abdulaziz/abdulaziz/courses/udacity/nd/fyyur/app.py", line 321, in edit_artist
    return render_template('forms/edit_artist.html', form=form, artist=artist)
  File "/home/abdulaziz/abdulaziz/courses/udacity/nd/fyyur/udacity_nd/lib/python3.10/site-packages/flask/templating.py", line 147, in render_template
    return _render(app, template, context)
  File "/home/abdulaziz/abdulaziz/courses/udacity/nd/fyyur/udacity_nd/lib/python3.10/site-packages/flask/templating.py", line 130, in _render
    rv = template.render(context)
  File "/home/abdulaziz/abdulaziz/courses/udacity/nd/fyyur/udacity_nd/lib/python3.10/site-packages/jinja2/environment.py", line 1301, in render
    self.environment.handle_exception()
  File "/home/abdulaziz/abdulaziz/courses/udacity/nd/fyyur/udacity_nd/lib/python3.10/site-packages/jinja2/environment.py", line 936, in handle_exception
    raise rewrite_traceback_stack(source=source)
  File "/home/abdulaziz/abdulaziz/courses/udacity/nd/fyyur/templates/forms/edit_artist.html", line 1, in top-level template code
    {% extends 'layouts/main.html' %}
  File "/home/abdulaziz/abdulaziz/courses/udacity/nd/fyyur/templates/layouts/main.html", line 103, in top-level template code
    {% block content %}{% endblock %}
  File "/home/abdulaziz/abdulaziz/courses/udacity/nd/fyyur/templates/forms/edit_artist.html", line 9, in block 'content'
    {{ form.name(class_ = 'form-control', autofocus = true) }}
TypeError: 'str' object is not callable
2023-04-08 19:38:58,199 INFO: errors [in /home/abdulaziz/abdulaziz/courses/udacity/nd/fyyur/app.py:484]
2023-04-08 19:39:00,119 ERROR: Exception on /artists/1/edit [GET] [in /home/abdulaziz/abdulaziz/courses/udacity/nd/fyyur/udacity_nd/lib/python3.10/site-packages/flask/app.py:1744]
Traceback (most recent call last):
  File "/home/abdulaziz/abdulaziz/courses/udacity/nd/fyyur/udacity_nd/lib/python3.10/site-packages/flask/app.py", line 2528, in wsgi_app
    response = self.full_dispatch_request()
  File "/home/abdulaziz/abdulaziz/courses/udacity/nd/fyyur/udacity_nd/lib/python3.10/site-packages/flask/app.py", line 1825, in full_dispatch_request
    rv = self.handle_user_exception(e)
  File "/home/abdulaziz/abdulaziz/courses/udacity/nd/fyyur/udacity_nd/lib/python3.10/site-packages/flask/app.py", line 1823, in full_dispatch_request
    rv = self.dispatch_request()
  File "/home/abdulaziz/abdulaziz/courses/udacity/nd/fyyur/udacity_nd/lib/python3.10/site-packages/flask/app.py", line 1799, in dispatch_request
    return self.ensure_sync(self.view_functions[rule.endpoint])(**view_args)
  File "/home/abdulaziz/abdulaziz/courses/udacity/nd/fyyur/app.py", line 310, in edit_artist
    form["name"] = artist.name
  File "/home/abdulaziz/abdulaziz/courses/udacity/nd/fyyur/udacity_nd/lib/python3.10/site-packages/wtforms/form.py", line 289, in __setitem__
    raise TypeError("Fields may not be added to Form instances, only classes.")
TypeError: Fields may not be added to Form instances, only classes.
2023-04-08 19:39:18,552 INFO: errors [in /home/abdulaziz/abdulaziz/courses/udacity/nd/fyyur/app.py:484]
2023-04-08 19:39:19,158 ERROR: Exception on /artists/1/edit [GET] [in /home/abdulaziz/abdulaziz/courses/udacity/nd/fyyur/udacity_nd/lib/python3.10/site-packages/flask/app.py:1744]
Traceback (most recent call last):
  File "/home/abdulaziz/abdulaziz/courses/udacity/nd/fyyur/udacity_nd/lib/python3.10/site-packages/flask/app.py", line 2528, in wsgi_app
    response = self.full_dispatch_request()
  File "/home/abdulaziz/abdulaziz/courses/udacity/nd/fyyur/udacity_nd/lib/python3.10/site-packages/flask/app.py", line 1825, in full_dispatch_request
    rv = self.handle_user_exception(e)
  File "/home/abdulaziz/abdulaziz/courses/udacity/nd/fyyur/udacity_nd/lib/python3.10/site-packages/flask/app.py", line 1823, in full_dispatch_request
    rv = self.dispatch_request()
  File "/home/abdulaziz/abdulaziz/courses/udacity/nd/fyyur/udacity_nd/lib/python3.10/site-packages/flask/app.py", line 1799, in dispatch_request
    return self.ensure_sync(self.view_functions[rule.endpoint])(**view_args)
  File "/home/abdulaziz/abdulaziz/courses/udacity/nd/fyyur/app.py", line 321, in edit_artist
    return render_template('forms/edit_artist.html', form=form, artist=artist)
  File "/home/abdulaziz/abdulaziz/courses/udacity/nd/fyyur/udacity_nd/lib/python3.10/site-packages/flask/templating.py", line 147, in render_template
    return _render(app, template, context)
  File "/home/abdulaziz/abdulaziz/courses/udacity/nd/fyyur/udacity_nd/lib/python3.10/site-packages/flask/templating.py", line 130, in _render
    rv = template.render(context)
  File "/home/abdulaziz/abdulaziz/courses/udacity/nd/fyyur/udacity_nd/lib/python3.10/site-packages/jinja2/environment.py", line 1301, in render
    self.environment.handle_exception()
  File "/home/abdulaziz/abdulaziz/courses/udacity/nd/fyyur/udacity_nd/lib/python3.10/site-packages/jinja2/environment.py", line 936, in handle_exception
    raise rewrite_traceback_stack(source=source)
  File "/home/abdulaziz/abdulaziz/courses/udacity/nd/fyyur/templates/forms/edit_artist.html", line 1, in top-level template code
    {% extends 'layouts/main.html' %}
  File "/home/abdulaziz/abdulaziz/courses/udacity/nd/fyyur/templates/layouts/main.html", line 103, in top-level template code
    {% block content %}{% endblock %}
  File "/home/abdulaziz/abdulaziz/courses/udacity/nd/fyyur/templates/forms/edit_artist.html", line 9, in block 'content'
    {{ form.name(class_ = 'form-control', autofocus = true) }}
TypeError: 'str' object is not callable
2023-04-08 19:39:53,731 INFO: errors [in /home/abdulaziz/abdulaziz/courses/udacity/nd/fyyur/app.py:474]
2023-04-08 19:40:08,125 INFO: errors [in /home/abdulaziz/abdulaziz/courses/udacity/nd/fyyur/app.py:474]
2023-04-08 19:40:09,040 ERROR: Exception on /artists/1/edit [GET] [in /home/abdulaziz/abdulaziz/courses/udacity/nd/fyyur/udacity_nd/lib/python3.10/site-packages/flask/app.py:1744]
Traceback (most recent call last):
  File "/home/abdulaziz/abdulaziz/courses/udacity/nd/fyyur/udacity_nd/lib/python3.10/site-packages/flask/app.py", line 2528, in wsgi_app
    response = self.full_dispatch_request()
  File "/home/abdulaziz/abdulaziz/courses/udacity/nd/fyyur/udacity_nd/lib/python3.10/site-packages/flask/app.py", line 1825, in full_dispatch_request
    rv = self.handle_user_exception(e)
  File "/home/abdulaziz/abdulaziz/courses/udacity/nd/fyyur/udacity_nd/lib/python3.10/site-packages/flask/app.py", line 1823, in full_dispatch_request
    rv = self.dispatch_request()
  File "/home/abdulaziz/abdulaziz/courses/udacity/nd/fyyur/udacity_nd/lib/python3.10/site-packages/flask/app.py", line 1799, in dispatch_request
    return self.ensure_sync(self.view_functions[rule.endpoint])(**view_args)
  File "/home/abdulaziz/abdulaziz/courses/udacity/nd/fyyur/app.py", line 311, in edit_artist
    return render_template('forms/edit_artist.html', form=form, artist=artist)
  File "/home/abdulaziz/abdulaziz/courses/udacity/nd/fyyur/udacity_nd/lib/python3.10/site-packages/flask/templating.py", line 147, in render_template
    return _render(app, template, context)
  File "/home/abdulaziz/abdulaziz/courses/udacity/nd/fyyur/udacity_nd/lib/python3.10/site-packages/flask/templating.py", line 130, in _render
    rv = template.render(context)
  File "/home/abdulaziz/abdulaziz/courses/udacity/nd/fyyur/udacity_nd/lib/python3.10/site-packages/jinja2/environment.py", line 1301, in render
    self.environment.handle_exception()
  File "/home/abdulaziz/abdulaziz/courses/udacity/nd/fyyur/udacity_nd/lib/python3.10/site-packages/jinja2/environment.py", line 936, in handle_exception
    raise rewrite_traceback_stack(source=source)
  File "/home/abdulaziz/abdulaziz/courses/udacity/nd/fyyur/templates/forms/edit_artist.html", line 1, in top-level template code
    {% extends 'layouts/main.html' %}
  File "/home/abdulaziz/abdulaziz/courses/udacity/nd/fyyur/templates/layouts/main.html", line 103, in top-level template code
    {% block content %}{% endblock %}
  File "/home/abdulaziz/abdulaziz/courses/udacity/nd/fyyur/templates/forms/edit_artist.html", line 9, in block 'content'
    {{ form.name(class_ = 'form-control', autofocus = true) }}
TypeError: 'str' object is not callable
2023-04-08 19:40:16,361 ERROR: Exception on /artists/1/edit [GET] [in /home/abdulaziz/abdulaziz/courses/udacity/nd/fyyur/udacity_nd/lib/python3.10/site-packages/flask/app.py:1744]
Traceback (most recent call last):
  File "/home/abdulaziz/abdulaziz/courses/udacity/nd/fyyur/udacity_nd/lib/python3.10/site-packages/flask/app.py", line 2528, in wsgi_app
    response = self.full_dispatch_request()
  File "/home/abdulaziz/abdulaziz/courses/udacity/nd/fyyur/udacity_nd/lib/python3.10/site-packages/flask/app.py", line 1825, in full_dispatch_request
    rv = self.handle_user_exception(e)
  File "/home/abdulaziz/abdulaziz/courses/udacity/nd/fyyur/udacity_nd/lib/python3.10/site-packages/flask/app.py", line 1823, in full_dispatch_request
    rv = self.dispatch_request()
  File "/home/abdulaziz/abdulaziz/courses/udacity/nd/fyyur/udacity_nd/lib/python3.10/site-packages/flask/app.py", line 1799, in dispatch_request
    return self.ensure_sync(self.view_functions[rule.endpoint])(**view_args)
  File "/home/abdulaziz/abdulaziz/courses/udacity/nd/fyyur/app.py", line 311, in edit_artist
    return render_template('forms/edit_artist.html', form=form, artist=artist)
  File "/home/abdulaziz/abdulaziz/courses/udacity/nd/fyyur/udacity_nd/lib/python3.10/site-packages/flask/templating.py", line 147, in render_template
    return _render(app, template, context)
  File "/home/abdulaziz/abdulaziz/courses/udacity/nd/fyyur/udacity_nd/lib/python3.10/site-packages/flask/templating.py", line 130, in _render
    rv = template.render(context)
  File "/home/abdulaziz/abdulaziz/courses/udacity/nd/fyyur/udacity_nd/lib/python3.10/site-packages/jinja2/environment.py", line 1301, in render
    self.environment.handle_exception()
  File "/home/abdulaziz/abdulaziz/courses/udacity/nd/fyyur/udacity_nd/lib/python3.10/site-packages/jinja2/environment.py", line 936, in handle_exception
    raise rewrite_traceback_stack(source=source)
  File "/home/abdulaziz/abdulaziz/courses/udacity/nd/fyyur/templates/forms/edit_artist.html", line 1, in top-level template code
    {% extends 'layouts/main.html' %}
  File "/home/abdulaziz/abdulaziz/courses/udacity/nd/fyyur/templates/layouts/main.html", line 103, in top-level template code
    {% block content %}{% endblock %}
  File "/home/abdulaziz/abdulaziz/courses/udacity/nd/fyyur/templates/forms/edit_artist.html", line 9, in block 'content'
    {{ form.name(class_ = 'form-control', autofocus = true) }}
TypeError: 'str' object is not callable
2023-04-08 19:40:33,153 INFO: errors [in /home/abdulaziz/abdulaziz/courses/udacity/nd/fyyur/app.py:483]
2023-04-08 19:40:33,928 ERROR: Exception on /artists/1/edit [GET] [in /home/abdulaziz/abdulaziz/courses/udacity/nd/fyyur/udacity_nd/lib/python3.10/site-packages/flask/app.py:1744]
Traceback (most recent call last):
  File "/home/abdulaziz/abdulaziz/courses/udacity/nd/fyyur/udacity_nd/lib/python3.10/site-packages/flask/app.py", line 2528, in wsgi_app
    response = self.full_dispatch_request()
  File "/home/abdulaziz/abdulaziz/courses/udacity/nd/fyyur/udacity_nd/lib/python3.10/site-packages/flask/app.py", line 1825, in full_dispatch_request
    rv = self.handle_user_exception(e)
  File "/home/abdulaziz/abdulaziz/courses/udacity/nd/fyyur/udacity_nd/lib/python3.10/site-packages/flask/app.py", line 1823, in full_dispatch_request
    rv = self.dispatch_request()
  File "/home/abdulaziz/abdulaziz/courses/udacity/nd/fyyur/udacity_nd/lib/python3.10/site-packages/flask/app.py", line 1799, in dispatch_request
    return self.ensure_sync(self.view_functions[rule.endpoint])(**view_args)
  File "/home/abdulaziz/abdulaziz/courses/udacity/nd/fyyur/app.py", line 309, in edit_artist
    form.name = artist.name
NameError: name 'artist' is not defined
2023-04-08 19:40:47,772 INFO: errors [in /home/abdulaziz/abdulaziz/courses/udacity/nd/fyyur/app.py:484]
2023-04-08 19:40:48,914 ERROR: Exception on /artists/1/edit [GET] [in /home/abdulaziz/abdulaziz/courses/udacity/nd/fyyur/udacity_nd/lib/python3.10/site-packages/flask/app.py:1744]
Traceback (most recent call last):
  File "/home/abdulaziz/abdulaziz/courses/udacity/nd/fyyur/udacity_nd/lib/python3.10/site-packages/flask/app.py", line 2528, in wsgi_app
    response = self.full_dispatch_request()
  File "/home/abdulaziz/abdulaziz/courses/udacity/nd/fyyur/udacity_nd/lib/python3.10/site-packages/flask/app.py", line 1825, in full_dispatch_request
    rv = self.handle_user_exception(e)
  File "/home/abdulaziz/abdulaziz/courses/udacity/nd/fyyur/udacity_nd/lib/python3.10/site-packages/flask/app.py", line 1823, in full_dispatch_request
    rv = self.dispatch_request()
  File "/home/abdulaziz/abdulaziz/courses/udacity/nd/fyyur/udacity_nd/lib/python3.10/site-packages/flask/app.py", line 1799, in dispatch_request
    return self.ensure_sync(self.view_functions[rule.endpoint])(**view_args)
  File "/home/abdulaziz/abdulaziz/courses/udacity/nd/fyyur/app.py", line 321, in edit_artist
    return render_template('forms/edit_artist.html', form=form)
  File "/home/abdulaziz/abdulaziz/courses/udacity/nd/fyyur/udacity_nd/lib/python3.10/site-packages/flask/templating.py", line 147, in render_template
    return _render(app, template, context)
  File "/home/abdulaziz/abdulaziz/courses/udacity/nd/fyyur/udacity_nd/lib/python3.10/site-packages/flask/templating.py", line 130, in _render
    rv = template.render(context)
  File "/home/abdulaziz/abdulaziz/courses/udacity/nd/fyyur/udacity_nd/lib/python3.10/site-packages/jinja2/environment.py", line 1301, in render
    self.environment.handle_exception()
  File "/home/abdulaziz/abdulaziz/courses/udacity/nd/fyyur/udacity_nd/lib/python3.10/site-packages/jinja2/environment.py", line 936, in handle_exception
    raise rewrite_traceback_stack(source=source)
  File "/home/abdulaziz/abdulaziz/courses/udacity/nd/fyyur/templates/forms/edit_artist.html", line 1, in top-level template code
    {% extends 'layouts/main.html' %}
  File "/home/abdulaziz/abdulaziz/courses/udacity/nd/fyyur/templates/layouts/main.html", line 103, in top-level template code
    {% block content %}{% endblock %}
  File "/home/abdulaziz/abdulaziz/courses/udacity/nd/fyyur/templates/forms/edit_artist.html", line 5, in block 'content'
    <form class="form" method="post" action="/artists/{{artist.id}}/edit">
  File "/home/abdulaziz/abdulaziz/courses/udacity/nd/fyyur/udacity_nd/lib/python3.10/site-packages/jinja2/environment.py", line 485, in getattr
    return getattr(obj, attribute)
jinja2.exceptions.UndefinedError: 'artist' is undefined
2023-04-08 19:41:00,442 INFO: errors [in /home/abdulaziz/abdulaziz/courses/udacity/nd/fyyur/app.py:484]
2023-04-08 19:41:01,223 ERROR: Exception on /artists/1/edit [GET] [in /home/abdulaziz/abdulaziz/courses/udacity/nd/fyyur/udacity_nd/lib/python3.10/site-packages/flask/app.py:1744]
Traceback (most recent call last):
  File "/home/abdulaziz/abdulaziz/courses/udacity/nd/fyyur/udacity_nd/lib/python3.10/site-packages/flask/app.py", line 2528, in wsgi_app
    response = self.full_dispatch_request()
  File "/home/abdulaziz/abdulaziz/courses/udacity/nd/fyyur/udacity_nd/lib/python3.10/site-packages/flask/app.py", line 1825, in full_dispatch_request
    rv = self.handle_user_exception(e)
  File "/home/abdulaziz/abdulaziz/courses/udacity/nd/fyyur/udacity_nd/lib/python3.10/site-packages/flask/app.py", line 1823, in full_dispatch_request
    rv = self.dispatch_request()
  File "/home/abdulaziz/abdulaziz/courses/udacity/nd/fyyur/udacity_nd/lib/python3.10/site-packages/flask/app.py", line 1799, in dispatch_request
    return self.ensure_sync(self.view_functions[rule.endpoint])(**view_args)
  File "/home/abdulaziz/abdulaziz/courses/udacity/nd/fyyur/app.py", line 321, in edit_artist
    return render_template('forms/edit_artist.html', form=form, artist=artist)
  File "/home/abdulaziz/abdulaziz/courses/udacity/nd/fyyur/udacity_nd/lib/python3.10/site-packages/flask/templating.py", line 147, in render_template
    return _render(app, template, context)
  File "/home/abdulaziz/abdulaziz/courses/udacity/nd/fyyur/udacity_nd/lib/python3.10/site-packages/flask/templating.py", line 130, in _render
    rv = template.render(context)
  File "/home/abdulaziz/abdulaziz/courses/udacity/nd/fyyur/udacity_nd/lib/python3.10/site-packages/jinja2/environment.py", line 1301, in render
    self.environment.handle_exception()
  File "/home/abdulaziz/abdulaziz/courses/udacity/nd/fyyur/udacity_nd/lib/python3.10/site-packages/jinja2/environment.py", line 936, in handle_exception
    raise rewrite_traceback_stack(source=source)
  File "/home/abdulaziz/abdulaziz/courses/udacity/nd/fyyur/templates/forms/edit_artist.html", line 1, in top-level template code
    {% extends 'layouts/main.html' %}
  File "/home/abdulaziz/abdulaziz/courses/udacity/nd/fyyur/templates/layouts/main.html", line 103, in top-level template code
    {% block content %}{% endblock %}
  File "/home/abdulaziz/abdulaziz/courses/udacity/nd/fyyur/templates/forms/edit_artist.html", line 9, in block 'content'
    {{ form.name(class_ = 'form-control', autofocus = true) }}
TypeError: 'str' object is not callable
2023-04-08 19:41:25,229 INFO: errors [in /home/abdulaziz/abdulaziz/courses/udacity/nd/fyyur/app.py:487]
2023-04-08 19:43:23,961 INFO: errors [in /home/abdulaziz/abdulaziz/courses/udacity/nd/fyyur/app.py:492]
2023-04-08 19:50:12,716 INFO: errors [in /home/abdulaziz/abdulaziz/courses/udacity/nd/fyyur/app.py:497]
2023-04-08 19:53:40,069 INFO: errors [in /home/abdulaziz/abdulaziz/courses/udacity/nd/fyyur/app.py:518]
2023-04-08 23:32:37,090 INFO: errors [in /home/abdulaziz/abdulaziz/courses/udacity/nd/fyyur/app.py:518]
2023-04-09 00:00:50,107 INFO: errors [in /home/abdulaziz/abdulaziz/courses/udacity/nd/fyyur/app.py:527]
2023-04-09 00:02:56,942 INFO: errors [in /home/abdulaziz/abdulaziz/courses/udacity/nd/fyyur/app.py:527]
2023-04-09 00:05:51,487 INFO: errors [in /home/abdulaziz/abdulaziz/courses/udacity/nd/fyyur/app.py:527]
2023-04-09 00:06:52,606 INFO: errors [in /home/abdulaziz/abdulaziz/courses/udacity/nd/fyyur/app.py:527]
2023-04-09 00:08:34,078 INFO: errors [in /home/abdulaziz/abdulaziz/courses/udacity/nd/fyyur/app.py:527]
2023-04-09 00:14:46,500 INFO: errors [in /home/abdulaziz/abdulaziz/courses/udacity/nd/fyyur/app.py:527]
2023-04-09 00:15:16,501 INFO: errors [in /home/abdulaziz/abdulaziz/courses/udacity/nd/fyyur/app.py:527]
2023-04-09 00:15:19,579 ERROR: Exception on /venues/3 [GET] [in /home/abdulaziz/abdulaziz/courses/udacity/nd/fyyur/udacity_nd/lib/python3.10/site-packages/flask/app.py:1744]
Traceback (most recent call last):
  File "/home/abdulaziz/abdulaziz/courses/udacity/nd/fyyur/udacity_nd/lib/python3.10/site-packages/flask/app.py", line 2528, in wsgi_app
    response = self.full_dispatch_request()
  File "/home/abdulaziz/abdulaziz/courses/udacity/nd/fyyur/udacity_nd/lib/python3.10/site-packages/flask/app.py", line 1825, in full_dispatch_request
    rv = self.handle_user_exception(e)
  File "/home/abdulaziz/abdulaziz/courses/udacity/nd/fyyur/udacity_nd/lib/python3.10/site-packages/flask/app.py", line 1823, in full_dispatch_request
    rv = self.dispatch_request()
  File "/home/abdulaziz/abdulaziz/courses/udacity/nd/fyyur/udacity_nd/lib/python3.10/site-packages/flask/app.py", line 1799, in dispatch_request
    return self.ensure_sync(self.view_functions[rule.endpoint])(**view_args)
  File "/home/abdulaziz/abdulaziz/courses/udacity/nd/fyyur/app.py", line 165, in show_venue
    upcoming_shows.append(result) if show.start_time > current_date else past_shows.append(result)
UnboundLocalError: local variable 'show' referenced before assignment
2023-04-09 00:15:58,899 INFO: errors [in /home/abdulaziz/abdulaziz/courses/udacity/nd/fyyur/app.py:527]
2023-04-09 00:16:26,500 INFO: errors [in /home/abdulaziz/abdulaziz/courses/udacity/nd/fyyur/app.py:527]
2023-04-09 00:19:24,611 INFO: errors [in /home/abdulaziz/abdulaziz/courses/udacity/nd/fyyur/app.py:527]
2023-04-09 00:19:29,331 ERROR: Exception on /venues/3 [GET] [in /home/abdulaziz/abdulaziz/courses/udacity/nd/fyyur/udacity_nd/lib/python3.10/site-packages/flask/app.py:1744]
Traceback (most recent call last):
  File "/home/abdulaziz/abdulaziz/courses/udacity/nd/fyyur/udacity_nd/lib/python3.10/site-packages/flask/app.py", line 2528, in wsgi_app
    response = self.full_dispatch_request()
  File "/home/abdulaziz/abdulaziz/courses/udacity/nd/fyyur/udacity_nd/lib/python3.10/site-packages/flask/app.py", line 1825, in full_dispatch_request
    rv = self.handle_user_exception(e)
  File "/home/abdulaziz/abdulaziz/courses/udacity/nd/fyyur/udacity_nd/lib/python3.10/site-packages/flask/app.py", line 1823, in full_dispatch_request
    rv = self.dispatch_request()
  File "/home/abdulaziz/abdulaziz/courses/udacity/nd/fyyur/udacity_nd/lib/python3.10/site-packages/flask/app.py", line 1799, in dispatch_request
    return self.ensure_sync(self.view_functions[rule.endpoint])(**view_args)
  File "/home/abdulaziz/abdulaziz/courses/udacity/nd/fyyur/app.py", line 165, in show_venue
    upcoming_shows.append(result) if show.start_time > current_date else past_shows.append(result)
UnboundLocalError: local variable 'show' referenced before assignment
2023-04-09 00:20:01,759 INFO: errors [in /home/abdulaziz/abdulaziz/courses/udacity/nd/fyyur/app.py:527]
2023-04-09 00:21:01,902 ERROR: Exception on /venues/3 [GET] [in /home/abdulaziz/abdulaziz/courses/udacity/nd/fyyur/udacity_nd/lib/python3.10/site-packages/flask/app.py:1744]
Traceback (most recent call last):
  File "/home/abdulaziz/abdulaziz/courses/udacity/nd/fyyur/udacity_nd/lib/python3.10/site-packages/flask/app.py", line 2528, in wsgi_app
    response = self.full_dispatch_request()
  File "/home/abdulaziz/abdulaziz/courses/udacity/nd/fyyur/udacity_nd/lib/python3.10/site-packages/flask/app.py", line 1825, in full_dispatch_request
    rv = self.handle_user_exception(e)
  File "/home/abdulaziz/abdulaziz/courses/udacity/nd/fyyur/udacity_nd/lib/python3.10/site-packages/flask/app.py", line 1823, in full_dispatch_request
    rv = self.dispatch_request()
  File "/home/abdulaziz/abdulaziz/courses/udacity/nd/fyyur/udacity_nd/lib/python3.10/site-packages/flask/app.py", line 1799, in dispatch_request
    return self.ensure_sync(self.view_functions[rule.endpoint])(**view_args)
  File "/home/abdulaziz/abdulaziz/courses/udacity/nd/fyyur/app.py", line 165, in show_venue
    upcoming_shows.append(result) if show.start_time > current_date else past_shows.append(result)
UnboundLocalError: local variable 'show' referenced before assignment
2023-04-09 00:21:55,300 INFO: errors [in /home/abdulaziz/abdulaziz/courses/udacity/nd/fyyur/app.py:527]
2023-04-09 00:22:10,426 INFO: errors [in /home/abdulaziz/abdulaziz/courses/udacity/nd/fyyur/app.py:527]
2023-04-09 00:22:39,701 INFO: errors [in /home/abdulaziz/abdulaziz/courses/udacity/nd/fyyur/app.py:527]
2023-04-09 00:23:01,397 INFO: errors [in /home/abdulaziz/abdulaziz/courses/udacity/nd/fyyur/app.py:527]
2023-04-09 00:23:22,146 INFO: errors [in /home/abdulaziz/abdulaziz/courses/udacity/nd/fyyur/app.py:527]
2023-04-09 00:27:37,360 INFO: errors [in /home/abdulaziz/abdulaziz/courses/udacity/nd/fyyur/app.py:527]
2023-04-09 00:31:48,172 INFO: errors [in /home/abdulaziz/abdulaziz/courses/udacity/nd/fyyur/app.py:527]
2023-04-09 00:32:48,135 INFO: errors [in /home/abdulaziz/abdulaziz/courses/udacity/nd/fyyur/app.py:527]
2023-04-09 00:33:56,941 INFO: errors [in /home/abdulaziz/abdulaziz/courses/udacity/nd/fyyur/app.py:527]
2023-04-09 00:34:02,160 ERROR: Exception on /venues/3 [GET] [in /home/abdulaziz/abdulaziz/courses/udacity/nd/fyyur/udacity_nd/lib/python3.10/site-packages/flask/app.py:1744]
Traceback (most recent call last):
  File "/home/abdulaziz/abdulaziz/courses/udacity/nd/fyyur/udacity_nd/lib/python3.10/site-packages/flask/app.py", line 2528, in wsgi_app
    response = self.full_dispatch_request()
  File "/home/abdulaziz/abdulaziz/courses/udacity/nd/fyyur/udacity_nd/lib/python3.10/site-packages/flask/app.py", line 1825, in full_dispatch_request
    rv = self.handle_user_exception(e)
  File "/home/abdulaziz/abdulaziz/courses/udacity/nd/fyyur/udacity_nd/lib/python3.10/site-packages/flask/app.py", line 1823, in full_dispatch_request
    rv = self.dispatch_request()
  File "/home/abdulaziz/abdulaziz/courses/udacity/nd/fyyur/udacity_nd/lib/python3.10/site-packages/flask/app.py", line 1799, in dispatch_request
    return self.ensure_sync(self.view_functions[rule.endpoint])(**view_args)
  File "/home/abdulaziz/abdulaziz/courses/udacity/nd/fyyur/app.py", line 165, in show_venue
    upcoming_shows.append(result) if show.start_time > current_date else past_shows.append(result)
UnboundLocalError: local variable 'show' referenced before assignment
2023-04-09 00:34:29,371 INFO: errors [in /home/abdulaziz/abdulaziz/courses/udacity/nd/fyyur/app.py:527]
2023-04-09 00:36:37,322 INFO: errors [in /home/abdulaziz/abdulaziz/courses/udacity/nd/fyyur/app.py:527]
2023-04-09 00:36:54,382 INFO: errors [in /home/abdulaziz/abdulaziz/courses/udacity/nd/fyyur/app.py:527]
2023-04-09 00:37:06,742 INFO: errors [in /home/abdulaziz/abdulaziz/courses/udacity/nd/fyyur/app.py:527]
2023-04-09 00:37:13,890 ERROR: Exception on /venues/3 [GET] [in /home/abdulaziz/abdulaziz/courses/udacity/nd/fyyur/udacity_nd/lib/python3.10/site-packages/flask/app.py:1744]
Traceback (most recent call last):
  File "/home/abdulaziz/abdulaziz/courses/udacity/nd/fyyur/udacity_nd/lib/python3.10/site-packages/flask/app.py", line 2528, in wsgi_app
    response = self.full_dispatch_request()
  File "/home/abdulaziz/abdulaziz/courses/udacity/nd/fyyur/udacity_nd/lib/python3.10/site-packages/flask/app.py", line 1825, in full_dispatch_request
    rv = self.handle_user_exception(e)
  File "/home/abdulaziz/abdulaziz/courses/udacity/nd/fyyur/udacity_nd/lib/python3.10/site-packages/flask/app.py", line 1823, in full_dispatch_request
    rv = self.dispatch_request()
  File "/home/abdulaziz/abdulaziz/courses/udacity/nd/fyyur/udacity_nd/lib/python3.10/site-packages/flask/app.py", line 1799, in dispatch_request
    return self.ensure_sync(self.view_functions[rule.endpoint])(**view_args)
  File "/home/abdulaziz/abdulaziz/courses/udacity/nd/fyyur/app.py", line 165, in show_venue
    upcoming_shows.append(result) if show.start_time > current_date else past_shows.append(result)
UnboundLocalError: local variable 'show' referenced before assignment
2023-04-09 00:37:18,796 ERROR: Exception on /venues/3 [GET] [in /home/abdulaziz/abdulaziz/courses/udacity/nd/fyyur/udacity_nd/lib/python3.10/site-packages/flask/app.py:1744]
Traceback (most recent call last):
  File "/home/abdulaziz/abdulaziz/courses/udacity/nd/fyyur/udacity_nd/lib/python3.10/site-packages/flask/app.py", line 2528, in wsgi_app
    response = self.full_dispatch_request()
  File "/home/abdulaziz/abdulaziz/courses/udacity/nd/fyyur/udacity_nd/lib/python3.10/site-packages/flask/app.py", line 1825, in full_dispatch_request
    rv = self.handle_user_exception(e)
  File "/home/abdulaziz/abdulaziz/courses/udacity/nd/fyyur/udacity_nd/lib/python3.10/site-packages/flask/app.py", line 1823, in full_dispatch_request
    rv = self.dispatch_request()
  File "/home/abdulaziz/abdulaziz/courses/udacity/nd/fyyur/udacity_nd/lib/python3.10/site-packages/flask/app.py", line 1799, in dispatch_request
    return self.ensure_sync(self.view_functions[rule.endpoint])(**view_args)
  File "/home/abdulaziz/abdulaziz/courses/udacity/nd/fyyur/app.py", line 165, in show_venue
    upcoming_shows.append(result) if show.start_time > current_date else past_shows.append(result)
UnboundLocalError: local variable 'show' referenced before assignment
2023-04-09 00:37:29,913 INFO: errors [in /home/abdulaziz/abdulaziz/courses/udacity/nd/fyyur/app.py:527]
2023-04-09 00:38:42,231 INFO: errors [in /home/abdulaziz/abdulaziz/courses/udacity/nd/fyyur/app.py:527]
2023-04-09 00:39:24,038 INFO: errors [in /home/abdulaziz/abdulaziz/courses/udacity/nd/fyyur/app.py:527]
2023-04-09 00:42:33,940 INFO: errors [in /home/abdulaziz/abdulaziz/courses/udacity/nd/fyyur/app.py:527]
2023-04-09 00:42:48,746 INFO: errors [in /home/abdulaziz/abdulaziz/courses/udacity/nd/fyyur/app.py:527]
2023-04-09 00:43:05,628 INFO: errors [in /home/abdulaziz/abdulaziz/courses/udacity/nd/fyyur/app.py:527]
2023-04-09 00:43:23,294 INFO: errors [in /home/abdulaziz/abdulaziz/courses/udacity/nd/fyyur/app.py:527]
2023-04-09 00:43:41,423 INFO: errors [in /home/abdulaziz/abdulaziz/courses/udacity/nd/fyyur/app.py:527]
2023-04-09 00:47:29,978 INFO: errors [in /home/abdulaziz/abdulaziz/courses/udacity/nd/fyyur/app.py:527]
2023-04-09 00:47:56,099 INFO: errors [in /home/abdulaziz/abdulaziz/courses/udacity/nd/fyyur/app.py:527]
2023-04-09 00:48:38,486 INFO: errors [in /home/abdulaziz/abdulaziz/courses/udacity/nd/fyyur/app.py:527]
2023-04-09 00:49:55,596 INFO: errors [in /home/abdulaziz/abdulaziz/courses/udacity/nd/fyyur/app.py:527]
2023-04-09 00:50:16,287 INFO: errors [in /home/abdulaziz/abdulaziz/courses/udacity/nd/fyyur/app.py:527]
2023-04-09 00:50:31,985 INFO: errors [in /home/abdulaziz/abdulaziz/courses/udacity/nd/fyyur/app.py:527]
2023-04-09 00:51:59,598 INFO: errors [in /home/abdulaziz/abdulaziz/courses/udacity/nd/fyyur/app.py:528]
2023-04-09 00:52:18,926 INFO: errors [in /home/abdulaziz/abdulaziz/courses/udacity/nd/fyyur/app.py:528]
2023-04-09 00:52:28,902 INFO: errors [in /home/abdulaziz/abdulaziz/courses/udacity/nd/fyyur/app.py:528]
2023-04-09 00:52:34,041 ERROR: Exception on /venues/3 [GET] [in /home/abdulaziz/abdulaziz/courses/udacity/nd/fyyur/udacity_nd/lib/python3.10/site-packages/flask/app.py:1744]
Traceback (most recent call last):
  File "/home/abdulaziz/abdulaziz/courses/udacity/nd/fyyur/udacity_nd/lib/python3.10/site-packages/flask/app.py", line 2528, in wsgi_app
    response = self.full_dispatch_request()
  File "/home/abdulaziz/abdulaziz/courses/udacity/nd/fyyur/udacity_nd/lib/python3.10/site-packages/flask/app.py", line 1825, in full_dispatch_request
    rv = self.handle_user_exception(e)
  File "/home/abdulaziz/abdulaziz/courses/udacity/nd/fyyur/udacity_nd/lib/python3.10/site-packages/flask/app.py", line 1823, in full_dispatch_request
    rv = self.dispatch_request()
  File "/home/abdulaziz/abdulaziz/courses/udacity/nd/fyyur/udacity_nd/lib/python3.10/site-packages/flask/app.py", line 1799, in dispatch_request
    return self.ensure_sync(self.view_functions[rule.endpoint])(**view_args)
  File "/home/abdulaziz/abdulaziz/courses/udacity/nd/fyyur/app.py", line 165, in show_venue
    upcoming_shows.append(result) if show.start_time > current_date else past_shows.append(result)
UnboundLocalError: local variable 'show' referenced before assignment
2023-04-09 00:52:36,672 ERROR: Exception on /venues/3 [GET] [in /home/abdulaziz/abdulaziz/courses/udacity/nd/fyyur/udacity_nd/lib/python3.10/site-packages/flask/app.py:1744]
Traceback (most recent call last):
  File "/home/abdulaziz/abdulaziz/courses/udacity/nd/fyyur/udacity_nd/lib/python3.10/site-packages/flask/app.py", line 2528, in wsgi_app
    response = self.full_dispatch_request()
  File "/home/abdulaziz/abdulaziz/courses/udacity/nd/fyyur/udacity_nd/lib/python3.10/site-packages/flask/app.py", line 1825, in full_dispatch_request
    rv = self.handle_user_exception(e)
  File "/home/abdulaziz/abdulaziz/courses/udacity/nd/fyyur/udacity_nd/lib/python3.10/site-packages/flask/app.py", line 1823, in full_dispatch_request
    rv = self.dispatch_request()
  File "/home/abdulaziz/abdulaziz/courses/udacity/nd/fyyur/udacity_nd/lib/python3.10/site-packages/flask/app.py", line 1799, in dispatch_request
    return self.ensure_sync(self.view_functions[rule.endpoint])(**view_args)
  File "/home/abdulaziz/abdulaziz/courses/udacity/nd/fyyur/app.py", line 165, in show_venue
    upcoming_shows.append(result) if show.start_time > current_date else past_shows.append(result)
UnboundLocalError: local variable 'show' referenced before assignment
2023-04-09 00:52:48,894 ERROR: Exception on /venues/3 [GET] [in /home/abdulaziz/abdulaziz/courses/udacity/nd/fyyur/udacity_nd/lib/python3.10/site-packages/flask/app.py:1744]
Traceback (most recent call last):
  File "/home/abdulaziz/abdulaziz/courses/udacity/nd/fyyur/udacity_nd/lib/python3.10/site-packages/flask/app.py", line 2528, in wsgi_app
    response = self.full_dispatch_request()
  File "/home/abdulaziz/abdulaziz/courses/udacity/nd/fyyur/udacity_nd/lib/python3.10/site-packages/flask/app.py", line 1825, in full_dispatch_request
    rv = self.handle_user_exception(e)
  File "/home/abdulaziz/abdulaziz/courses/udacity/nd/fyyur/udacity_nd/lib/python3.10/site-packages/flask/app.py", line 1823, in full_dispatch_request
    rv = self.dispatch_request()
  File "/home/abdulaziz/abdulaziz/courses/udacity/nd/fyyur/udacity_nd/lib/python3.10/site-packages/flask/app.py", line 1799, in dispatch_request
    return self.ensure_sync(self.view_functions[rule.endpoint])(**view_args)
  File "/home/abdulaziz/abdulaziz/courses/udacity/nd/fyyur/app.py", line 165, in show_venue
    upcoming_shows.append(result) if show.start_time > current_date else past_shows.append(result)
UnboundLocalError: local variable 'show' referenced before assignment
2023-04-09 00:53:57,179 INFO: errors [in /home/abdulaziz/abdulaziz/courses/udacity/nd/fyyur/app.py:529]
2023-04-09 00:54:29,697 INFO: errors [in /home/abdulaziz/abdulaziz/courses/udacity/nd/fyyur/app.py:530]
2023-04-09 00:54:46,285 INFO: errors [in /home/abdulaziz/abdulaziz/courses/udacity/nd/fyyur/app.py:529]
2023-04-09 00:56:43,234 INFO: errors [in /home/abdulaziz/abdulaziz/courses/udacity/nd/fyyur/app.py:529]
2023-04-09 00:56:52,053 ERROR: Exception on /venues/3 [GET] [in /home/abdulaziz/abdulaziz/courses/udacity/nd/fyyur/udacity_nd/lib/python3.10/site-packages/flask/app.py:1744]
Traceback (most recent call last):
  File "/home/abdulaziz/abdulaziz/courses/udacity/nd/fyyur/udacity_nd/lib/python3.10/site-packages/flask/app.py", line 2528, in wsgi_app
    response = self.full_dispatch_request()
  File "/home/abdulaziz/abdulaziz/courses/udacity/nd/fyyur/udacity_nd/lib/python3.10/site-packages/flask/app.py", line 1825, in full_dispatch_request
    rv = self.handle_user_exception(e)
  File "/home/abdulaziz/abdulaziz/courses/udacity/nd/fyyur/udacity_nd/lib/python3.10/site-packages/flask/app.py", line 1823, in full_dispatch_request
    rv = self.dispatch_request()
  File "/home/abdulaziz/abdulaziz/courses/udacity/nd/fyyur/udacity_nd/lib/python3.10/site-packages/flask/app.py", line 1799, in dispatch_request
    return self.ensure_sync(self.view_functions[rule.endpoint])(**view_args)
  File "/home/abdulaziz/abdulaziz/courses/udacity/nd/fyyur/app.py", line 165, in show_venue
    upcoming_shows.append(result) if show.start_time > current_date else past_shows.append(result)
UnboundLocalError: local variable 'show' referenced before assignment
2023-04-09 00:57:23,431 INFO: errors [in /home/abdulaziz/abdulaziz/courses/udacity/nd/fyyur/app.py:530]
2023-04-09 00:57:31,223 INFO: errors [in /home/abdulaziz/abdulaziz/courses/udacity/nd/fyyur/app.py:530]
2023-04-09 00:58:18,552 INFO: errors [in /home/abdulaziz/abdulaziz/courses/udacity/nd/fyyur/app.py:533]
2023-04-09 00:58:36,040 INFO: errors [in /home/abdulaziz/abdulaziz/courses/udacity/nd/fyyur/app.py:533]
2023-04-09 00:59:07,428 INFO: errors [in /home/abdulaziz/abdulaziz/courses/udacity/nd/fyyur/app.py:533]
2023-04-09 00:59:16,735 INFO: errors [in /home/abdulaziz/abdulaziz/courses/udacity/nd/fyyur/app.py:533]
2023-04-09 00:59:33,689 INFO: errors [in /home/abdulaziz/abdulaziz/courses/udacity/nd/fyyur/app.py:533]
2023-04-09 01:00:44,395 INFO: errors [in /home/abdulaziz/abdulaziz/courses/udacity/nd/fyyur/app.py:535]
2023-04-09 01:05:22,065 INFO: errors [in /home/abdulaziz/abdulaziz/courses/udacity/nd/fyyur/app.py:537]
2023-04-09 01:05:58,771 INFO: errors [in /home/abdulaziz/abdulaziz/courses/udacity/nd/fyyur/app.py:539]
2023-04-09 01:06:15,994 INFO: errors [in /home/abdulaziz/abdulaziz/courses/udacity/nd/fyyur/app.py:538]
2023-04-09 01:06:33,631 INFO: errors [in /home/abdulaziz/abdulaziz/courses/udacity/nd/fyyur/app.py:536]
2023-04-09 01:06:43,549 INFO: errors [in /home/abdulaziz/abdulaziz/courses/udacity/nd/fyyur/app.py:536]
2023-04-09 01:07:21,363 INFO: errors [in /home/abdulaziz/abdulaziz/courses/udacity/nd/fyyur/app.py:533]
2023-04-09 01:07:33,217 INFO: errors [in /home/abdulaziz/abdulaziz/courses/udacity/nd/fyyur/app.py:533]
2023-04-09 01:07:45,394 INFO: errors [in /home/abdulaziz/abdulaziz/courses/udacity/nd/fyyur/app.py:533]
2023-04-09 01:07:52,846 INFO: errors [in /home/abdulaziz/abdulaziz/courses/udacity/nd/fyyur/app.py:533]
2023-04-09 01:07:53,831 ERROR: Exception on /venues/4 [DELETE] [in /home/abdulaziz/abdulaziz/courses/udacity/nd/fyyur/udacity_nd/lib/python3.10/site-packages/flask/app.py:1744]
Traceback (most recent call last):
  File "/home/abdulaziz/abdulaziz/courses/udacity/nd/fyyur/udacity_nd/lib/python3.10/site-packages/sqlalchemy/engine/base.py", line 1964, in _exec_single_context
    self.dialect.do_execute(
  File "/home/abdulaziz/abdulaziz/courses/udacity/nd/fyyur/udacity_nd/lib/python3.10/site-packages/sqlalchemy/engine/default.py", line 748, in do_execute
    cursor.execute(statement, parameters)
psycopg2.errors.ForeignKeyViolation: update or delete on table "venue" violates foreign key constraint "show_venue_id_fkey" on table "show"
DETAIL:  Key (id)=(4) is still referenced from table "show".


The above exception was the direct cause of the following exception:

Traceback (most recent call last):
  File "/home/abdulaziz/abdulaziz/courses/udacity/nd/fyyur/udacity_nd/lib/python3.10/site-packages/flask/app.py", line 2528, in wsgi_app
    response = self.full_dispatch_request()
  File "/home/abdulaziz/abdulaziz/courses/udacity/nd/fyyur/udacity_nd/lib/python3.10/site-packages/flask/app.py", line 1825, in full_dispatch_request
    rv = self.handle_user_exception(e)
  File "/home/abdulaziz/abdulaziz/courses/udacity/nd/fyyur/udacity_nd/lib/python3.10/site-packages/flask/app.py", line 1823, in full_dispatch_request
    rv = self.dispatch_request()
  File "/home/abdulaziz/abdulaziz/courses/udacity/nd/fyyur/udacity_nd/lib/python3.10/site-packages/flask/app.py", line 1799, in dispatch_request
    return self.ensure_sync(self.view_functions[rule.endpoint])(**view_args)
  File "/home/abdulaziz/abdulaziz/courses/udacity/nd/fyyur/app.py", line 237, in delete_venue
    print(Venue.query.filter_by(id=venue_id).delete())
  File "/home/abdulaziz/abdulaziz/courses/udacity/nd/fyyur/udacity_nd/lib/python3.10/site-packages/sqlalchemy/orm/query.py", line 3191, in delete
    self.session.execute(
  File "/home/abdulaziz/abdulaziz/courses/udacity/nd/fyyur/udacity_nd/lib/python3.10/site-packages/sqlalchemy/orm/session.py", line 2229, in execute
    return self._execute_internal(
  File "/home/abdulaziz/abdulaziz/courses/udacity/nd/fyyur/udacity_nd/lib/python3.10/site-packages/sqlalchemy/orm/session.py", line 2124, in _execute_internal
    result: Result[Any] = compile_state_cls.orm_execute_statement(
  File "/home/abdulaziz/abdulaziz/courses/udacity/nd/fyyur/udacity_nd/lib/python3.10/site-packages/sqlalchemy/orm/bulk_persistence.py", line 1838, in orm_execute_statement
    return super().orm_execute_statement(
  File "/home/abdulaziz/abdulaziz/courses/udacity/nd/fyyur/udacity_nd/lib/python3.10/site-packages/sqlalchemy/orm/context.py", line 253, in orm_execute_statement
    result = conn.execute(
  File "/home/abdulaziz/abdulaziz/courses/udacity/nd/fyyur/udacity_nd/lib/python3.10/site-packages/sqlalchemy/engine/base.py", line 1414, in execute
    return meth(
  File "/home/abdulaziz/abdulaziz/courses/udacity/nd/fyyur/udacity_nd/lib/python3.10/site-packages/sqlalchemy/sql/elements.py", line 486, in _execute_on_connection
    return connection._execute_clauseelement(
  File "/home/abdulaziz/abdulaziz/courses/udacity/nd/fyyur/udacity_nd/lib/python3.10/site-packages/sqlalchemy/engine/base.py", line 1638, in _execute_clauseelement
    ret = self._execute_context(
  File "/home/abdulaziz/abdulaziz/courses/udacity/nd/fyyur/udacity_nd/lib/python3.10/site-packages/sqlalchemy/engine/base.py", line 1842, in _execute_context
    return self._exec_single_context(
  File "/home/abdulaziz/abdulaziz/courses/udacity/nd/fyyur/udacity_nd/lib/python3.10/site-packages/sqlalchemy/engine/base.py", line 1983, in _exec_single_context
    self._handle_dbapi_exception(
  File "/home/abdulaziz/abdulaziz/courses/udacity/nd/fyyur/udacity_nd/lib/python3.10/site-packages/sqlalchemy/engine/base.py", line 2326, in _handle_dbapi_exception
    raise sqlalchemy_exception.with_traceback(exc_info[2]) from e
  File "/home/abdulaziz/abdulaziz/courses/udacity/nd/fyyur/udacity_nd/lib/python3.10/site-packages/sqlalchemy/engine/base.py", line 1964, in _exec_single_context
    self.dialect.do_execute(
  File "/home/abdulaziz/abdulaziz/courses/udacity/nd/fyyur/udacity_nd/lib/python3.10/site-packages/sqlalchemy/engine/default.py", line 748, in do_execute
    cursor.execute(statement, parameters)
sqlalchemy.exc.IntegrityError: (psycopg2.errors.ForeignKeyViolation) update or delete on table "venue" violates foreign key constraint "show_venue_id_fkey" on table "show"
DETAIL:  Key (id)=(4) is still referenced from table "show".

[SQL: DELETE FROM venue WHERE venue.id = %(id_1)s]
[parameters: {'id_1': '4'}]
(Background on this error at: https://sqlalche.me/e/20/gkpj)
2023-04-09 01:08:11,147 INFO: errors [in /home/abdulaziz/abdulaziz/courses/udacity/nd/fyyur/app.py:533]
2023-04-09 01:08:12,513 ERROR: Exception on /venues/4 [DELETE] [in /home/abdulaziz/abdulaziz/courses/udacity/nd/fyyur/udacity_nd/lib/python3.10/site-packages/flask/app.py:1744]
Traceback (most recent call last):
  File "/home/abdulaziz/abdulaziz/courses/udacity/nd/fyyur/udacity_nd/lib/python3.10/site-packages/flask/app.py", line 2528, in wsgi_app
    response = self.full_dispatch_request()
  File "/home/abdulaziz/abdulaziz/courses/udacity/nd/fyyur/udacity_nd/lib/python3.10/site-packages/flask/app.py", line 1825, in full_dispatch_request
    rv = self.handle_user_exception(e)
  File "/home/abdulaziz/abdulaziz/courses/udacity/nd/fyyur/udacity_nd/lib/python3.10/site-packages/flask/app.py", line 1823, in full_dispatch_request
    rv = self.dispatch_request()
  File "/home/abdulaziz/abdulaziz/courses/udacity/nd/fyyur/udacity_nd/lib/python3.10/site-packages/flask/app.py", line 1799, in dispatch_request
    return self.ensure_sync(self.view_functions[rule.endpoint])(**view_args)
  File "/home/abdulaziz/abdulaziz/courses/udacity/nd/fyyur/app.py", line 237, in delete_venue
    print(Venue.query.filter_by(id=venue_id).all().delete())
AttributeError: 'list' object has no attribute 'delete'
2023-04-09 01:08:22,889 INFO: errors [in /home/abdulaziz/abdulaziz/courses/udacity/nd/fyyur/app.py:533]
2023-04-09 01:08:23,935 ERROR: Exception on /venues/4 [DELETE] [in /home/abdulaziz/abdulaziz/courses/udacity/nd/fyyur/udacity_nd/lib/python3.10/site-packages/flask/app.py:1744]
Traceback (most recent call last):
  File "/home/abdulaziz/abdulaziz/courses/udacity/nd/fyyur/udacity_nd/lib/python3.10/site-packages/flask/app.py", line 2528, in wsgi_app
    response = self.full_dispatch_request()
  File "/home/abdulaziz/abdulaziz/courses/udacity/nd/fyyur/udacity_nd/lib/python3.10/site-packages/flask/app.py", line 1825, in full_dispatch_request
    rv = self.handle_user_exception(e)
  File "/home/abdulaziz/abdulaziz/courses/udacity/nd/fyyur/udacity_nd/lib/python3.10/site-packages/flask/app.py", line 1823, in full_dispatch_request
    rv = self.dispatch_request()
  File "/home/abdulaziz/abdulaziz/courses/udacity/nd/fyyur/udacity_nd/lib/python3.10/site-packages/flask/app.py", line 1799, in dispatch_request
    return self.ensure_sync(self.view_functions[rule.endpoint])(**view_args)
  File "/home/abdulaziz/abdulaziz/courses/udacity/nd/fyyur/app.py", line 237, in delete_venue
    print(Venue.query.filter_by(id=venue_id).all()[0].delete())
AttributeError: 'Venue' object has no attribute 'delete'
2023-04-09 01:08:31,831 INFO: errors [in /home/abdulaziz/abdulaziz/courses/udacity/nd/fyyur/app.py:533]
2023-04-09 01:08:57,687 INFO: errors [in /home/abdulaziz/abdulaziz/courses/udacity/nd/fyyur/app.py:534]
2023-04-09 01:09:14,297 INFO: errors [in /home/abdulaziz/abdulaziz/courses/udacity/nd/fyyur/app.py:533]
2023-04-09 01:09:20,934 INFO: errors [in /home/abdulaziz/abdulaziz/courses/udacity/nd/fyyur/app.py:533]
2023-04-09 01:09:27,964 INFO: errors [in /home/abdulaziz/abdulaziz/courses/udacity/nd/fyyur/app.py:533]
2023-04-09 01:09:35,830 INFO: errors [in /home/abdulaziz/abdulaziz/courses/udacity/nd/fyyur/app.py:533]
2023-04-09 01:11:44,155 INFO: errors [in /home/abdulaziz/abdulaziz/courses/udacity/nd/fyyur/app.py:534]
2023-04-09 01:12:31,508 INFO: errors [in /home/abdulaziz/abdulaziz/courses/udacity/nd/fyyur/app.py:534]
